Workbook
Name ___evp1: [1]ESピット!#REF!
Name ___evp2: [2]外房⑥ESピット!#REF!
Name ___evp3: '[3]２．EVピット'!#REF!
Name _C66093: #REF!
Name _C69093: #REF!
Name _C71093: #REF!
Name _C91093: #REF!
Name _evp22: #REF!
Name \: '[7]C5-基本計算（常時）'!#REF!
Name \\: '[7]C5-基本計算（常時）'!#REF!
Name \a: #REF!
Name \d: #N/A
Name \m: #REF!
Name \p: #N/A
Name \r: #REF!
Name \z: #REF!
Name §１: #REF!
Name a: '[9]§３.（発進）平行'!$C$7
Name A111111111111: #REF!
Name aa: '[7]C5-基本計算（常時）'!#REF!
Name aaa: [10]設計条件!$C$13
Name ag: [11]せん断弾性波速度!$D$9
Name arufa: #REF!
Name Ａ通り側壁: #REF!
Name b: [8]基本ﾃﾞｰﾀｼｰﾄ!$C$27
Name basew: [10]設計条件!$C$13
Name bbb: [10]設計条件!$C$14
Name beeta: #REF!
Name C_ｽﾊﾟﾝ: '[12]C3-基本1'!$AF$53
Name C_ｽﾊﾟﾝL: '[7]C5-基本計算（常時）'!#REF!
Name C_ｽﾊﾟﾝR: '[7]C5-基本計算（常時）'!#REF!
Name ccc: [2]外房⑥ESピット!#REF!
Name DATA: '[9]§４.（発進）擁壁横、松戸'!$A$1:$IV$65536
Name DATA1: #REF!
Name DATA保存: #REF!
Name ddd: #REF!
Name df: [10]設計条件!$C$14
Name dgdkgkgk: [13]固死!#REF!
Name dghkdghkdg: '[7]C5-基本計算（常時）'!#REF!
Name dgkd: '[7]C5-基本計算（常時）'!#REF!
Name dgkdgkdg: [13]固死!#REF!
Name dgkhkdgkg: [13]固死!#REF!
Name dgkhkhgkgdh: '[7]C5-基本計算（常時）'!#REF!
Name djyfurur: '[7]C5-基本計算（常時）'!#REF!
Name dkgdghkry: '[7]C5-基本計算（常時）'!#REF!
Name e: [8]基本ﾃﾞｰﾀｼｰﾄ!$C$29
Name EA17W2: [14]列車荷重等値等分布荷重!$F$7:$I$18
Name EA17W2l: [14]列車荷重等値等分布荷重!$F$7:$F$18
Name EA17W2S: [14]列車荷重等値等分布荷重!$F$7:$I$7
Name ee: '[15]×構造計算 (表層厚66.50m)'!$K$334
Name eee: '[15]×構造計算 (表層厚66.50m)'!$H$322
Name eie6iyre: '[7]C5-基本計算（常時）'!#REF!
Name eiue6rre6: '[7]C5-基本計算（常時）'!#REF!
Name Excel_BuiltIn__FilterDatabase_4: #REF!
Name Excel_BuiltIn__FilterDatabase_5: #REF!
Name eyujdfj: '[7]C5-基本計算（常時）'!#REF!
Name E通り側壁: #REF!
Name f: [8]基本ﾃﾞｰﾀｼｰﾄ!$C$15
Name fff: '[15]×構造計算 (表層厚66.50m)'!$Q$672
Name fg: [11]せん断弾性波速度!$D$8

Sheet 水平地盤ばね定数(4P右)
C2: c) | D2: 4P右(1,3列目)
D3: 杭径 | E3: 1.3 | F3: m
D4: 杭全長 | E4: 31 | F4: m
D5: 杭本数 | E5: 3 | F5: 本
D6: 層番号 | E6: 層厚 (m) | F6: 水平地盤反力係数 khg (kN/m3) | G6: 部材長 (m) | I6: 部材番号 | K6: 各部材の水平地盤反力係数 khg (kN/m3) | L6: 各部材の水平ばね定数 KH (kN/m2) | P6: 右押し（→） | U6: 左押し（←）
P9: 節点番号 | Q9: 水平ばね | R9: 有効抵抗土圧力 | U9: 節点番号 | V9: 水平ばね | W9: 有効抵抗土圧力
L10: 杭1本当り | M10: =+E5 -> 3 | R10: 上端 | S10: 下端 | W10: 上端 | X10: 下端
D11: ① | E11: 1.5 | F11: 15080 | G11: =+E3 -> 1.3 | I11: 98 | J11: 148 | K11: =+F11 -> 15080 | L11: =K11*E3 -> 19604 | M11: =L11*E5 -> 58812 | P11: =+I11 -> 98 | Q11: =+M11 -> 58812 | R11: =+'有効抵抗土圧(4P右)'!G142 -> 1163.0298 | S11: =+'有効抵抗土圧(4P右)'!G143 -> 1307.4657 | U11: =+P11 -> 98 | V11: =+Q11 -> 58812 | W11: =+R61 -> 2907.5744 | X11: =+S61 -> 3268.6642
G12: =+G11 -> 1.3 | H12: =+E11-G11 -> 0.2 | I12: =+I11+1 -> 99 | J12: =+J11+1 -> 149 | K12: =(F11*H12+F13*H13)/G12 -> 69765.231 | L12: =K12*E3 -> 90694.8 | M12: =L12*E5 -> 272084.4 | P12: =+P11+1 -> 99 | Q12: =+M12 -> 272084.4 | R12: =+'有効抵抗土圧(4P右)'!G144 -> 1989.0401 | S12: =+'有効抵抗土圧(4P右)'!G145 -> 1989.0401 | U12: =+P12 -> 99 | V12: =+Q12 -> 272084.4 | W12: =+R62 -> 4972.6003 | X12: =+S62 -> 4972.6003
D13: ② | E13: 1.3 | F13: 79708 | H13: =+G12-H12 -> 1.1 | P13: =+P12+1 -> 100 | Q13: =+M14 -> 141501.9 | R13: =+'有効抵抗土圧(4P右)'!G146 -> 907.71051 | S13: =+'有効抵抗土圧(4P右)'!G147 -> 907.71051 | U13: =+P13 -> 100 | V13: =+Q13 -> 141501.9 | W13: =+R63 -> 2269.2763 | X13: =+S63 -> 2269.2763
G14: =+G12 -> 1.3 | H14: =+E13-H13 -> 0.2 | I14: =+I12+1 -> 100 | J14: =+J12+1 -> 150 | K14: =(F13*H14+F15*H15)/G14 -> 36282.538 | L14: =K14*E3 -> 47167.3 | M14: =L14*E5 -> 141501.9 | P14: =+P13+1 -> 101 | Q14: =+M16 -> 110709.3 | R14: =+'有効抵抗土圧(4P右)'!G148 -> 669.006 | S14: =+'有効抵抗土圧(4P右)'!G149 -> 669.006 | U14: =+P14 -> 101 | V14: =+Q14 -> 110709.3 | W14: =+R64 -> 1672.515 | X14: =+S64 -> 1672.515
D15: ③ | E15: 2.9 | F15: 28387 | H15: =+G14-H14 -> 1.1 | P15: =+P14+1 -> 102 | Q15: =+M17 -> 165448.8 | R15: =+'有効抵抗土圧(4P右)'!G150 -> 1740.9709 | S15: =+'有効抵抗土圧(4P右)'!G151 -> 1740.9709 | U15: =+P15 -> 102 | V15: =+Q15 -> 165448.8 | W15: =+R65 -> 4352.4272 | X15: =+S65 -> 4352.4272
G16: =+G14 -> 1.3 | I16: =+I14+1 -> 101 | J16: =+J14+1 -> 151 | K16: =+F15 -> 28387 | L16: =K16*E3 -> 36903.1 | M16: =L16*E5 -> 110709.3 | P16: =+P15+1 -> 103 | Q16: =+M19 -> 268854.3 | R16: =+'有効抵抗土圧(4P右)'!G152 -> 2472.7948 | S16: =+'有効抵抗土圧(4P右)'!G153 -> 2673.794 | U16: =+P16 -> 103 | V16: =+Q16 -> 268854.3 | W16: =+R66 -> 6181.9871 | X16: =+S66 -> 6684.485
G17: =+G16 -> 1.3 | H17: =+E15-H15-G16 -> 0.5 | I17: =+I16+1 -> 102 | J17: =+J16+1 -> 152 | K17: =(F16*H17+F18*H18)/G17 -> 42422.769 | L17: =K17*E3 -> 55149.6 | M17: =L17*E5 -> 165448.8 | P17: =+P16+1 -> 104 | Q17: =+M20 -> 363439.5 | R17: =+'有効抵抗土圧(4P右)'!G154 -> 2640.6296 | S17: =+'有効抵抗土圧(4P右)'!G155 -> 2640.6296 | U17: =+P17 -> 104 | V17: =+Q17 -> 363439.5 | W17: =+R67 -> 6601.5739 | X17: =+S67 -> 6601.5739
D18: ④ | E18: 2.6 | F18: 68937 | H18: =+G17-H17 -> 0.8 | P18: =+P17+1 -> 105 | Q18: =+M23 -> 403279.5 | R18: =+'有効抵抗土圧(4P右)'!G156 -> 3142.5541 | S18: =+'有効抵抗土圧(4P右)'!G157 -> 3142.5541 | U18: =+P18 -> 105 | V18: =+Q18 -> 403279.5 | W18: =+R68 -> 7856.3853 | X18: =+S68 -> 7856.3853
G19: =+G17 -> 1.3 | I19: =+I17+1 -> 103 | J19: =+J17+1 -> 153 | K19: =+F18 -> 68937 | L19: =K19*E3 -> 89618.1 | M19: =L19*E5 -> 268854.3 | P19: =+P18+1 -> 106 | Q19: =+M24 -> 403279.5 | R19: =+'有効抵抗土圧(4P右)'!G158 -> 3190.7596 | S19: =+'有効抵抗土圧(4P右)'!G159 -> 3400.6897 | U19: =+P19 -> 106 | V19: =+Q19 -> 403279.5 | W19: =+R69 -> 7976.8989 | X19: =+S69 -> 8501.7243
G20: =+G19 -> 1.3 | H20: =+E18-H18-G19 -> 0.5 | I20: =+I19+1 -> 104 | J20: =+J19+1 -> 154 | K20: =(F18*H20+F21*H21+F22*H22)/G20 -> 93189.615 | L20: =K20*E3 -> 121146.5 | M20: =L20*E5 -> 363439.5 | P20: =+P19+1 -> 107 | Q20: =+M25 -> 403279.5 | R20: =+'有効抵抗土圧(4P右)'!G160 -> 3400.6897 | S20: =+'有効抵抗土圧(4P右)'!G161 -> 3610.6199 | U20: =+P20 -> 107 | V20: =+Q20 -> 403279.5 | W20: =+R70 -> 8501.7243 | X20: =+S70 -> 9026.5498
D21: ⑤ | E21: 0.6 | F21: 109995 | H21: =+E21 -> 0.6 | P21: =+P20+1 -> 108 | Q21: =+M26 -> 403279.5 | R21: =+'有効抵抗土圧(4P右)'!G162 -> 3610.6199 | S21: =+'有効抵抗土圧(4P右)'!G163 -> 3820.5501 | U21: =+P21 -> 108 | V21: =+Q21 -> 403279.5 | W21: =+R71 -> 9026.5498 | X21: =+S71 -> 9551.3752
D22: ⑥ | E22: 9.5 | F22: 103405 | H22: =+G20-H20-H21 -> 0.2 | P22: =+P21+1 -> 109 | Q22: =+M27 -> 403279.5 | R22: =+'有効抵抗土圧(4P右)'!G164 -> 3820.5501 | S22: =+'有効抵抗土圧(4P右)'!G165 -> 4030.4802 | U22: =+P22 -> 109 | V22: =+Q22 -> 403279.5 | W22: =+R72 -> 9551.3752 | X22: =+S72 -> 10076.201
G23: =+G20 -> 1.3 | I23: =+I20+1 -> 105 | J23: =+J20+1 -> 155 | K23: =+F22 -> 103405 | L23: =K23*E3 -> 134426.5 | M23: =L23*E5 -> 403279.5 | P23: =+P22+1 -> 110 | Q23: =+M28 -> 403279.5 | R23: =+'有効抵抗土圧(4P右)'!G166 -> 4030.4802 | S23: =+'有効抵抗土圧(4P右)'!G167 -> 4240.4104 | U23: =+P23 -> 110 | V23: =+Q23 -> 403279.5 | W23: =+R73 -> 10076.201 | X23: =+S73 -> 10601.026
G24: =+G23 -> 1.3 | I24: =+I23+1 -> 106 | J24: =+J23+1 -> 156 | K24: =+K23 -> 103405 | L24: =K24*E3 -> 134426.5 | M24: =L24*E5 -> 403279.5 | P24: =+P23+1 -> 111 | Q24: =+M29 -> 403279.5 | R24: =+'有効抵抗土圧(4P右)'!G168 -> 4240.4104 | S24: =+'有効抵抗土圧(4P右)'!G169 -> 4450.3406 | U24: =+P24 -> 111 | V24: =+Q24 -> 403279.5 | W24: =+R74 -> 10601.026 | X24: =+S74 -> 11125.851
G25: =+G24 -> 1.3 | I25: =+I24+1 -> 107 | J25: =+J24+1 -> 157 | K25: =+K24 -> 103405 | L25: =K25*E3 -> 134426.5 | M25: =L25*E5 -> 403279.5 | P25: =+P24+1 -> 112 | Q25: =+M30 -> 225970.5 | R25: =+'有効抵抗土圧(4P右)'!G170 -> 1683.4565 | S25: =+'有効抵抗土圧(4P右)'!G171 -> 1683.4565 | U25: =+P25 -> 112 | V25: =+Q25 -> 225970.5 | W25: =+R75 -> 4208.6412 | X25: =+S75 -> 4208.6412
G26: =+G25 -> 1.3 | I26: =+I25+1 -> 108 | J26: =+J25+1 -> 158 | K26: =+K25 -> 103405 | L26: =K26*E3 -> 134426.5 | M26: =L26*E5 -> 403279.5 | P26: =+P25+1 -> 113 | Q26: =+M32 -> 193732.5 | R26: =+'有効抵抗土圧(4P右)'!G172 -> 3088.8 | S26: =+'有効抵抗土圧(4P右)'!G173 -> 3088.8 | U26: =+P26 -> 113 | V26: =+Q26 -> 193732.5 | W26: =+R76 -> 3088.8 | X26: =+S76 -> 3088.8
G27: =+G26 -> 1.3 | I27: =+I26+1 -> 109 | J27: =+J26+1 -> 159 | K27: =+K26 -> 103405 | L27: =K27*E3 -> 134426.5 | M27: =L27*E5 -> 403279.5 | P27: =+P26+1 -> 114 | Q27: =+M33 -> 193732.5 | R27: =+'有効抵抗土圧(4P右)'!G174 -> 3088.8 | S27: =+'有効抵抗土圧(4P右)'!G175 -> 3088.8 | U27: =+P27 -> 114 | V27: =+Q27 -> 193732.5 | W27: =+R77 -> 3088.8 | X27: =+S77 -> 3088.8
G28: =+G27 -> 1.3 | I28: =+I27+1 -> 110 | J28: =+J27+1 -> 160 | K28: =+K27 -> 103405 | L28: =K28*E3 -> 134426.5 | M28: =L28*E5 -> 403279.5 | P28: =+P27+1 -> 115 | Q28: =+M34 -> 193732.5 | R28: =+'有効抵抗土圧(4P右)'!G176 -> 3088.8 | S28: =+'有効抵抗土圧(4P右)'!G177 -> 3088.8 | U28: =+P28 -> 115 | V28: =+Q28 -> 193732.5 | W28: =+R78 -> 3088.8 | X28: =+S78 -> 3088.8
G29: =+G28 -> 1.3 | I29: =+I28+1 -> 111 | J29: =+J28+1 -> 161 | K29: =+K28 -> 103405 | L29: =K29*E3 -> 134426.5 | M29: =L29*E5 -> 403279.5 | P29: =+P28+1 -> 116 | Q29: =+M35 -> 193732.5 | R29: =+'有効抵抗土圧(4P右)'!G178 -> 3088.8 | S29: =+'有効抵抗土圧(4P右)'!G179 -> 3088.8 | U29: =+P29 -> 116 | V29: =+Q29 -> 193732.5 | W29: =+R79 -> 3088.8 | X29: =+S79 -> 3088.8
G30: =+G29 -> 1.3 | H30: =+E22-H22-G23-G24-G25-G26-G27-G28-G29 -> 0.2 | I30: =+I29+1 -> 112 | J30: =+J29+1 -> 162 | K30: =(F22*H30+F31*H31)/G30 -> 57941.154 | L30: =K30*E3 -> 75323.5 | M30: =L30*E5 -> 225970.5 | P30: =+P29+1 -> 117 | Q30: =+M36 -> 193732.5 | R30: =+'有効抵抗土圧(4P右)'!G180 -> 3088.8 | S30: =+'有効抵抗土圧(4P右)'!G181 -> 3088.8 | U30: =+P30 -> 117 | V30: =+Q30 -> 193732.5 | W30: =+R80 -> 3088.8 | X30: =+S80 -> 3088.8
D31: ⑦ | E31: 12.6 | F31: 49675 | H31: =+G30-H30 -> 1.1 | P31: =+P30+1 -> 118 | Q31: =+M37 -> 193732.5 | R31: =+'有効抵抗土圧(4P右)'!G182 -> 3088.8 | S31: =+'有効抵抗土圧(4P右)'!G183 -> 3088.8 | U31: =+P31 -> 118 | V31: =+Q31 -> 193732.5 | W31: =+R81 -> 3088.8 | X31: =+S81 -> 3088.8
G32: =+G30 -> 1.3 | I32: =+I30+1 -> 113 | J32: =+J30+1 -> 163 | K32: =+F31 -> 49675 | L32: =K32*E3 -> 64577.5 | M32: =L32*E5 -> 193732.5 | P32: =+P31+1 -> 119 | Q32: =+M38 -> 193732.5 | R32: =+'有効抵抗土圧(4P右)'!G184 -> 3088.8 | S32: =+'有効抵抗土圧(4P右)'!G185 -> 3088.8 | U32: =+P32 -> 119 | V32: =+Q32 -> 193732.5 | W32: =+R82 -> 3088.8 | X32: =+S82 -> 3088.8
G33: =+G32 -> 1.3 | I33: =+I32+1 -> 114 | J33: =+J32+1 -> 164 | K33: =+K32 -> 49675 | L33: =K33*E3 -> 64577.5 | M33: =L33*E5 -> 193732.5 | P33: =+P32+1 -> 120 | Q33: =+M39 -> 193732.5 | R33: =+'有効抵抗土圧(4P右)'!G186 -> 3088.8 | S33: =+'有効抵抗土圧(4P右)'!G187 -> 3088.8 | U33: =+P33 -> 120 | V33: =+Q33 -> 193732.5 | W33: =+R83 -> 3088.8 | X33: =+S83 -> 3088.8
G34: =+G33 -> 1.3 | I34: =+I33+1 -> 115 | J34: =+J33+1 -> 165 | K34: =+K33 -> 49675 | L34: =K34*E3 -> 64577.5 | M34: =L34*E5 -> 193732.5 | P34: =+P33+1 -> 121 | Q34: =+M40 -> 193732.5 | R34: =+'有効抵抗土圧(4P右)'!G188 -> 3088.8 | S34: =+'有効抵抗土圧(4P右)'!G189 -> 3088.8 | U34: =+P34 -> 121 | V34: =+Q34 -> 193732.5 | W34: =+R84 -> 3088.8 | X34: =+S84 -> 3088.8
G35: =+G34 -> 1.3 | I35: =+I34+1 -> 116 | J35: =+J34+1 -> 166 | K35: =+K34 -> 49675 | L35: =K35*E3 -> 64577.5 | M35: =L35*E5 -> 193732.5
G36: =+G35 -> 1.3 | I36: =+I35+1 -> 117 | J36: =+J35+1 -> 167 | K36: =+K35 -> 49675 | L36: =K36*E3 -> 64577.5 | M36: =L36*E5 -> 193732.5 | P36: =+I54 -> 123 | Q36: =+M54 -> 39208 | R36: =+'有効抵抗土圧(4P右)'!H142 -> 1004.7861 | S36: =+'有効抵抗土圧(4P右)'!H143 -> 1129.5699 | U36: =+P36 -> 123 | V36: =+Q36 -> 39208 | W36: =+R36 -> 1004.7861 | X36: =+S36 -> 1129.5699
G37: =+G36 -> 1.3 | I37: =+I36+1 -> 118 | J37: =+J36+1 -> 168 | K37: =+K36 -> 49675 | L37: =K37*E3 -> 64577.5 | M37: =L37*E5 -> 193732.5 | P37: =+P36+1 -> 124 | Q37: =+M55 -> 181389.6 | R37: =+'有効抵抗土圧(4P右)'!H144 -> 1718.4082 | S37: =+'有効抵抗土圧(4P右)'!H145 -> 1718.4082 | U37: =+P37 -> 124 | V37: =+Q37 -> 181389.6 | W37: =+R37 -> 1718.4082 | X37: =+S37 -> 1718.4082
G38: =+G37 -> 1.3 | I38: =+I37+1 -> 119 | J38: =+J37+1 -> 169 | K38: =+K37 -> 49675 | L38: =K38*E3 -> 64577.5 | M38: =L38*E5 -> 193732.5 | P38: =+P37+1 -> 125 | Q38: =+M57 -> 94334.6 | R38: =+'有効抵抗土圧(4P右)'!H146 -> 784.206 | S38: =+'有効抵抗土圧(4P右)'!H147 -> 784.206 | U38: =+P38 -> 125 | V38: =+Q38 -> 94334.6 | W38: =+R38 -> 784.206 | X38: =+S38 -> 784.206
G39: =+G38 -> 1.3 | I39: =+I38+1 -> 120 | J39: =+J38+1 -> 170 | K39: =+K38 -> 49675 | L39: =K39*E3 -> 64577.5 | M39: =L39*E5 -> 193732.5 | P39: =+P38+1 -> 126 | Q39: =+M59 -> 73806.2 | R39: =+'有効抵抗土圧(4P右)'!H148 -> 577.98 | S39: =+'有効抵抗土圧(4P右)'!H149 -> 577.98 | U39: =+P39 -> 126 | V39: =+Q39 -> 73806.2 | W39: =+R39 -> 577.98 | X39: =+S39 -> 577.98
G40: =E31-H31-SUM(G32:H39) -> 1.1 | I40: =+I39+1 -> 121 | J40: =+J39+1 -> 171 | K40: =+K39 -> 49675 | L40: =K40*E3 -> 64577.5 | M40: =L40*E5 -> 193732.5 | P40: =+P39+1 -> 127 | Q40: =+M60 -> 110299.2 | R40: =+'有効抵抗土圧(4P右)'!H150 -> 1504.0917 | S40: =+'有効抵抗土圧(4P右)'!H151 -> 1504.0917 | U40: =+P40 -> 127 | V40: =+Q40 -> 110299.2 | W40: =+R40 -> 1504.0917 | X40: =+S40 -> 1504.0917
D41: Σ | E41: =SUM(E11:E40) -> 31 | G41: =SUM(G11:G40) -> 31 | P41: =+P40+1 -> 128 | Q41: =+M62 -> 179236.2 | R41: =+'有効抵抗土圧(4P右)'!H152 -> 2136.3425 | S41: =+'有効抵抗土圧(4P右)'!H153 -> 2309.9934 | U41: =+P41 -> 128 | V41: =+Q41 -> 179236.2 | W41: =+R41 -> 2136.3425 | X41: =+S41 -> 2309.9934
P42: =+P41+1 -> 129 | Q42: =+M63 -> 242293 | R42: =+'有効抵抗土圧(4P右)'!H154 -> 2281.3414 | S42: =+'有効抵抗土圧(4P右)'!H155 -> 2281.3414 | U42: =+P42 -> 129 | V42: =+Q42 -> 242293 | W42: =+R42 -> 2281.3414 | X42: =+S42 -> 2281.3414
P43: =+P42+1 -> 130 | Q43: =+M66 -> 268853 | R43: =+'有効抵抗土圧(4P右)'!H156 -> 2714.9733 | S43: =+'有効抵抗土圧(4P右)'!H157 -> 2714.9733 | U43: =+P43 -> 130 | V43: =+Q43 -> 268853 | W43: =+R43 -> 2714.9733 | X43: =+S43 -> 2714.9733
...

Sheet 有効抵抗土圧(4P右)
C2: 2) | D2: 4P右
C3: a) | D3: 単杭の有効抵抗土圧力度pe(z)
D4: 杭径 | E4: 1.3 | F4: m
D5: 杭全長 | E5: 31 | F5: m
D6: 層番号 | E6: 層種別 | F6: 層厚 (m) | G6: 部材番号 | J6: 有効抵抗土圧力度を求める深さ z (m) | K6: 層境の 分布幅 (m) | L6: 単杭の 有効抵抗 土圧力度 pe(z) (kN/m2) | M6: 有効抵抗土圧力度の平均値 pe(z) (kN/m2)
D11: ① | E11: 砂質土 | F11: 1.5 | G11: 98 | H11: 123 | I11: 148 | J11: 0 | L11: 782.3
J12: 1.3 | L12: =+L11+(L14-L11)/F11*(J12-J11) -> 879.45333
G13: =+G11+1 -> 99 | H13: =+H11+1 -> 124 | I13: =+I11+1 -> 149 | K13: =+J14-J12 -> 0.2 | M13: =0.5*((L12+L14)*K13+(L15+L16)*K15)/(K13+K15) -> 1337.9074
J14: =+F11 -> 1.5 | L14: 894.4
D15: ② | E15: 砂質土 | F15: 1.3 | J15: =+J14 -> 1.5 | K15: =+J16-J15 -> 1.1 | L15: 1357.5
J16: =+J12+E4 -> 2.6 | L16: =+L15+(L18-L15)/F15*(J16-J15) -> 1482.3077 | M16: =+M13 -> 1337.9074
G17: =+G13+1 -> 100 | H17: =+H13+1 -> 125 | I17: =+I13+1 -> 150 | K17: =+J18-J16 -> 0.2 | M17: =0.5*((L16+L18)*K17+(L19+L20)*K19)/(K17+K19) -> 610.56213
J18: =+J15+F15 -> 2.8 | L18: 1505
D19: ③ | E19: 粘性土 | F19: 2.9 | J19: =+J18 -> 2.8 | K19: =+J20-J19 -> 1.1 | L19: 450
J20: =+J16+E4 -> 3.9 | L20: =+L19+(L24-L19)/F19*(J20-J19) -> 450 | M20: =+M17 -> 610.56213
G21: =+G17+1 -> 101 | H21: =+H17+1 -> 126 | I21: =+I17+1 -> 151
J22: =+J20+E4 -> 5.2 | L22: =+L19+(L24-L19)/F19*(J22-J19) -> 450
G23: =+G21+1 -> 102 | H23: =+H21+1 -> 127 | I23: =+I21+1 -> 152 | K23: =+J24-J22 -> 0.5 | M23: =0.5*((L22+L24)*K23+(L25+L26)*K25)/(K23+K25) -> 1171.0462
J24: =+J19+F19 -> 5.7 | L24: 450
D25: ④ | E25: 砂質土 | F25: 2.6 | J25: =+J24 -> 5.7 | K25: =+J26-J25 -> 0.8 | L25: 1580.1
J26: =+J22+E4 -> 6.5 | L26: =+L25+(L30-L25)/F25*(J26-J25) -> 1663.3 | M26: =+M23 -> 1171.0462
G27: =+G23+1 -> 103 | H27: =+H23+1 -> 128 | I27: =+I23+1 -> 153
J28: =+J26+E4 -> 7.8 | L28: =+L25+(L30-L25)/F25*(J28-J25) -> 1798.5
G29: =+G27+1 -> 104 | H29: =+H27+1 -> 129 | I29: =+I27+1 -> 154 | K29: =+J30-J28 -> 0.5 | M29: =0.5*((L28+L30)*K29+(L31+L32)*K31)/(K29+K31) -> 1776.1923
J30: =+J25+F25 -> 8.3 | L30: 1850.5
D31: ⑤ | E31: 粘性土 | F31: 0.6 | J31: =+J30 -> 8.3 | K31: =+J32-J31 -> 0.8 | L31: 1746
J32: =+J28+E4 -> 9.1 | L32: =+L31+(L34-L31)/F31*(J32-J31) -> 1746 | M32: =+M29 -> 1776.1923
G33: =+G29+1 -> 105 | H33: =+H29+1 -> 130 | I33: =+I29+1 -> 155 | K33: =+J34-J32 -> -0.2 | M33: =0.5*((L32+L34)*K33+(L35+L36)*K35)/(K33+K35) -> 2113.8067
J34: =+J31+F31 -> 8.9 | L34: 1746
D35: ⑥ | E35: 砂質土 | F35: 9.5 | J35: =+J34 -> 8.9 | K35: =+J36-J35 -> 1.5 | L35: 1983.3
J36: =+J32+E4 -> 10.4 | L36: =+L35+(L50-L35)/F35*(J36-J35) -> 2146.2316 | M36: =+M33 -> 2113.8067
G37: =+G33+1 -> 106 | H37: =+H33+1 -> 131 | I37: =+I33+1 -> 156
J38: =+J36+E4 -> 11.7 | L38: =+L35+(L50-L35)/F35*(J38-J35) -> 2287.4389
G39: =+G37+1 -> 107 | H39: =+H37+1 -> 132 | I39: =+I37+1 -> 157
J40: =+J38+E4 -> 13 | L40: =+L35+(L50-L35)/F35*(J40-J35) -> 2428.6463
G41: =+G39+1 -> 108 | H41: =+H39+1 -> 133 | I41: =+I39+1 -> 158
J42: =+J40+E4 -> 14.3 | L42: =+L35+(L50-L35)/F35*(J42-J35) -> 2569.8537
G43: =+G41+1 -> 109 | H43: =+H41+1 -> 134 | I43: =+I41+1 -> 159
J44: =+J42+E4 -> 15.6 | L44: =+L35+(L50-L35)/F35*(J44-J35) -> 2711.0611
G45: =+G43+1 -> 110 | H45: =+H43+1 -> 135 | I45: =+I43+1 -> 160
...

Sheet 鉛直せん断地盤ばね定数(4P右)
C2: c) | D2: 4P右(1,3列目)
D3: 杭径 | E3: 1.3 | F3: m
D4: 周長 | E4: =+PI()*E3 -> 4.0840704 | F4: m
D5: 杭全長 | E5: 31 | F5: m
D6: 1/β | E6: 4.945 | F6: m
D7: 杭本数 | E7: 3 | F7: 本
D8: 層番号 | E8: 層厚 (m) | F8: 鉛直せん断地盤ばねを考慮する層厚(m) | G8: 鉛直地盤 反力係数 kfv (kN/m3) | H8: 分布幅 (m) | J8: 1/βを考慮 した分布幅 (m) | L8: 節点番号 | N8: 分布幅の鉛直地盤反力係数 kfv (kN/m2) | O8: 各節点の鉛直ばね定数 Kfv (kN/m) | S8: 節点番号 | T8: 拘束方向 | U8: 第1勾配 | X8: 第2勾配 | AA8: 第3勾配 | AB8: 第1勾配 | AC8: 第2勾配 | AD8: 第3勾配
U9: 鉛直ばね | V9: 制限値 | X9: 鉛直ばね | Y9: 制限値 | AA9: 鉛直ばね | AB9: 鉛直ばね | AC9: 鉛直ばね | AD9: 鉛直ばね
U10: ＋側 | V10: ＋側 | W10: －側 | X10: ＋側 | Y10: ＋側 | Z10: －側 | AA10: ＋側 | AB10: －側 | AC10: －側 | AD10: －側
S11: =+L13 -> 98
O12: 杭1本当り | P12: =+E7 -> 3 | S12: =+S11+1 -> 99
D13: ① | E13: 1.5 | F13: － | G13: 2000 | H13: =+E3/2 -> 0.65 | J13: － | K13: － | L13: 98 | M13: 148 | N13: － | O13: － | P13: － | S13: =+S12+1 -> 100
H14: =+E3 -> 1.3 | I14: =+E13-H13 -> 0.85 | J14: － | K14: － | L14: =+L13+1 -> 99 | M14: =+M13+1 -> 149 | N14: － | O14: － | P14: － | S14: =+S13+1 -> 101
D15: ② | E15: 1.3 | F15: － | G15: 10571 | I15: =+H14-I14 -> 0.45 | K15: － | S15: =+S14+1 -> 102 | T15: Y | U15: =+P20 -> 51631.125 | V15: =+'周面支持力(4P右)'!P20 -> 361.44023 | W15: =+V15 -> 361.44023 | X15: =+U15 -> 51631.125 | Y15: =+V15 -> 361.44023 | Z15: =+Y15 -> 361.44023 | AA15: =+X15 -> 51631.125 | AB15: =+AA15 -> 51631.125 | AC15: =+AB15 -> 51631.125 | AD15: =+AC15 -> 51631.125
H16: =+H14 -> 1.3 | I16: =+E15-I15 -> 0.85 | J16: － | K16: － | L16: =+L14+1 -> 100 | M16: =+M14+1 -> 150 | N16: － | O16: － | P16: － | S16: =+S15+1 -> 103 | T16: Y | U16: =+P22 -> 145628.56 | V16: =+'周面支持力(4P右)'!P22 -> 1529.076 | W16: =+V16 -> 1529.076 | X16: =+U16 -> 145628.56 | Y16: =+V16 -> 1529.076 | Z16: =+Y16 -> 1529.076 | AA16: =+X16 -> 145628.56 | AB16: =+AA16 -> 145628.56 | AC16: =+AB16 -> 145628.56 | AD16: =+AC16 -> 145628.56
D17: ③ | E17: 2.9 | F17: =+E13+E15+E17-E6 -> 0.755 | G17: 3765 | I17: =+H16-I16 -> 0.45 | K17: － | S17: =+S16+1 -> 104 | T17: Y | U17: =+P24 -> 155635.55 | V17: =+'周面支持力(4P右)'!P24 -> 1495.2599 | W17: =+V17 -> 1495.2599 | X17: =+U17 -> 155635.55 | Y17: =+V17 -> 1495.2599 | Z17: =+Y17 -> 1495.2599 | AA17: =+X17 -> 155635.55 | AB17: =+AA17 -> 155635.55 | AC17: =+AB17 -> 155635.55 | AD17: =+AC17 -> 155635.55
H18: =+H16 -> 1.3 | J18: － | L18: =+L16+1 -> 101 | M18: =+M16+1 -> 151 | N18: － | O18: － | P18: － | S18: =+S17+1 -> 105 | T18: Y | U18: =+P26 -> 223253.67 | V18: =+'周面支持力(4P右)'!P26 -> 1927.5179 | W18: =+V18 -> 1927.5179 | X18: =+U18 -> 223253.67 | Y18: =+V18 -> 1927.5179 | Z18: =+Y18 -> 1927.5179 | AA18: =+X18 -> 223253.67 | AB18: =+AA18 -> 223253.67 | AC18: =+AB18 -> 223253.67 | AD18: =+AC18 -> 223253.67
S19: =+S18+1 -> 106 | T19: Y | U19: =+P28 -> 218434.87 | V19: =+'周面支持力(4P右)'!P28 -> 2293.614 | W19: =+V19 -> 2293.614 | X19: =+U19 -> 218434.87 | Y19: =+V19 -> 2293.614 | Z19: =+Y19 -> 2293.614 | AA19: =+X19 -> 218434.87 | AB19: =+AA19 -> 218434.87 | AC19: =+AB19 -> 218434.87 | AD19: =+AC19 -> 218434.87
H20: =+H18 -> 1.3 | I20: =+E17-I17-H18 -> 1.15 | J20: =+E3 -> 1.3 | K20: =+F17 -> 0.755 | L20: =+L18+1 -> 102 | M20: =+M18+1 -> 152 | N20: =+G17*K20+G21*K21 -> 4214.025 | O20: =+E4*N20 -> 17210.375 | P20: =+E7*O20 -> 51631.125 | S20: =+S19+1 -> 107 | T20: Y | U20: =+P30 -> 218434.87 | V20: =+'周面支持力(4P右)'!P30 -> 2293.614 | W20: =+V20 -> 2293.614 | X20: =+U20 -> 218434.87 | Y20: =+V20 -> 2293.614 | Z20: =+Y20 -> 2293.614 | AA20: =+X20 -> 218434.87 | AB20: =+AA20 -> 218434.87 | AC20: =+AB20 -> 218434.87 | AD20: =+AC20 -> 218434.87
D21: ④ | E21: 2.6 | F21: =+E21 -> 2.6 | G21: 9143 | I21: =+H20-I20 -> 0.15 | K21: =+I21 -> 0.15 | S21: =+S20+1 -> 108 | T21: Y | U21: =+P32 -> 218434.87 | V21: =+'周面支持力(4P右)'!P32 -> 2293.614 | W21: =+V21 -> 2293.614 | X21: =+U21 -> 218434.87 | Y21: =+V21 -> 2293.614 | Z21: =+Y21 -> 2293.614 | AA21: =+X21 -> 218434.87 | AB21: =+AA21 -> 218434.87 | AC21: =+AB21 -> 218434.87 | AD21: =+AC21 -> 218434.87
H22: =+H20 -> 1.3 | J22: =+J20 -> 1.3 | L22: =+L20+1 -> 103 | M22: =+M20+1 -> 153 | N22: =+G21*J22 -> 11885.9 | O22: =+E4*N22 -> 48542.853 | P22: =+E7*O22 -> 145628.56 | S22: =+S21+1 -> 109 | T22: Y | U22: =+P34 -> 218434.87 | V22: =+'周面支持力(4P右)'!P34 -> 2293.614 | W22: =+V22 -> 2293.614 | X22: =+U22 -> 218434.87 | Y22: =+V22 -> 2293.614 | Z22: =+Y22 -> 2293.614 | AA22: =+X22 -> 218434.87 | AB22: =+AA22 -> 218434.87 | AC22: =+AB22 -> 218434.87 | AD22: =+AC22 -> 218434.87
S23: =+S22+1 -> 110 | T23: Y | U23: =+P36 -> 218434.87 | V23: =+'周面支持力(4P右)'!P36 -> 2293.614 | W23: =+V23 -> 2293.614 | X23: =+U23 -> 218434.87 | Y23: =+V23 -> 2293.614 | Z23: =+Y23 -> 2293.614 | AA23: =+X23 -> 218434.87 | AB23: =+AA23 -> 218434.87 | AC23: =+AB23 -> 218434.87 | AD23: =+AC23 -> 218434.87
H24: =+H22 -> 1.3 | I24: =+E21-I21-H22 -> 1.15 | J24: =+J22 -> 1.3 | K24: =+I24 -> 1.15 | L24: =+L22+1 -> 104 | M24: =+M22+1 -> 154 | N24: =+G21*K24+G25*K25 -> 12702.65 | O24: =+E4*N24 -> 51878.517 | P24: =+E7*O24 -> 155635.55 | S24: =+S23+1 -> 111 | T24: Y | U24: =+P38 -> 218434.87 | V24: =+'周面支持力(4P右)'!P38 -> 2293.614 | W24: =+V24 -> 2293.614 | X24: =+U24 -> 218434.87 | Y24: =+V24 -> 2293.614 | Z24: =+Y24 -> 2293.614 | AA24: =+X24 -> 218434.87 | AB24: =+AA24 -> 218434.87 | AC24: =+AB24 -> 218434.87 | AD24: =+AC24 -> 218434.87
D25: ⑤ | E25: 0.6 | F25: =+E25 -> 0.6 | G25: 14588 | I25: =+H24-I24 -> 0.15 | K25: =+I25 -> 0.15 | S25: =+S24+1 -> 112 | T25: Y | U25: =+P40 -> 179145.71 | V25: =+'周面支持力(4P右)'!P40 -> 1693.7457 | W25: =+V25 -> 1693.7457 | X25: =+U25 -> 179145.71 | Y25: =+V25 -> 1693.7457 | Z25: =+Y25 -> 1693.7457 | AA25: =+X25 -> 179145.71 | AB25: =+AA25 -> 179145.71 | AC25: =+AB25 -> 179145.71 | AD25: =+AC25 -> 179145.71
H26: =+H24 -> 1.3 | I26: =+E25-I25 -> 0.45 | J26: =+J24 -> 1.3 | K26: =+I26 -> 0.45 | L26: =+L24+1 -> 105 | M26: =+M24+1 -> 155 | N26: =+G25*K26+G27*K27 -> 18221.5 | O26: =+E4*N26 -> 74417.89 | P26: =+E7*O26 -> 223253.67 | S26: =+S25+1 -> 113 | T26: Y | U26: =+P42 -> 104932.84 | V26: =+'周面支持力(4P右)'!P42 -> 560.66119 | W26: =+V26 -> 560.66119 | X26: =+U26 -> 104932.84 | Y26: =+V26 -> 560.66119 | Z26: =+Y26 -> 560.66119 | AA26: =+X26 -> 104932.84 | AB26: =+AA26 -> 104932.84 | AC26: =+AB26 -> 104932.84 | AD26: =+AC26 -> 104932.84
D27: ⑥ | E27: 9.5 | F27: =+E27 -> 9.5 | G27: 13714 | I27: =+H26-I26 -> 0.85 | K27: =+I27 -> 0.85 | S27: =+S26+1 -> 114 | T27: Y | U27: =+P44 -> 104932.84 | V27: =+'周面支持力(4P右)'!P44 -> 560.66119 | W27: =+V27 -> 560.66119 | X27: =+U27 -> 104932.84 | Y27: =+V27 -> 560.66119 | Z27: =+Y27 -> 560.66119 | AA27: =+X27 -> 104932.84 | AB27: =+AA27 -> 104932.84 | AC27: =+AB27 -> 104932.84 | AD27: =+AC27 -> 104932.84
H28: =+H26 -> 1.3 | J28: =+J26 -> 1.3 | L28: =+L26+1 -> 106 | M28: =+M26+1 -> 156 | N28: =+G27*J28 -> 17828.2 | O28: =+E4*N28 -> 72811.625 | P28: =+E7*O28 -> 218434.87 | S28: =+S27+1 -> 115 | T28: Y | U28: =+P46 -> 104932.84 | V28: =+'周面支持力(4P右)'!P46 -> 560.66119 | W28: =+V28 -> 560.66119 | X28: =+U28 -> 104932.84 | Y28: =+V28 -> 560.66119 | Z28: =+Y28 -> 560.66119 | AA28: =+X28 -> 104932.84 | AB28: =+AA28 -> 104932.84 | AC28: =+AB28 -> 104932.84 | AD28: =+AC28 -> 104932.84
S29: =+S28+1 -> 116 | T29: Y | U29: =+P48 -> 104932.84 | V29: =+'周面支持力(4P右)'!P48 -> 560.66119 | W29: =+V29 -> 560.66119 | X29: =+U29 -> 104932.84 | Y29: =+V29 -> 560.66119 | Z29: =+Y29 -> 560.66119 | AA29: =+X29 -> 104932.84 | AB29: =+AA29 -> 104932.84 | AC29: =+AB29 -> 104932.84 | AD29: =+AC29 -> 104932.84
H30: =+H28 -> 1.3 | J30: =+J28 -> 1.3 | L30: =+L28+1 -> 107 | M30: =+M28+1 -> 157 | N30: =+G27*J30 -> 17828.2 | O30: =+E4*N30 -> 72811.625 | P30: =+E7*O30 -> 218434.87 | S30: =+S29+1 -> 117 | T30: Y | U30: =+P50 -> 104932.84 | V30: =+'周面支持力(4P右)'!P50 -> 560.66119 | W30: =+V30 -> 560.66119 | X30: =+U30 -> 104932.84 | Y30: =+V30 -> 560.66119 | Z30: =+Y30 -> 560.66119 | AA30: =+X30 -> 104932.84 | AB30: =+AA30 -> 104932.84 | AC30: =+AB30 -> 104932.84 | AD30: =+AC30 -> 104932.84
S31: =+S30+1 -> 118 | T31: Y | U31: =+P52 -> 104932.84 | V31: =+'周面支持力(4P右)'!P52 -> 560.66119 | W31: =+V31 -> 560.66119 | X31: =+U31 -> 104932.84 | Y31: =+V31 -> 560.66119 | Z31: =+Y31 -> 560.66119 | AA31: =+X31 -> 104932.84 | AB31: =+AA31 -> 104932.84 | AC31: =+AB31 -> 104932.84 | AD31: =+AC31 -> 104932.84
H32: =+H30 -> 1.3 | J32: =+J30 -> 1.3 | L32: =+L30+1 -> 108 | M32: =+M30+1 -> 158 | N32: =+G27*J32 -> 17828.2 | O32: =+E4*N32 -> 72811.625 | P32: =+E7*O32 -> 218434.87 | S32: =+S31+1 -> 119 | T32: Y | U32: =+P54 -> 104932.84 | V32: =+'周面支持力(4P右)'!P54 -> 560.66119 | W32: =+V32 -> 560.66119 | X32: =+U32 -> 104932.84 | Y32: =+V32 -> 560.66119 | Z32: =+Y32 -> 560.66119 | AA32: =+X32 -> 104932.84 | AB32: =+AA32 -> 104932.84 | AC32: =+AB32 -> 104932.84 | AD32: =+AC32 -> 104932.84
S33: =+S32+1 -> 120 | T33: Y | U33: =+P56 -> 104932.84 | V33: =+'周面支持力(4P右)'!P56 -> 560.66119 | W33: =+V33 -> 560.66119 | X33: =+U33 -> 104932.84 | Y33: =+V33 -> 560.66119 | Z33: =+Y33 -> 560.66119 | AA33: =+X33 -> 104932.84 | AB33: =+AA33 -> 104932.84 | AC33: =+AB33 -> 104932.84 | AD33: =+AC33 -> 104932.84
H34: =+H32 -> 1.3 | J34: =+J32 -> 1.3 | L34: =+L32+1 -> 109 | M34: =+M32+1 -> 159 | N34: =+G27*J34 -> 17828.2 | O34: =+E4*N34 -> 72811.625 | P34: =+E7*O34 -> 218434.87 | S34: =+S33+1 -> 121 | T34: Y | U34: =+P58 -> 36322.906 | V34: =+'周面支持力(4P右)'!P58 -> 194.07503 | W34: =+V34 -> 194.07503 | X34: =+U34 -> 36322.906 | Y34: =+V34 -> 194.07503 | Z34: =+Y34 -> 194.07503 | AA34: =+X34 -> 36322.906 | AB34: =+AA34 -> 36322.906 | AC34: =+AB34 -> 36322.906 | AD34: =+AC34 -> 36322.906
S35: =+S34+1 -> 122
H36: =+H34 -> 1.3 | J36: =+J34 -> 1.3 | L36: =+L34+1 -> 110 | M36: =+M34+1 -> 160 | N36: =+G27*J36 -> 17828.2 | O36: =+E4*N36 -> 72811.625 | P36: =+E7*O36 -> 218434.87
H38: =+H36 -> 1.3 | J38: =+J36 -> 1.3 | L38: =+L36+1 -> 111 | M38: =+M36+1 -> 161 | N38: =+G27*J38 -> 17828.2 | O38: =+E4*N38 -> 72811.625 | P38: =+E7*O38 -> 218434.87
H40: =+H38 -> 1.3 | I40: =+E27-I27-H28-H30-H32-H34-H36-H38 -> 0.85 | J40: =+J38 -> 1.3 | K40: =+I40 -> 0.85 | L40: =+L38+1 -> 112 | M40: =+M38+1 -> 162 | N40: =+G27*K40+G41*K41 -> 14621.5 | O40: =+E4*N40 -> 59715.236 | P40: =+E7*O40 -> 179145.71
D41: ⑦ | E41: 12.6 | F41: =+E41-E3 -> 11.3 | G41: 6588 | I41: =+H42-I40 -> 0.45 | K41: =+I41 -> 0.45
H42: =+H40 -> 1.3 | J42: =+J40 -> 1.3 | L42: =+L40+1 -> 113 | M42: =+M40+1 -> 163 | N42: =+G41*J42 -> 8564.4 | O42: =+E4*N42 -> 34977.613 | P42: =+E7*O42 -> 104932.84
H44: =+H42 -> 1.3 | J44: =+J42 -> 1.3 | L44: =+L42+1 -> 114 | M44: =+M42+1 -> 164 | N44: =+G41*J44 -> 8564.4 | O44: =+E4*N44 -> 34977.613 | P44: =+E7*O44 -> 104932.84
...

Sheet 周面支持力(4P右)
C2: c) | D2: 4P右(1,3列目)
D3: 杭径 | E3: 1.3 | F3: m
D4: 周長 | E4: =+PI()*E3 -> 4.0840704 | F4: m
D5: 杭全長 | E5: 31 | F5: m
D6: 1/β | E6: 4.945 | F6: m
D7: 杭本数 | E7: 3 | F7: 本
D8: 層番号 | E8: 層厚 (m) | F8: 周面支持力を考慮する層厚(m) | G8: 各層での 基準周面 支持力度 rfk (kN/m2) | H8: 分布幅 (m) | J8: 1/βを考慮 した分布幅 (m) | L8: 節点番号 | N8: 分布幅の周面 支持力度 rfk (kN/m) | O8: 各節点の周面支持力 Rfk (kN)
O12: 杭1本当り | P12: =+E7 -> 3
D13: ① | E13: 1.5 | F13: － | G13: 21 | H13: =+E3/2 -> 0.65 | J13: － | K13: － | L13: 98 | M13: 148 | N13: － | O13: － | P13: －
H14: =+E3 -> 1.3 | I14: =+E13-H13 -> 0.85 | J14: － | K14: － | L14: =+L13+1 -> 99 | M14: =+M13+1 -> 149 | N14: － | O14: － | P14: －
D15: ② | E15: 1.3 | F15: － | G15: 111 | I15: =+H14-I14 -> 0.45 | K15: －
H16: =+H14 -> 1.3 | I16: =+E15-I15 -> 0.85 | J16: － | K16: － | L16: =+L14+1 -> 100 | M16: =+M14+1 -> 150 | N16: － | O16: － | P16: －
D17: ③ | E17: 2.9 | F17: =+E13+E15+E17-E6 -> 0.755 | G17: 20 | I17: =+H16-I16 -> 0.45 | K17: －
H18: =+H16 -> 1.3 | J18: － | L18: =+L16+1 -> 101 | M18: =+M16+1 -> 151 | N18: － | O18: － | P18: －
H20: =+H18 -> 1.3 | I20: =+E17-I17-H18 -> 1.15 | J20: =+E3 -> 1.3 | K20: =+F17 -> 0.755 | L20: =+L18+1 -> 102 | M20: =+M18+1 -> 152 | N20: =+G17*K20+G21*K21 -> 29.5 | O20: =+E4*N20 -> 120.48008 | P20: =+E7*O20 -> 361.44023
D21: ④ | E21: 2.6 | F21: =+E21 -> 2.6 | G21: 96 | I21: =+H20-I20 -> 0.15 | K21: =+I21 -> 0.15
H22: =+H20 -> 1.3 | J22: =+J20 -> 1.3 | L22: =+L20+1 -> 103 | M22: =+M20+1 -> 153 | N22: =+G21*J22 -> 124.8 | O22: =+E4*N22 -> 509.69199 | P22: =+E7*O22 -> 1529.076
H24: =+H22 -> 1.3 | I24: =+E21-I21-H22 -> 1.15 | J24: =+J22 -> 1.3 | K24: =+I24 -> 1.15 | L24: =+L22+1 -> 104 | M24: =+M22+1 -> 154 | N24: =+G21*K24+G25*K25 -> 122.04 | O24: =+E4*N24 -> 498.41996 | P24: =+E7*O24 -> 1495.2599
D25: ⑤ | E25: 0.6 | F25: =+E25 -> 0.6 | G25: 77.6 | I25: =+H24-I24 -> 0.15 | K25: =+I25 -> 0.15
H26: =+H24 -> 1.3 | I26: =+E25-I25 -> 0.45 | J26: =+J24 -> 1.3 | K26: =+I26 -> 0.45 | L26: =+L24+1 -> 105 | M26: =+M24+1 -> 155 | N26: =+G25*K26+G27*K27 -> 157.32 | O26: =+E4*N26 -> 642.50596 | P26: =+E7*O26 -> 1927.5179
D27: ⑥ | E27: 9.5 | F27: =+E27 -> 9.5 | G27: 144 | I27: =+H26-I26 -> 0.85 | K27: =+I27 -> 0.85
H28: =+H26 -> 1.3 | J28: =+J26 -> 1.3 | L28: =+L26+1 -> 106 | M28: =+M26+1 -> 156 | N28: =+G27*J28 -> 187.2 | O28: =+E4*N28 -> 764.53799 | P28: =+E7*O28 -> 2293.614
H30: =+H28 -> 1.3 | J30: =+J28 -> 1.3 | L30: =+L28+1 -> 107 | M30: =+M28+1 -> 157 | N30: =+G27*J30 -> 187.2 | O30: =+E4*N30 -> 764.53799 | P30: =+E7*O30 -> 2293.614
H32: =+H30 -> 1.3 | J32: =+J30 -> 1.3 | L32: =+L30+1 -> 108 | M32: =+M30+1 -> 158 | N32: =+G27*J32 -> 187.2 | O32: =+E4*N32 -> 764.53799 | P32: =+E7*O32 -> 2293.614
H34: =+H32 -> 1.3 | J34: =+J32 -> 1.3 | L34: =+L32+1 -> 109 | M34: =+M32+1 -> 159 | N34: =+G27*J34 -> 187.2 | O34: =+E4*N34 -> 764.53799 | P34: =+E7*O34 -> 2293.614
H36: =+H34 -> 1.3 | J36: =+J34 -> 1.3 | L36: =+L34+1 -> 110 | M36: =+M34+1 -> 160 | N36: =+G27*J36 -> 187.2 | O36: =+E4*N36 -> 764.53799 | P36: =+E7*O36 -> 2293.614
H38: =+H36 -> 1.3 | J38: =+J36 -> 1.3 | L38: =+L36+1 -> 111 | M38: =+M36+1 -> 161 | N38: =+G27*J38 -> 187.2 | O38: =+E4*N38 -> 764.53799 | P38: =+E7*O38 -> 2293.614
H40: =+H38 -> 1.3 | I40: =+E27-I27-H28-H30-H32-H34-H36-H38 -> 0.85 | J40: =+J38 -> 1.3 | K40: =+I40 -> 0.85 | L40: =+L38+1 -> 112 | M40: =+M38+1 -> 162 | N40: =+G27*K40+G41*K41 -> 138.24 | O40: =+E4*N40 -> 564.5819 | P40: =+E7*O40 -> 1693.7457
D41: ⑦ | E41: 12.6 | F41: =+E41-E3 -> 11.3 | G41: 35.2 | I41: =+H42-I40 -> 0.45 | K41: =+I41 -> 0.45
H42: =+H40 -> 1.3 | J42: =+J40 -> 1.3 | L42: =+L40+1 -> 113 | M42: =+M40+1 -> 163 | N42: =+G41*J42 -> 45.76 | O42: =+E4*N42 -> 186.88706 | P42: =+E7*O42 -> 560.66119
H44: =+H42 -> 1.3 | J44: =+J42 -> 1.3 | L44: =+L42+1 -> 114 | M44: =+M42+1 -> 164 | N44: =+G41*J44 -> 45.76 | O44: =+E4*N44 -> 186.88706 | P44: =+E7*O44 -> 560.66119
H46: =+H44 -> 1.3 | J46: =+J44 -> 1.3 | L46: =+L44+1 -> 115 | M46: =+M44+1 -> 165 | N46: =+G41*J46 -> 45.76 | O46: =+E4*N46 -> 186.88706 | P46: =+E7*O46 -> 560.66119
H48: =+H46 -> 1.3 | J48: =+J46 -> 1.3 | L48: =+L46+1 -> 116 | M48: =+M46+1 -> 166 | N48: =+G41*J48 -> 45.76 | O48: =+E4*N48 -> 186.88706 | P48: =+E7*O48 -> 560.66119
H50: =+H48 -> 1.3 | J50: =+J48 -> 1.3 | L50: =+L48+1 -> 117 | M50: =+M48+1 -> 167 | N50: =+G41*J50 -> 45.76 | O50: =+E4*N50 -> 186.88706 | P50: =+E7*O50 -> 560.66119
H52: =+H50 -> 1.3 | J52: =+J50 -> 1.3 | L52: =+L50+1 -> 118 | M52: =+M50+1 -> 168 | N52: =+G41*J52 -> 45.76 | O52: =+E4*N52 -> 186.88706 | P52: =+E7*O52 -> 560.66119
H54: =+H52 -> 1.3 | J54: =+J52 -> 1.3 | L54: =+L52+1 -> 119 | M54: =+M52+1 -> 169 | N54: =+G41*J54 -> 45.76 | O54: =+E4*N54 -> 186.88706 | P54: =+E7*O54 -> 560.66119
H56: =+H54 -> 1.3 | J56: =+J54 -> 1.3 | L56: =+L54+1 -> 120 | M56: =+M54+1 -> 170 | N56: =+G41*J56 -> 45.76 | O56: =+E4*N56 -> 186.88706 | P56: =+E7*O56 -> 560.66119
H58: 1.2 | J58: =+F41-K41-J42-J44-J46-J48-J50-J52-J54-J56 -> 0.45 | L58: =+L56+1 -> 121 | M58: =+M56+1 -> 171 | N58: =+G41*J58 -> 15.84 | O58: =+E4*N58 -> 64.691676 | P58: =+E7*O58 -> 194.07503
H60: =+E41-I41-H42-H44-H46-H48-H50-H52-H54-H56-H58 -> 0.55 | J60: － | L60: =+L58+1 -> 122 | M60: =+M58+1 -> 172 | N60: － | O60: － | P60: －
D61: Σ | E61: =SUM(E13:E60) -> 31 | F61: =SUM(F13:F60) -> 24.755 | H61: =SUM(H12:H60) -> 31 | J61: =SUM(J18:J59) -> 25.15
...

Sheet 杭先端のばね定数（節点ばね）
C2: 3) | D2: 杭先端のばね定数（節点ばね）
E3: 節点番号 | F3: 杭先端の鉛直地盤ばね定数 | S3: 節点番号 | T3: 拘束方向 | U3: 第1勾配 | X3: 第2勾配 | AA3: 第3勾配 | AB3: 第1勾配 | AC3: 第2勾配 | AD3: 第3勾配
F4: Ktv(kN/m) | U4: 鉛直ばね | V4: 制限値 | X4: 鉛直ばね | Y4: 制限値 | AA4: 鉛直ばね | AB4: 鉛直ばね | AC4: 鉛直ばね | AD4: 鉛直ばね
F5: 短期（第１勾配） | G5: 短期（第２勾配） | U5: ＋側 | V5: ＋側 | W5: －側 | X5: ＋側 | Y5: ＋側 | Z5: －側 | AA5: ＋側 | AB5: －側 | AC5: －側 | AD5: －側
D6: 4P(左) | E6: 41 | F6: 218048 | G6: 58945 | S6: =+E6 -> 41 | T6: Y | U6: =+F6 -> 218048 | V6: =+先端支持力!F6 -> 4778.4 | X6: =+G6 -> 58945 | Y6: =+先端支持力!G6 -> 11149.5 | AA6: =+X6 -> 58945 | AB6: =+U6 -> 218048 | AC6: =+X6 -> 58945 | AD6: =+AA6 -> 58945
E7: 66 | F7: 109024 | G7: 29473 | S7: =+E7 -> 66 | T7: Y | U7: =+F7 -> 109024 | V7: =+先端支持力!F7 -> 2389.2 | X7: =+G7 -> 29473 | Y7: =+先端支持力!G7 -> 5574.8 | AA7: =+X7 -> 29473 | AB7: =+U7 -> 109024 | AC7: =+X7 -> 29473 | AD7: =+AA7 -> 29473
E8: 91 | F8: =+F6 -> 218048 | G8: =+G6 -> 58945 | S8: =+E8 -> 91 | T8: Y | U8: =+F8 -> 218048 | V8: =+先端支持力!F8 -> 4778.4 | X8: =+G8 -> 58945 | Y8: =+先端支持力!G8 -> 11149.5 | AA8: =+X8 -> 58945 | AB8: =+U8 -> 218048 | AC8: =+X8 -> 58945 | AD8: =+AA8 -> 58945
D9: 4P(右) | E9: 122 | F9: 327072 | G9: 88418 | S9: =+E9 -> 122 | T9: Y | U9: =+F9 -> 327072 | V9: =+先端支持力!F9 -> 7167.5 | X9: =+G9 -> 88418 | Y9: =+先端支持力!G9 -> 16724.3 | AA9: =+X9 -> 88418 | AB9: =+U9 -> 327072 | AC9: =+X9 -> 88418 | AD9: =+AA9 -> 88418
E10: 147 | F10: 218048 | G10: 58945 | S10: =+E10 -> 147 | T10: Y | U10: =+F10 -> 218048 | V10: =+先端支持力!F10 -> 4778.4 | X10: =+G10 -> 58945 | Y10: =+先端支持力!G10 -> 11149.5 | AA10: =+X10 -> 58945 | AB10: =+U10 -> 218048 | AC10: =+X10 -> 58945 | AD10: =+AA10 -> 58945
E11: 172 | F11: =+F9 -> 327072 | G11: =+G9 -> 88418 | S11: =+E11 -> 172 | T11: Y | U11: =+F11 -> 327072 | V11: =+先端支持力!F11 -> 7167.5 | X11: =+G11 -> 88418 | Y11: =+先端支持力!G11 -> 16724.3 | AA11: =+X11 -> 88418 | AB11: =+U11 -> 327072 | AC11: =+X11 -> 88418 | AD11: =+AA11 -> 88418

Sheet 先端支持力
C2: (6) | D2: 先端支持力
E3: 節点番号 | F3: 杭先端の鉛直地盤支持力
F4: (kN)
F5: 降伏点 | G5: 終局点
D6: 4P(左) | E6: 41 | F6: 4778.4 | G6: 11149.5
E7: 66 | F7: 2389.2 | G7: 5574.8
E8: 91 | F8: =+F6 -> 4778.4 | G8: =+G6 -> 11149.5
D9: 4P(右) | E9: 122 | F9: 7167.5 | G9: 16724.3
E10: 147 | F10: 4778.4 | G10: 11149.5
E11: 172 | F11: =+F9 -> 7167.5 | G11: =+G9 -> 16724.3
