Workbook
Name ___evp1: [1]ESピット!#REF!
Name ___evp2: [2]外房⑥ESピット!#REF!
Name ___evp3: '[3]２．EVピット'!#REF!
Name _C66093: #REF!
Name _C69093: #REF!
Name _C71093: #REF!
Name _C91093: #REF!
Name _evp22: #REF!
Name \: '[7]C5-基本計算（常時）'!#REF!
Name \\: '[7]C5-基本計算（常時）'!#REF!
Name \a: #REF!
Name \d: #N/A
Name \m: #REF!
Name \p: #N/A
Name \r: #REF!
Name \z: #REF!
Name §１: #REF!
Name a: [8]基本ﾃﾞｰﾀｼｰﾄ!$C$25
Name a: [8]基本ﾃﾞｰﾀｼｰﾄ!$C$25
Name a: [8]基本ﾃﾞｰﾀｼｰﾄ!$C$25
Name a: '[9]§３.（発進）平行'!$C$7
Name A111111111111: #REF!
Name aa: '[7]C5-基本計算（常時）'!#REF!
Name aaa: [10]設計条件!$C$13
Name ag: [11]せん断弾性波速度!$D$9
Name arufa: #REF!
Name Ａ通り側壁: #REF!
Name b: [8]基本ﾃﾞｰﾀｼｰﾄ!$C$27
Name basew: [10]設計条件!$C$13
Name bbb: [10]設計条件!$C$14
Name beeta: #REF!
Name C_ｽﾊﾟﾝ: '[7]C5-基本計算（常時）'!#REF!
Name C_ｽﾊﾟﾝ: '[7]C5-基本計算（常時）'!#REF!
Name C_ｽﾊﾟﾝ: '[7]C5-基本計算（常時）'!#REF!
Name C_ｽﾊﾟﾝ: '[12]C3-基本1'!$AF$53
Name C_ｽﾊﾟﾝL: '[7]C5-基本計算（常時）'!#REF!
Name C_ｽﾊﾟﾝR: '[7]C5-基本計算（常時）'!#REF!
Name ccc: [2]外房⑥ESピット!#REF!
Name DATA: '[9]§４.（発進）擁壁横、松戸'!$A$1:$IV$65536
Name DATA1: #REF!
Name DATA保存: #REF!
Name ddd: #REF!
Name df: [10]設計条件!$C$14
Name dgdkgkgk: [13]固死!#REF!
Name dghkdghkdg: '[7]C5-基本計算（常時）'!#REF!
Name dgkd: '[7]C5-基本計算（常時）'!#REF!
Name dgkdgkdg: [13]固死!#REF!
Name dgkhkdgkg: [13]固死!#REF!
Name dgkhkhgkgdh: '[7]C5-基本計算（常時）'!#REF!
Name djyfurur: '[7]C5-基本計算（常時）'!#REF!
Name dkgdghkry: '[7]C5-基本計算（常時）'!#REF!
Name e: [8]基本ﾃﾞｰﾀｼｰﾄ!$C$29
Name EA17W2: [14]列車荷重等値等分布荷重!$F$7:$I$18
Name EA17W2l: [14]列車荷重等値等分布荷重!$F$7:$F$18
Name EA17W2S: [14]列車荷重等値等分布荷重!$F$7:$I$7
Name ee: '[15]×構造計算 (表層厚66.50m)'!$K$334
Name eee: '[15]×構造計算 (表層厚66.50m)'!$H$322
Name eie6iyre: '[7]C5-基本計算（常時）'!#REF!
Name eiue6rre6: '[7]C5-基本計算（常時）'!#REF!
Name Excel_BuiltIn__FilterDatabase_4: #REF!

Sheet 表紙
C3: 研開構 第１７６号
C7: （26債）新幹線構造物の地震時応答特性解析
C15: 特 殊 構 造 物 検 討 書
C17: 【今町橋りょう4P】
K34: 2026年 10月
K37: 照査技術者 | O37: 主任技術者 | S37: 照 査 者 | W37: 設 計 者
C44: 東日本旅客鉄道株式会社 JR東日本研究開発センター
C46: ジェイアール東日本コンサルタンツ株式会社

Sheet 目次
A1: ― 目 次 ―
AB3: 頁
A5: §1.設計の目的及び一般条件 | L5: ------------------------------------------------------------------------------------------------------------ | AB5: 1 | AC5: － | AD5: 1
C6: 1. | D6: 設計の目的 | I6: ------------------------------------------------------------------------------------------------------------ | AB6: 1 | AC6: － | AD6: 1
C7: 2. | D7: 適用基準及び使用プログラム | N7: ------------------------------------------------------------------------------------------------------------ | AB7: 1 | AC7: － | AD7: 1
C8: 3. | D8: 一般条件 | H8: ------------------------------------------------------------------------------------------------------------ | AB8: 1 | AC8: － | AD8: 2
C9: 4. | D9: 設計作用 | H9: ------------------------------------------------------------------------------------------------------------ | AB9: 1 | AC9: － | AD9: 3
C10: 5. | D10: 地盤条件 | H10: ------------------------------------------------------------------------------------------------------------ | AB10: 1 | AC10: － | AD10: 4
C11: 6. | D11: 上部工荷重 | I11: ------------------------------------------------------------------------------------------------------------ | AB11: 1 | AC11: － | AD11: 4
A13: §2.設計総括表 | H13: ------------------------------------------------------------------------------------------------------------ | AB13: 2 | AC13: － | AD13: 1
A15: §3.線路直角方向の検討 | K15: ------------------------------------------------------------------------------------------------------------ | AB15: 3 | AC15: － | AD15: 1
C16: 1. | D16: 基本計算 | H16: ------------------------------------------------------------------------------------------------------------ | AB16: 3 | AC16: － | AD16: 1 | AE16: ～ | AF16: =+AD17-1 -> 38
C17: 2. | D17: 地盤のモデル化 | J17: ------------------------------------------------------------------------------------------------------------ | AB17: 3 | AC17: － | AD17: 39 | AE17: ～ | AF17: =+AD18-1 -> 116
C18: 3. | D18: 荷重計算 | H18: ------------------------------------------------------------------------------------------------------------ | AB18: 3 | AC18: － | AD18: 117 | AE18: ～ | AF18: =+AD19-1 -> 119
C19: 4. | D19: 荷重図 | H19: ------------------------------------------------------------------------------------------------------------ | AB19: 3 | AC19: － | AD19: 120 | AE19: ～ | AF19: =+AD20-1 -> 125
C20: 5. | D20: 組合せ | H20: ------------------------------------------------------------------------------------------------------------ | AB20: 3 | AC20: － | AD20: 126
C21: 6. | D21: 解析条件 | H21: ------------------------------------------------------------------------------------------------------------ | AB21: 3 | AC21: － | AD21: 127
C22: 7. | D22: 解析結果 | H22: ------------------------------------------------------------------------------------------------------------ | AB22: 3 | AC22: － | AD22: 128 | AE22: ～ | AF22: =+AD23-1 -> 173
C23: 8. | D23: JRSNAP 入力データ出力 | L23: ------------------------------------------------------------------------------------------------------------ | AB23: 3 | AC23: － | AD23: 174 | AE23: ～ | AF23: 224
A25: §4.財産図 | AB25: 4 | AC25: － | AD25: 1 | AE25: ～ | AF25: 6

Sheet §1.設計の目的及び一般条件
B2: §1.設計の目的及び一般条件
C4: 1.設計の目的
D6: 高架橋の土木構造物の地震時応答を算出するには，個々の土木構造物が有する固有周期等
D7: の特性値が必要である．本件では，上越新幹線構造物について，財産図および地質柱状図の
D8: 情報に基づく構造解析モデルを作成し，等価固有周期と降伏震度を算定する．
C10: 2.適用基準及び使用プログラム
D12: 2.1 設計標準
E14: ・ | F14: 鉄道構造物等設計標準（コンクリート構造物）【 平成16年 4月版 】 | AF14: ・ | AG14: 鉄道構造物等設計標準（土構造物）【 平成19年 1月版 】 | BE14: [ 本建第45号 平成21年 7月 ]
AD15: [ 本建第463号 平成17年 3月 ] | AH15: ⇒ | AI15: 【 土標準 】と略記
G16: ⇒ | H16: 【 RC標準 】と略記
E18: ・ | F18: 鉄道構造物等設計標準（鋼・合成構造物）【 平成21年 7月版 】
AD19: [ 本建第304号 平成21年 7月 ]
G20: ⇒ | H20: 【 鋼標準 】と略記
E22: ・ | F22: 鉄道構造物等設計標準（基礎構造物）【 平成24年 1月版 】
AD23: [ 本建第504号 平成26年 3月 ]
G24: ⇒ | H24: 【 基礎標準(H24) 】と略記
E26: ・ | F26: 鉄道構造物等設計標準（耐震設計）【 平成24年 9月版 】
AD27: [ 本建第501号 平成26年 3月 ]
G28: ⇒ | H28: 【 耐震標準 】と略記
E30: ・ | F30: 鉄道構造物等設計標準（変位制限）【 平成18年 2月版 】
AD31: [ 本建第123号 平成19年 6月 ]
G32: ⇒ | H32: 【 変位標準 】と略記
D34: 2.2 手引き
E36: ・ | F36: 鉄道構造物等設計標準（耐震設計）【 平成24年版 】橋梁および高架橋耐震照査の手引き
AD37: [ 鉄道総研 平成29年 3月 ]
G38: ⇒ | H38: 【 耐震照査の手引き 】と略記
E40: ・ | F40: 鉄道構造物等設計標準（基礎構造物）【 平成24年版 】基礎構造物の性能照査の手引き
AD41: [ 鉄道総研 平成30年 7月 ]
G42: ⇒ | H42: 【 基礎照査の手引き 】と略記
E44: ・ | F44: 鉄道構造物等設計標準（基礎構造物）【 平成24年 1月版 】杭体設計の手引き
AD45: [ 鉄道総研 平成27年10月 ]
G46: ⇒ | H46: 【 杭体の手引き 】と略記
D48: 2.3 使用プログラム
F50: JRSNAP Ver.5.2-L03：公益財団法人 鉄道総合技術研究所
C54: 3.一般条件
D56: ・ | E56: 線名 | H56: ： | I56: 上越新幹線
D57: ・ | E57: 構造形式 | H57: ： | I57: ＲＣ馬桁式橋脚
D58: ・ | E58: 軌道構造 | H58: ： | I58: 直結軌道
D59: ・ | E59: 基礎形式 | H59: ： | I59: 杭基礎φ1300 (オールケーシング工法)
C63: 4.設計作用
...

Sheet §2.設計総括表
A2: §2.設計総括表
C4: 解析ケース | D4: Case | F4: 1 | G4: 2
D5: 名称 | F5: ρm＝1.0,αf＝1.0 右押し(→) | G5: ρm＝1.0,αf＝1.0 左押し(←)
D6: αf | F6: 1 | G6: 1
D7: ρm | F7: 1 | G7: 1
C8: 降伏点 | D8: 初期降伏震度 | E8: Khy | F8: 0.25 | G8: 0.255
D9: 全体系折曲点震度 | E9: Kheq | F9: 0.273 | G9: 0.276
D10: 降伏変位 | E10: δeq(mm) | F10: 41.5 | G10: 42.2
D11: 降伏個所 | F11: 左く体・損傷レベル | G11: 左く体・損傷レベル
D12: 等価固有周期 | E12: Teq(sec) | F12: 0.78 | G12: 0.782
C13: 復旧性 | D13: 応答塑性率 | E13: μ | F13: 7.04 | G13: 6.93
D14: 最大応答変位 | E14: δmax(mm) | F14: =+F13*F10 -> 292.16 | G14: =+G13*G10 -> 292.446
D15: 最大応答震度 | E15: Khmax | F15: 0.297 | G15: 0.297
D16: L1地震動 | E16: KhL1 | F16: 0.378 | G16: 0.378
C17: 安全性 | D17: 応答塑性率 | E17: μ | F17: 9.29 | G17: 9.16
D18: 最大応答変位 | E18: δmax(mm) | F18: =+F17*F10 -> 385.535 | G18: =+G17*G10 -> 386.552
D19: 最大応答震度 | E19: Khmax | F19: =+F15 -> 0.297 | G19: =+G15 -> 0.297

Sheet §3.線路直角方向の計算
A2: §3.線路直角方向の計算
B4: 1.基本計算
C6: (1) | D6: 構造解析モデル
D8: Case1 | G8: ρm＝1.0,αf＝1.0 右押し（→）
D12: Case2 | G12: ρm＝1.0,αf＝1.0 左押し（←）
C14: ※ | D14: Case1に対して異なるデータのみ記載する。

Sheet 断面積および断面二次モーメント
C2: (2) | D2: 断面積および断面二次モーメント
C4: 1) | D4: 馬桁
E6: A | F6: ＝ | G6: ∞ | I6: m2 | L6: I | M6: ＝ | N6: ∞ | P6: m4 | R6: （剛域）
C8: 2) | D8: く体(4P左)
E10: A | F10: ＝ | G10: 8 | J10: × | K10: 1.7 | S10: ＝ | T10: =+ROUND(G10*K10,3) -> 13.6 | W10: m2
E12: I | F12: ＝ | G12: 0.083333333 | J12: × | K12: =+G10 -> 8 | N12: × | O12: =+K10 -> 1.7 | R12: 3 | S12: ＝ | T12: =+ROUND(G12*K12*O12^R12,5) -> 3.27533 | W12: m4
C14: 3) | D14: く体(4P右)
E16: A | F16: ＝ | G16: 8 | J16: × | K16: 2 | S16: ＝ | T16: =+ROUND(G16*K16,3) -> 16 | W16: m2
E18: I | F18: ＝ | G18: 0.083333333 | J18: × | K18: =+G16 -> 8 | N18: × | O18: =+K16 -> 2 | R18: 3 | S18: ＝ | T18: =+ROUND(G18*K18*O18^R18,5) -> 5.33333 | W18: m4
C20: 4) | D20: フーチング
E22: A | F22: ＝ | G22: ∞ | I22: m2 | L22: I | M22: ＝ | N22: ∞ | P22: m4 | R22: （剛域）
C24: ※ | D24: 軸線重心位置
N25: (4P左)
N26: =SUM(J27:T27) -> 8
J27: 3.05 | N27: 1.9 | R27: =+J27 -> 3.05
E29: 0.7
I30: ① | N30: ② | Q30: ③
E32: 2.1 | I32: ④
E37: 計算式 | Q37: A(m2) | T37: y(m) | W37: A･y(m3)
E38: ① | F38: 0.5 | I38: × | J38: =+J27 -> 3.05 | M38: × | N38: =+E29 -> 0.7 | Q38: =+ROUND(F38*J38*N38,3) -> 1.068 | T38: =+ROUND(E32+E29/3,3) -> 2.333 | W38: =+ROUND(Q38*T38,3) -> 2.492
E39: ② | F39: =+N27 -> 1.9 | I39: × | J39: =+E29 -> 0.7 | Q39: =+ROUND(F39*J39,3) -> 1.33 | T39: =+ROUND(E32+E29/2,3) -> 2.45 | W39: =+ROUND(Q39*T39,3) -> 3.259
E40: ③ | F40: 0.5 | I40: × | J40: =+R27 -> 3.05 | M40: × | N40: =+E29 -> 0.7 | Q40: =+ROUND(F40*J40*N40,3) -> 1.068 | T40: =+ROUND(E32+E29/3,3) -> 2.333 | W40: =+ROUND(Q40*T40,3) -> 2.492
E41: ④ | F41: =+N26 -> 8 | I41: × | J41: =+E32 -> 2.1 | Q41: =+ROUND(F41*J41,3) -> 16.8 | T41: =+ROUND(E32/2,3) -> 1.05 | W41: =+ROUND(Q41*T41,3) -> 17.64
E42: Σ | Q42: =SUM(Q38:S41) -> 20.266 | W42: =SUM(W38:Z41) -> 25.883
E44: yG | G44: ＝ | H44: A･y | J44: ＝ | K44: =+W42 -> 25.883 | N44: ＝ | O44: =+ROUND(K44/K45,2) -> 1.28 | R44: m
H45: A | K45: =+Q42 -> 20.266
N49: (4P右)
N50: =SUM(J51:T51) -> 10
J51: 3.9 | N51: 2.2 | R51: =+J51 -> 3.9
E53: 0.7
I54: ① | N54: ② | Q54: ③
E56: 2.1 | I56: ④
E61: 計算式 | Q61: A(m2) | T61: y(m) | W61: A･y(m3)
E62: ① | F62: 0.5 | I62: × | J62: =+J51 -> 3.9 | M62: × | N62: =+E53 -> 0.7 | Q62: =+ROUND(F62*J62*N62,3) -> 1.365 | T62: =+ROUND(E56+E53/3,3) -> 2.333 | W62: =+ROUND(Q62*T62,3) -> 3.185
E63: ② | F63: =+N51 -> 2.2 | I63: × | J63: =+E53 -> 0.7 | Q63: =+ROUND(F63*J63,3) -> 1.54 | T63: =+ROUND(E56+E53/2,3) -> 2.45 | W63: =+ROUND(Q63*T63,3) -> 3.773
E64: ③ | F64: 0.5 | I64: × | J64: =+R51 -> 3.9 | M64: × | N64: =+E53 -> 0.7 | Q64: =+ROUND(F64*J64*N64,3) -> 1.365 | T64: =+ROUND(E56+E53/3,3) -> 2.333 | W64: =+ROUND(Q64*T64,3) -> 3.185
E65: ④ | F65: =+N50 -> 10 | I65: × | J65: =+E56 -> 2.1 | Q65: =+ROUND(F65*J65,3) -> 21 | T65: =+ROUND(E56/2,3) -> 1.05 | W65: =+ROUND(Q65*T65,3) -> 22.05
E66: Σ | Q66: =SUM(Q62:S65) -> 25.27 | W66: =SUM(W62:Z65) -> 32.193
E68: yG | G68: ＝ | H68: A･y | J68: ＝ | K68: =+W66 -> 32.193 | N68: ＝ | O68: =+ROUND(K68/K69,2) -> 1.27 | R68: m
H69: A | K69: =+Q66 -> 25.27
...

Sheet コンクリートの弾性係数
C2: (3) | D2: コンクリートの弾性係数
C4: 1) | D4: く体
D6: ・ | E6: 設計基準強度 | K6: ： | L6: f'ck | N6: ＝ | O6: 21 | Q6: N/mm2 | S6: （財産図より） | AK6: 性能照査
AK7: コンクリート強度 | AL7: 設計圧縮強度 | AM7: 設計引張強度 | AN7: 設計付着強度 | AO7: ヤング係数 | AP7: コンクリート強度 | AQ7: 設計圧縮強度 | AR7: 設計引張強度 | AS7: 設計付着強度
D8: ・ | E8: ヤング係数 | K8: ： | L8: Ec | N8: ＝ | O8: =VLOOKUP(O6,AK9:AT15,5) -> 23.5 | Q8: × | R8: 106 | T8: kN/m2 | AK8: γc=1.0の場合 | AL8: f'cd | AM8: ftd | AN8: fbod | AO8: Eo(kN/mm2) | AP8: γc=1.3の場合 | AQ8: f'cd | AR8: ftd | AS8: fbod(N/mm2)
AK9: 18 | AL9: 18 | AM9: 1.6 | AN9: 1.9 | AO9: 22 | AP9: 18 | AQ9: 13.8 | AR9: 1.2 | AS9: 1.5
C10: 2) | D10: フーチング | AK10: 21 | AL10: 21 | AM10: 1.8 | AN10: 2.1 | AO10: 23.5 | AP10: 21 | AQ10: 16.2 | AR10: 1.3 | AS10: 1.6
AK11: 24 | AL11: 24 | AM11: 1.9 | AN11: 2.3 | AO11: 25 | AP11: 24 | AQ11: 18.5 | AR11: 1.5 | AS11: 1.8
D12: ・ | E12: 設計基準強度 | K12: ： | L12: f'ck | N12: ＝ | O12: 21 | Q12: N/mm2 | S12: （財産図より） | AK12: 27 | AL12: 27 | AM12: 2.1 | AN12: 2.5 | AO12: 26.5 | AP12: 27 | AQ12: 20.8 | AR12: 1.6 | AS12: 1.9
AK13: 30 | AL13: 30 | AM13: 2.2 | AN13: 2.7 | AO13: 28 | AP13: 30 | AQ13: 23.1 | AR13: 1.7 | AS13: 2.1
D14: ・ | E14: ヤング係数 | K14: ： | L14: Ec | N14: ＝ | O14: =VLOOKUP(O12,AK9:AT15,5) -> 23.5 | Q14: × | R14: 106 | T14: kN/m2 | AK14: 40 | AL14: 40 | AM14: 2.7 | AN14: 3.3 | AO14: 31 | AP14: 40 | AQ14: 30.8 | AR14: 2.1 | AS14: 2.5
AK15: 50 | AL15: 50 | AM15: 3.1 | AN15: 3.8 | AO15: 33
C16: 3) | D16: 杭
D18: ・ | E18: 設計基準強度 | K18: ： | L18: ｆ'ck | N18: ＝ | O18: 30 | Q18: N/mm2 | S18: （財産図より）
L19: ｆ'ck | N19: × | O19: ρc | R19: ＝ | S19: =O18 -> 30 | U19: × | V19: 0.7 | Y19: ＝ | Z19: =ROUND(S19*V19,1) -> 21 | AB19: N/mm2
D21: ・ | E21: ヤング係数 | K21: ： | L21: Ｅc | N21: ＝ | O21: =VLOOKUP(O18,AK9:AS15,5) -> 28 | Q21: × | R21: 106 | T21: kN/m2
L22: Ｅc | N22: × | O22: ρc | R22: ＝ | S22: =O21 -> 28 | U22: × | V22: 107 | X22: × | Y22: 0.8
R23: ＝ | S23: =ROUND(S22*Y22,2) -> 22.4 | U23: × | V23: 106 | X23: kN/m2
E25: ※1) | F25: ρc | G25: ： | H25: コンクリートの施工条件に関する施工修正係数
H26: 今設計では、水中施工・泥水比重管理条件なしとして設定する.

Sheet 材料非線形特性
C2: (4) | D2: 材料非線形特性
C4: 1) | D4: く体(4P左)
D21: 断面番号 | F21: b | I21: h | L21: 軸方向鉄筋 | U21: せん断補強鉄筋
L22: 部材上面 | O22: 鉄筋径 | R22: 本数 | U22: 鉄筋径 | X22: 本数 | AA22: 間隔
L23: からの
L24: 鉄筋位置
F25: (mm) | I25: (mm) | L25: (mm) | O25: (mm) | R25: (本) | U25: (mm) | X25: (本) | AA25: (mm)
D26: 1 | F26: 8000 | I26: 1700 | L26: 100 | O26: 19 | R26: 63 | U26: 13 | X26: 17 | AA26: 150 | AK26: 1 | AL26: =+L26 -> 100 | AM26: =+O26 -> 19 | AN26: =+R26 -> 63
L27: 350 | O27: 19 | R27: 2 | AK27: 2 | AL27: =+L27 -> 350 | AM27: =+O27 -> 19 | AN27: =+R27 -> 2
L28: =+L27+250 -> 600 | O28: 19 | R28: 2 | AK28: 3 | AL28: =+L28 -> 600 | AM28: =+O28 -> 19 | AN28: =+R28 -> 2
L29: =+L28+250 -> 850 | O29: 19 | R29: 2 | AK29: 4 | AL29: =+L29 -> 850 | AM29: =+O29 -> 19 | AN29: =+R29 -> 2
L30: =+L29+250 -> 1100 | O30: 19 | R30: 2 | AK30: 5 | AL30: =+L30 -> 1100 | AM30: =+O30 -> 19 | AN30: =+R30 -> 2
L31: =+L30+250 -> 1350 | O31: 19 | R31: 2 | AK31: 6 | AL31: =+L31 -> 1350 | AM31: =+O31 -> 19 | AN31: =+R31 -> 2
L32: =+L31+250 -> 1600 | O32: 19 | R32: 63 | AK32: 7 | AL32: =+L32 -> 1600 | AM32: =+O32 -> 19 | AN32: =+R32 -> 63
C36: 2) | D36: く体(4P右)
AL48: 13 | AM48: 126.7
AL49: 16 | AM49: 198.6
AL50: 19 | AM50: 286.5
AL51: 22 | AM51: 387.1
AL52: 25 | AM52: 506.7
AL53: 29 | AM53: 642.4
D54: 断面番号 | F54: b | I54: h | L54: 軸方向鉄筋 | U54: せん断補強鉄筋 | AL54: 32 | AM54: 794.2
L55: 部材上面 | O55: 鉄筋径 | R55: 本数 | U55: 鉄筋径 | X55: ※本数 | AA55: 間隔 | AL55: 38 | AM55: 1140
L56: からの
L57: 鉄筋位置
F58: (mm) | I58: (mm) | L58: (mm) | O58: (mm) | R58: (本) | U58: (mm) | X58: (本) | AA58: (mm)
D59: 2 | F59: 8000 | I59: 2000 | L59: 100 | O59: 29 | R59: 63 | U59: 19 | X59: =+R75 -> 12.397906 | AA59: 150 | AE59: ctc | AG59: 150 | AK59: 1 | AL59: =+L59 -> 100 | AM59: =+O59 -> 29 | AN59: =+R59 -> 63
L60: 400 | O60: 29 | R60: 2 | AE60: ctc | AG60: 150 | AK60: 2 | AL60: =+L60 -> 400 | AM60: =+O60 -> 29 | AN60: =+R60 -> 2
L61: =+L60+300 -> 700 | O61: 29 | R61: 2 | AK61: 3 | AL61: =+L61 -> 700 | AM61: =+O61 -> 29 | AN61: =+R61 -> 2
L62: =+L61+300 -> 1000 | O62: 29 | R62: 2 | AK62: 4 | AL62: =+L62 -> 1000 | AM62: =+O62 -> 29 | AN62: =+R62 -> 2
L63: =+L62+300 -> 1300 | O63: 29 | R63: 2 | AK63: 5 | AL63: =+L63 -> 1300 | AM63: =+O63 -> 29 | AN63: =+R63 -> 2
L64: =+L63+300 -> 1600 | O64: 29 | R64: 2 | AK64: 6 | AL64: =+L64 -> 1600 | AM64: =+O64 -> 29 | AN64: =+R64 -> 2
L65: =+L64+300 -> 1900 | O65: 29 | R65: 63 | AK65: 7 | AL65: =+L65 -> 1900 | AM65: =+O65 -> 29 | AN65: =+R65 -> 63
F67: ※ | G67: せん断補強鉄筋
G68: 19 | I68: － | J68: 2 | L68: 本 | M68: ＝ | N68: =+SUMIF(AL48:AL55,G68,AM48:AM55) -> 286.5 | Q68: × | R68: =+J68 -> 2 | T68: ＝ | U68: =+N68*R68 -> 573 | X68: mm2
G69: 16 | I69: － | J69: 15 | L69: 本 | M69: ＝ | N69: =+SUMIF(AL48:AL55,G69,AM48:AM55) -> 198.6 | Q69: × | R69: =+J69 -> 15 | T69: ＝ | U69: =+N69*R69 -> 2979 | X69: mm2
S72: Σ | T72: ＝ | U72: =SUM(U68:W69) -> 3552 | X72: mm2
G74: 19 | I74: に換算
G75: n | I75: ＝ | J75: =+U72 -> 3552 | M75: / | N75: =+SUMIF(AL48:AL55,G74,AM48:AM55) -> 286.5 | Q75: ＝ | R75: =+J75/N75 -> 12.397906 | U75: 本
C79: 3) | D79: 杭①(4P左)
...

Sheet 要素の構成
C2: (5) | D2: 要素の構成
D3: 部材 | F3: 要素 | L3: 非線形 番号 | M3: 断面 番号 | N3: 要素 種別 | Q3: Ａ (m2) | T3: Ｉ (m4) | W3: Ｅ (kN/m2) | AB3: 適用
F4: 要素 番号 | H4: 節点番号
H5: ｉ端 | J5: ｊ端
D6: 馬桁 | F6: 1 | H6: 1 | J6: 2 | N6: 剛域 | Q6: 1000 | T6: 1000 | W6: 2 | Y6: × | Z6: 108
F7: =+F6+1 -> 2 | H7: 2 | J7: 3 | N7: 剛域 | Q7: 1000 | T7: 1000 | W7: =W6 -> 2 | Y7: × | Z7: 108
F8: =+F7+1 -> 3 | H8: 3 | J8: 4 | N8: 剛域 | Q8: 1000 | T8: 1000 | W8: =W7 -> 2 | Y8: × | Z8: 108
F9: =+F8+1 -> 4 | H9: 2 | J9: 5 | N9: 剛域 | Q9: 1000 | T9: 1000 | W9: =W8 -> 2 | Y9: × | Z9: 107
F10: =+F9+1 -> 5 | H10: 3 | J10: 8 | N10: 剛域 | Q10: 1000 | T10: 1000 | W10: =W9 -> 2 | Y10: × | Z10: 107
D11: ※1 | F11: =+F10+1 -> 6 | H11: 5 | J11: 6 | N11: 剛域 | Q11: 1000 | T11: 1000 | W11: 2.35 | Y11: × | Z11: 107
F12: =+F11+1 -> 7 | H12: 6 | J12: 7 | N12: 剛域 | Q12: 1000 | T12: 1000 | W12: =+W11 -> 2.35 | Y12: × | Z12: 107
F13: =+F12+1 -> 8 | H13: 7 | J13: 11 | L13: 1 | M13: 1 | N13: Ｍ～θ | Q13: ---- | T13: ---- | W13: =+W12 -> 2.35 | Y13: × | Z13: 107 | AB13: 抜出し考慮
D14: ※2 | F14: =+F13+1 -> 9 | H14: 8 | J14: 9 | N14: 剛域 | Q14: 1000 | T14: 1000 | W14: =+W13 -> 2.35 | Y14: × | Z14: 107
F15: =+F14+1 -> 10 | H15: 9 | J15: 10 | N15: 剛域 | Q15: 1000 | T15: 1000 | W15: =+W14 -> 2.35 | Y15: × | Z15: 107
F16: =+F15+1 -> 11 | H16: 10 | J16: 92 | L16: =+L13+1 -> 2 | M16: 2 | N16: Ｍ～θ | Q16: ---- | T16: ---- | W16: =+W15 -> 2.35 | Y16: × | Z16: 107 | AB16: 抜出し考慮
D17: ※3 | F17: =+F16+1 -> 12 | H17: 11 | J17: 14 | N17: 剛域 | Q17: 1000 | T17: 1000 | W17: =+W16 -> 2.35 | Y17: × | Z17: 107
F18: =+F17+1 -> 13 | H18: 12 | J18: 13 | N18: 剛域 | Q18: 1000 | T18: 1000 | W18: =+W17 -> 2.35 | Y18: × | Z18: 107
F19: =+F18+1 -> 14 | H19: 13 | J19: 14 | N19: 剛域 | Q19: 1000 | T19: 1000 | W19: =+W18 -> 2.35 | Y19: × | Z19: 107
F20: =+F19+1 -> 15 | H20: 14 | J20: 15 | N20: 剛域 | Q20: 1000 | T20: 1000 | W20: =+W19 -> 2.35 | Y20: × | Z20: 107
F21: =+F20+1 -> 16 | H21: 15 | J21: 16 | N21: 剛域 | Q21: 1000 | T21: 1000 | W21: =+W20 -> 2.35 | Y21: × | Z21: 107
D22: 杭(左1列目) | F22: =+F21+1 -> 17 | H22: 13 | J22: 17 | N22: 剛域 | Q22: 1000 | T22: 1000 | W22: =+W21 -> 2.35 | Y22: × | Z22: 107
F23: =+F22+1 -> 18 | H23: =+J22 -> 17 | J23: =+J22+1 -> 18 | L23: =+L16+1 -> 3 | M23: 3 | N23: Ｍ～φ | Q23: ---- | T23: ---- | W23: 2.24 | Y23: × | Z23: 107 | AB23: 抜出し考慮
F24: =+F23+1 -> 19 | H24: =+H23+1 -> 18 | J24: =+J23+1 -> 19 | L24: =+L23+1 -> 4 | M24: =+M23 -> 3 | N24: Ｍ～φ | Q24: ---- | T24: ---- | W24: =W23 -> 2.24 | Y24: × | Z24: 107
F25: =+F24+1 -> 20 | H25: =+H24+1 -> 19 | J25: =+J24+1 -> 20 | L25: =+L24+1 -> 5 | M25: 4 | N25: Ｍ～φ | Q25: ---- | T25: ---- | W25: =W24 -> 2.24 | Y25: × | Z25: 107
F26: =+F25+1 -> 21 | H26: =+H25+1 -> 20 | J26: =+J25+1 -> 21 | L26: =+L25+1 -> 6 | M26: =+M25 -> 4 | N26: Ｍ～φ | Q26: ---- | T26: ---- | W26: =W25 -> 2.24 | Y26: × | Z26: 107
F27: =+F26+1 -> 22 | H27: =+H26+1 -> 21 | J27: =+J26+1 -> 22 | L27: =+L26+1 -> 7 | M27: =+M26 -> 4 | N27: Ｍ～φ | Q27: ---- | T27: ---- | W27: =W26 -> 2.24 | Y27: × | Z27: 107
F28: =+F27+1 -> 23 | H28: =+H27+1 -> 22 | J28: =+J27+1 -> 23 | L28: =+L27+1 -> 8 | M28: =+M27 -> 4 | N28: Ｍ～φ | Q28: ---- | T28: ---- | W28: =W27 -> 2.24 | Y28: × | Z28: 107
F29: =+F28+1 -> 24 | H29: =+H28+1 -> 23 | J29: =+J28+1 -> 24 | L29: =+L28+1 -> 9 | M29: =+M28 -> 4 | N29: Ｍ～φ | Q29: ---- | T29: ---- | W29: =W28 -> 2.24 | Y29: × | Z29: 107
F30: =+F29+1 -> 25 | H30: =+H29+1 -> 24 | J30: =+J29+1 -> 25 | L30: =+L29+1 -> 10 | M30: 5 | N30: Ｍ～φ | Q30: ---- | T30: ---- | W30: =W29 -> 2.24 | Y30: × | Z30: 107
F31: =+F30+1 -> 26 | H31: =+H30+1 -> 25 | J31: =+J30+1 -> 26 | L31: =+L30+1 -> 11 | M31: =+M30 -> 5 | N31: Ｍ～φ | Q31: ---- | T31: ---- | W31: =W30 -> 2.24 | Y31: × | Z31: 107
F32: =+F31+1 -> 27 | H32: =+H31+1 -> 26 | J32: =+J31+1 -> 27 | L32: =+L31+1 -> 12 | M32: =+M31 -> 5 | N32: Ｍ～φ | Q32: ---- | T32: ---- | W32: =W31 -> 2.24 | Y32: × | Z32: 107
F33: =+F32+1 -> 28 | H33: =+H32+1 -> 27 | J33: =+J32+1 -> 28 | L33: =+L32+1 -> 13 | M33: =+M32 -> 5 | N33: Ｍ～φ | Q33: ---- | T33: ---- | W33: =W32 -> 2.24 | Y33: × | Z33: 107
F34: =+F33+1 -> 29 | H34: =+H33+1 -> 28 | J34: =+J33+1 -> 29 | L34: =+L33+1 -> 14 | M34: =+M33 -> 5 | N34: Ｍ～φ | Q34: ---- | T34: ---- | W34: =W33 -> 2.24 | Y34: × | Z34: 107
F35: =+F34+1 -> 30 | H35: =+H34+1 -> 29 | J35: =+J34+1 -> 30 | L35: =+L34+1 -> 15 | M35: =+M34 -> 5 | N35: Ｍ～φ | Q35: ---- | T35: ---- | W35: =W34 -> 2.24 | Y35: × | Z35: 107
F36: =+F35+1 -> 31 | H36: =+H35+1 -> 30 | J36: =+J35+1 -> 31 | L36: =+L35+1 -> 16 | M36: 6 | N36: Ｍ～φ | Q36: ---- | T36: ---- | W36: =W35 -> 2.24 | Y36: × | Z36: 107
F37: =+F36+1 -> 32 | H37: =+H36+1 -> 31 | J37: =+J36+1 -> 32 | L37: =+L36+1 -> 17 | M37: =+M36 -> 6 | N37: Ｍ～φ | Q37: ---- | T37: ---- | W37: =W36 -> 2.24 | Y37: × | Z37: 107
F38: =+F37+1 -> 33 | H38: =+H37+1 -> 32 | J38: =+J37+1 -> 33 | L38: =+L37+1 -> 18 | M38: =+M37 -> 6 | N38: Ｍ～φ | Q38: ---- | T38: ---- | W38: =W37 -> 2.24 | Y38: × | Z38: 107
F39: =+F38+1 -> 34 | H39: =+H38+1 -> 33 | J39: =+J38+1 -> 34 | L39: =+L38+1 -> 19 | M39: =+M38 -> 6 | N39: Ｍ～φ | Q39: ---- | T39: ---- | W39: =W38 -> 2.24 | Y39: × | Z39: 107
F40: =+F39+1 -> 35 | H40: =+H39+1 -> 34 | J40: =+J39+1 -> 35 | L40: =+L39+1 -> 20 | M40: =+M39 -> 6 | N40: Ｍ～φ | Q40: ---- | T40: ---- | W40: =W39 -> 2.24 | Y40: × | Z40: 107
F41: =+F40+1 -> 36 | H41: =+H40+1 -> 35 | J41: =+J40+1 -> 36 | L41: =+L40+1 -> 21 | M41: =+M40 -> 6 | N41: Ｍ～φ | Q41: ---- | T41: ---- | W41: =W40 -> 2.24 | Y41: × | Z41: 107
...

Sheet 2.地盤のモデル化
B2: 2.地盤のモデル化
C4: (1) | D4: 4P左
C8: (2) | D8: 4P右
AN16: JR東日本
AM17: 場所打ち杭 | AN17: 0 | AO17: 0.1 | AP17: 0.2 | AQ17: 0.3 | AR17: 0.4 | AS17: 0.5 | AT17: 0.6 | AU17: 0.7 | AV17: 0.8 | AW17: 0.9 | AX17: 1
AM18: 長期支持性能 | AN18: 0.55 | AO18: 0.55 | AP18: 0.55 | AQ18: 0.55 | AR18: 0.55 | AS18: 0.55 | AT18: 0.55 | AU18: 0.48 | AV18: 0.4 | AW18: 0.33 | AX18: 0.25
AM19: 短期支持性能 | AN19: 0.65 | AO19: 0.65 | AP19: 0.65 | AQ19: 0.65 | AR19: 0.65 | AS19: 0.65 | AT19: 0.65 | AU19: 0.59 | AV19: 0.53 | AW19: 0.46 | AX19: 0.4
AM20: 安全性(地震時以外) | AN20: 0.86 | AO20: 0.85 | AP20: 0.83 | AQ20: 0.81 | AR20: 0.79 | AS20: 0.77 | AT20: 0.74 | AU20: 0.7 | AV20: 0.65 | AW20: 0.6 | AX20: 0.55
AM21: 復旧性(性能レベル1) | AN21: 0.92 | AO21: 0.9 | AP21: 0.88 | AQ21: 0.85 | AR21: 0.83 | AS21: 0.8 | AT21: 0.77 | AU21: 0.73 | AV21: 0.69 | AW21: 0.64 | AX21: 0.58
AM22: 復旧性(性能レベル2) | AN22: 1.15 | AO22: 1.15 | AP22: 1.15 | AQ22: 1.15 | AR22: 1.15 | AS22: 1.15 | AT22: 1.14 | AU22: 1.13 | AV22: 1.12 | AW22: 1.11 | AX22: 1.1

Sheet 水平地盤ばね定数(4P左)
C2: (3) | D2: ばね定数
C3: 1) | D3: 水平地盤ばね定数（部材ばね）
C4: a) | D4: 4P左(1,3列目)
D5: 杭径 | E5: 1.3 | F5: m
D6: 杭全長 | E6: 31 | F6: m
D7: 杭本数 | E7: 2 | F7: 本
D8: 層番号 | E8: 層厚 (m) | F8: 水平地盤反力係数 khg (kN/m3) | G8: 部材長 (m) | I8: 部材番号 | K8: 各部材の水平地盤反力係数 khg (kN/m3) | L8: 各部材の水平ばね定数 KH (kN/m2) | P8: 右押し（→） | U8: 左押し（←）
P11: 節点番号 | Q11: 水平ばね | R11: 有効抵抗土圧力 | U11: 節点番号 | V11: 水平ばね | W11: 有効抵抗土圧力
L12: 杭1本当り | M12: =+E7 -> 2 | R12: 上端 | S12: 下端 | W12: 上端 | X12: 下端
D13: ① | E13: 3.3 | F13: 19476 | G13: =+E5 -> 1.3 | I13: 18 | J13: 68 | K13: =+F13 -> 19476 | L13: =K13*E5 -> 25318.8 | M13: =+E7*L13 -> 50637.6 | P13: =+I13 -> 18 | Q13: =+M13 -> 50637.6 | R13: =+'有効抵抗土圧(4P左)'!G202 -> 715.52 | S13: =+'有効抵抗土圧(4P左)'!G203 -> 849.12218 | U13: =+P13 -> 18 | V13: =+Q13 -> 50637.6 | W13: =+R63 -> 1788.8 | X13: =+S63 -> 2122.8055
G14: =+G13 -> 1.3 | I14: =+I13+1 -> 19 | J14: =+J13+1 -> 69 | K14: =+F13 -> 19476 | L14: =K14*E5 -> 25318.8 | M14: =+E7*L14 -> 50637.6 | P14: =+P13+1 -> 19 | Q14: =+M14 -> 50637.6 | R14: =+'有効抵抗土圧(4P左)'!G204 -> 849.12218 | S14: =+'有効抵抗土圧(4P左)'!G205 -> 982.72436 | U14: =+P14 -> 19 | V14: =+Q14 -> 50637.6 | W14: =+R64 -> 2122.8055 | X14: =+S64 -> 2456.8109
G15: =+G14 -> 1.3 | H15: =+E13-G13-G14 -> 0.7 | I15: =+I14+1 -> 20 | J15: =+J14+1 -> 70 | K15: =(F13*H15+F16*H16)/G15 -> 58000.615 | L15: =+E5*K15 -> 75400.8 | M15: =+E7*L15 -> 150801.6 | P15: =+P14+1 -> 20 | Q15: =+M15 -> 150801.6 | R15: =+'有効抵抗土圧(4P左)'!G206 -> 1303.6341 | S15: =+'有効抵抗土圧(4P左)'!G207 -> 1303.6341 | U15: =+P15 -> 20 | V15: =+Q15 -> 150801.6 | W15: =+R65 -> 3259.0852 | X15: =+S65 -> 3259.0852
D16: ② | E16: 1.3 | F16: 102946 | H16: =+G15-H15 -> 0.6 | P16: =+P15+1 -> 21 | Q16: =+M17 -> 188118.8 | R16: =+'有効抵抗土圧(4P左)'!G208 -> 1138.2575 | S16: =+'有効抵抗土圧(4P左)'!G209 -> 1138.2575 | U16: =+P16 -> 21 | V16: =+Q16 -> 188118.8 | W16: =+R66 -> 2845.6438 | X16: =+S66 -> 2845.6438
G17: =+G15 -> 1.3 | H17: =+E16-H16 -> 0.7 | I17: =+I15+1 -> 21 | J17: =+J15+1 -> 71 | K17: =(F16*H17+F18*H18)/G17 -> 72353.385 | L17: =+E5*K17 -> 94059.4 | M17: =+E7*L17 -> 188118.8 | P17: =+P16+1 -> 22 | Q17: =+M19 -> 95321.2 | R17: =+'有効抵抗土圧(4P左)'!G210 -> 468 | S17: =+'有効抵抗土圧(4P左)'!G211 -> 468 | U17: =+P17 -> 22 | V17: =+Q17 -> 95321.2 | W17: =+R67 -> 1170 | X17: =+S67 -> 1170
D18: ③ | E18: 2.9 | F18: 36662 | H18: =+G17-H17 -> 0.6 | P18: =+P17+1 -> 23 | Q18: =+M20 -> 53420.4 | R18: =+'有効抵抗土圧(4P左)'!G212 -> 782.904 | S18: =+'有効抵抗土圧(4P左)'!G213 -> 782.904 | U18: =+P18 -> 23 | V18: =+Q18 -> 53420.4 | W18: =+R68 -> 1957.26 | X18: =+S68 -> 1957.26
G19: =+G17 -> 1.3 | I19: =+I17+1 -> 22 | J19: =+J17+1 -> 72 | K19: =+F18 -> 36662 | L19: =+E5*K19 -> 47660.6 | M19: =+E7*L19 -> 95321.2 | P19: =+P18+1 -> 24 | Q19: =+M22 -> 231488.4 | R19: =+'有効抵抗土圧(4P左)'!G214 -> 1848.808 | S19: =+'有効抵抗土圧(4P左)'!G215 -> 1989.416 | U19: =+P19 -> 24 | V19: =+Q19 -> 231488.4 | W19: =+R69 -> 4622.02 | X19: =+S69 -> 4973.54
G20: =+G19 -> 1.3 | H20: =+E18-H18-G19 -> 1 | I20: =+I19+1 -> 23 | J20: =+J19+1 -> 73 | K20: =(F19*H20+F21*H21)/G20 -> 20546.308 | L20: =+E5*K20 -> 26710.2 | M20: =+E7*L20 -> 53420.4 | P20: =+P19+1 -> 25 | Q20: =+M23 -> 85237.2 | R20: =+'有効抵抗土圧(4P左)'!G216 -> 1990.96 | S20: =+'有効抵抗土圧(4P左)'!G217 -> 1990.96 | U20: =+P20 -> 25 | V20: =+Q20 -> 85237.2 | W20: =+R70 -> 4977.4 | X20: =+S70 -> 4977.4
D21: ④ | E21: 2.6 | F21: 89034 | H21: =+G20-H20 -> 0.3 | P21: =+P20+1 -> 26 | Q21: =+M25 -> 352339.2 | R21: =+'有効抵抗土圧(4P左)'!G218 -> 2188.1642 | S21: =+'有効抵抗土圧(4P左)'!G219 -> 2188.1642 | U21: =+P21 -> 26 | V21: =+Q21 -> 352339.2 | W21: =+R71 -> 5470.4105 | X21: =+S71 -> 5470.4105
G22: =+G20 -> 1.3 | I22: =+I20+1 -> 24 | J22: =+J20+1 -> 74 | K22: =+F21 -> 89034 | L22: =+E5*K22 -> 115744.2 | M22: =+E7*L22 -> 231488.4 | P22: =+P21+1 -> 27 | Q22: =+M27 -> 347232.6 | R22: =+'有効抵抗土圧(4P左)'!G220 -> 2356.3389 | S22: =+'有効抵抗土圧(4P左)'!G221 -> 2503.1804 | U22: =+P22 -> 27 | V22: =+Q22 -> 347232.6 | W22: =+R72 -> 5890.8474 | X22: =+S72 -> 6257.9509
G23: =+G22 -> 1.3 | H23: =+E21-H21-G22 -> 1 | I23: =+I22+1 -> 25 | J23: =+J22+1 -> 75 | K23: =(F22*H23+F24*H24)/G23 -> 32783.538 | L23: =+E5*K23 -> 42618.6 | M23: =+E7*L23 -> 85237.2 | P23: =+P22+1 -> 28 | Q23: =+M28 -> 347232.6 | R23: =+'有効抵抗土圧(4P左)'!G222 -> 2503.1804 | S23: =+'有効抵抗土圧(4P左)'!G223 -> 2650.0218 | U23: =+P23 -> 28 | V23: =+Q23 -> 347232.6 | W23: =+R73 -> 6257.9509 | X23: =+S73 -> 6625.0545
D24: ⑤ | E24: 0.6 | F24: 142062 | H24: =+G23-H23 -> 0.3 | P24: =+P23+1 -> 29 | Q24: =+M29 -> 347232.6 | R24: =+'有効抵抗土圧(4P左)'!G224 -> 2650.0218 | S24: =+'有効抵抗土圧(4P左)'!G225 -> 2796.8632 | U24: =+P24 -> 29 | V24: =+Q24 -> 347232.6 | W24: =+R74 -> 6625.0545 | X24: =+S74 -> 6992.1581
G25: =+G23 -> 1.3 | H25: =+E24-H24 -> 0.3 | I25: =+I23+1 -> 26 | J25: =+J23+1 -> 76 | K25: =(F24*H25+F26*H26)/G25 -> 135515.08 | L25: =+E5*K25 -> 176169.6 | M25: =+E7*L25 -> 352339.2 | P25: =+P24+1 -> 30 | Q25: =+M30 -> 347232.6 | R25: =+'有効抵抗土圧(4P左)'!G226 -> 2796.8632 | S25: =+'有効抵抗土圧(4P左)'!G227 -> 2943.7047 | U25: =+P25 -> 30 | V25: =+Q25 -> 347232.6 | W25: =+R75 -> 6992.1581 | X25: =+S75 -> 7359.2617
D26: ⑥ | E26: 9.5 | F26: 133551 | H26: =+G25-H25 -> 1 | P26: =+P25+1 -> 31 | Q26: =+M31 -> 347232.6 | R26: =+'有効抵抗土圧(4P左)'!G228 -> 2943.7047 | S26: =+'有効抵抗土圧(4P左)'!G229 -> 3090.5461 | U26: =+P26 -> 31 | V26: =+Q26 -> 347232.6 | W26: =+R76 -> 7359.2617 | X26: =+S76 -> 7726.3653
G27: =+G25 -> 1.3 | I27: =+I25+1 -> 27 | J27: =+J25+1 -> 77 | K27: =+F26 -> 133551 | L27: =+E5*K27 -> 173616.3 | M27: =+E7*L27 -> 347232.6 | P27: =+P26+1 -> 32 | Q27: =+M32 -> 347232.6 | R27: =+'有効抵抗土圧(4P左)'!G230 -> 3090.5461 | S27: =+'有効抵抗土圧(4P左)'!G231 -> 3237.3875 | U27: =+P27 -> 32 | V27: =+Q27 -> 347232.6 | W27: =+R77 -> 7726.3653 | X27: =+S77 -> 8093.4688
G28: =+G27 -> 1.3 | I28: =+I27+1 -> 28 | J28: =+J27+1 -> 78 | K28: =+F26 -> 133551 | L28: =+E5*K28 -> 173616.3 | M28: =+E7*L28 -> 347232.6 | P28: =+P27+1 -> 33 | Q28: =+M33 -> 263959.8 | R28: =+'有効抵抗土圧(4P左)'!G232 -> 2144.6563 | S28: =+'有効抵抗土圧(4P左)'!G233 -> 2144.6563 | U28: =+P28 -> 33 | V28: =+Q28 -> 263959.8 | W28: =+R78 -> 5361.6408 | X28: =+S78 -> 5361.6408
G29: =+G28 -> 1.3 | I29: =+I28+1 -> 29 | J29: =+J28+1 -> 79 | K29: =+F26 -> 133551 | L29: =+E5*K29 -> 173616.3 | M29: =+E7*L29 -> 347232.6 | P29: =+P28+1 -> 34 | Q29: =+M35 -> 166808.2 | R29: =+'有効抵抗土圧(4P左)'!G234 -> 2059.2 | S29: =+'有効抵抗土圧(4P左)'!G235 -> 2059.2 | U29: =+P29 -> 34 | V29: =+Q29 -> 166808.2 | W29: =+R79 -> 2059.2 | X29: =+S79 -> 2059.2
G30: =+G29 -> 1.3 | I30: =+I29+1 -> 30 | J30: =+J29+1 -> 80 | K30: =+F26 -> 133551 | L30: =+E5*K30 -> 173616.3 | M30: =+E7*L30 -> 347232.6 | P30: =+P29+1 -> 35 | Q30: =+M36 -> 166808.2 | R30: =+'有効抵抗土圧(4P左)'!G236 -> 2059.2 | S30: =+'有効抵抗土圧(4P左)'!G237 -> 2059.2 | U30: =+P30 -> 35 | V30: =+Q30 -> 166808.2 | W30: =+R80 -> 2059.2 | X30: =+S80 -> 2059.2
G31: =+G30 -> 1.3 | I31: =+I30+1 -> 31 | J31: =+J30+1 -> 81 | K31: =+F26 -> 133551 | L31: =+E5*K31 -> 173616.3 | M31: =+E7*L31 -> 347232.6 | P31: =+P30+1 -> 36 | Q31: =+M37 -> 166808.2 | R31: =+'有効抵抗土圧(4P左)'!G238 -> 2059.2 | S31: =+'有効抵抗土圧(4P左)'!G239 -> 2059.2 | U31: =+P31 -> 36 | V31: =+Q31 -> 166808.2 | W31: =+R81 -> 2059.2 | X31: =+S81 -> 2059.2
G32: =+G31 -> 1.3 | I32: =+I31+1 -> 32 | J32: =+J31+1 -> 82 | K32: =+F26 -> 133551 | L32: =+E5*K32 -> 173616.3 | M32: =+E7*L32 -> 347232.6 | P32: =+P31+1 -> 37 | Q32: =+M38 -> 166808.2 | R32: =+'有効抵抗土圧(4P左)'!G240 -> 2059.2 | S32: =+'有効抵抗土圧(4P左)'!G241 -> 2059.2 | U32: =+P32 -> 37 | V32: =+Q32 -> 166808.2 | W32: =+R82 -> 2059.2 | X32: =+S82 -> 2059.2
G33: =+G32 -> 1.3 | H33: =+E26-H26-G27-G28-G29-G30-G31-G32 -> 0.7 | I33: =+I32+1 -> 33 | J33: =+J32+1 -> 83 | K33: =(F26*H33+F34*H34)/G33 -> 101523 | L33: =+E5*K33 -> 131979.9 | M33: =+E7*L33 -> 263959.8 | P33: =+P32+1 -> 38 | Q33: =+M39 -> 166808.2 | R33: =+'有効抵抗土圧(4P左)'!G242 -> 2059.2 | S33: =+'有効抵抗土圧(4P左)'!G243 -> 2059.2 | U33: =+P33 -> 38 | V33: =+Q33 -> 166808.2 | W33: =+R83 -> 2059.2 | X33: =+S83 -> 2059.2
D34: ⑦ | E34: 10.8 | F34: 64157 | H34: =+G33-H33 -> 0.6 | P34: =+P33+1 -> 39 | Q34: =+M40 -> 166808.2 | R34: =+'有効抵抗土圧(4P左)'!G244 -> 2059.2 | S34: =+'有効抵抗土圧(4P左)'!G245 -> 2059.2 | U34: =+P34 -> 39 | V34: =+Q34 -> 166808.2 | W34: =+R84 -> 2059.2 | X34: =+S84 -> 2059.2
G35: =+G33 -> 1.3 | I35: =+I33+1 -> 34 | J35: =+J33+1 -> 84 | K35: =+F34 -> 64157 | L35: =+E5*K35 -> 83404.1 | M35: =+E7*L35 -> 166808.2 | P35: =+P34+1 -> 40 | Q35: =+M41 -> 166808.2 | R35: =+'有効抵抗土圧(4P左)'!G246 -> 2059.2 | S35: =+'有効抵抗土圧(4P左)'!G247 -> 2059.2 | U35: =+P35 -> 40 | V35: =+Q35 -> 166808.2 | W35: =+R85 -> 2059.2 | X35: =+S85 -> 2059.2
G36: =+G35 -> 1.3 | I36: =+I35+1 -> 35 | J36: =+J35+1 -> 85 | K36: =+F34 -> 64157 | L36: =+E5*K36 -> 83404.1 | M36: =+E7*L36 -> 166808.2 | P36: =+P35+1 -> 41 | Q36: =+M42 -> 166808.2 | R36: =+'有効抵抗土圧(4P左)'!G248 -> 2059.2 | S36: =+'有効抵抗土圧(4P左)'!G249 -> 2059.2 | U36: =+P36 -> 41 | V36: =+Q36 -> 166808.2 | W36: =+R86 -> 2059.2 | X36: =+S86 -> 2059.2
G37: =+G36 -> 1.3 | I37: =+I36+1 -> 36 | J37: =+J36+1 -> 86 | K37: =+F34 -> 64157 | L37: =+E5*K37 -> 83404.1 | M37: =+E7*L37 -> 166808.2
G38: =+G37 -> 1.3 | I38: =+I37+1 -> 37 | J38: =+J37+1 -> 87 | K38: =+F34 -> 64157 | L38: =+E5*K38 -> 83404.1 | M38: =+E7*L38 -> 166808.2 | P38: =+I56 -> 43 | Q38: =+M56 -> 25318.8 | R38: =+'有効抵抗土圧(4P左)'!H202 -> 447.2 | S38: =+'有効抵抗土圧(4P左)'!H203 -> 530.70136 | U38: =+P38 -> 43 | V38: =+Q38 -> 25318.8 | W38: =+R38 -> 447.2 | X38: =+S38 -> 530.70136
G39: =+G38 -> 1.3 | I39: =+I38+1 -> 38 | J39: =+J38+1 -> 88 | K39: =+F34 -> 64157 | L39: =+E5*K39 -> 83404.1 | M39: =+E7*L39 -> 166808.2 | P39: =+P38+1 -> 44 | Q39: =+M57 -> 25318.8 | R39: =+'有効抵抗土圧(4P左)'!H204 -> 530.70136 | S39: =+'有効抵抗土圧(4P左)'!H205 -> 614.20273 | U39: =+P39 -> 44 | V39: =+Q39 -> 25318.8 | W39: =+R39 -> 530.70136 | X39: =+S39 -> 614.20273
G40: =+G39 -> 1.3 | I40: =+I39+1 -> 39 | J40: =+J39+1 -> 89 | K40: =+F34 -> 64157 | L40: =+E5*K40 -> 83404.1 | M40: =+E7*L40 -> 166808.2 | P40: =+P39+1 -> 45 | Q40: =+M58 -> 75400.8 | R40: =+'有効抵抗土圧(4P左)'!H206 -> 814.77131 | S40: =+'有効抵抗土圧(4P左)'!H207 -> 814.77131 | U40: =+P40 -> 45 | V40: =+Q40 -> 75400.8 | W40: =+R40 -> 814.77131 | X40: =+S40 -> 814.77131
G41: =+G40 -> 1.3 | I41: =+I40+1 -> 40 | J41: =+J40+1 -> 90 | K41: =+F34 -> 64157 | L41: =+E5*K41 -> 83404.1 | M41: =+E7*L41 -> 166808.2 | P41: =+P40+1 -> 46 | Q41: =+M60 -> 94059.4 | R41: =+'有効抵抗土圧(4P左)'!H208 -> 711.41096 | S41: =+'有効抵抗土圧(4P左)'!H209 -> 711.41096 | U41: =+P41 -> 46 | V41: =+Q41 -> 94059.4 | W41: =+R41 -> 711.41096 | X41: =+S41 -> 711.41096
G42: 1.1 | I42: =+I41+1 -> 41 | J42: =+J41+1 -> 91 | K42: =+F34 -> 64157 | L42: =+E5*K42 -> 83404.1 | M42: =+E7*L42 -> 166808.2 | P42: =+P41+1 -> 47 | Q42: =+M62 -> 47660.6 | R42: =+'有効抵抗土圧(4P左)'!H210 -> 292.5 | S42: =+'有効抵抗土圧(4P左)'!H211 -> 292.5 | U42: =+P42 -> 47 | V42: =+Q42 -> 47660.6 | W42: =+R42 -> 292.5 | X42: =+S42 -> 292.5
D43: Σ | E43: =SUM(E13:E42) -> 31 | G43: =SUM(G13:G42) -> 31 | P43: =+P42+1 -> 48 | Q43: =+M63 -> 26710.2 | R43: =+'有効抵抗土圧(4P左)'!H212 -> 489.315 | S43: =+'有効抵抗土圧(4P左)'!H213 -> 489.315 | U43: =+P43 -> 48 | V43: =+Q43 -> 26710.2 | W43: =+R43 -> 489.315 | X43: =+S43 -> 489.315
...

Sheet 水平地盤ばね定数(4P右)
C2: c) | D2: 4P右(1,3列目)
D3: 杭径 | E3: 1.3 | F3: m
D4: 杭全長 | E4: 31 | F4: m
D5: 杭本数 | E5: 3 | F5: 本
D6: 層番号 | E6: 層厚 (m) | F6: 水平地盤反力係数 khg (kN/m3) | G6: 部材長 (m) | I6: 部材番号 | K6: 各部材の水平地盤反力係数 khg (kN/m3) | L6: 各部材の水平ばね定数 KH (kN/m2) | P6: 右押し（→） | U6: 左押し（←）
P9: 節点番号 | Q9: 水平ばね | R9: 有効抵抗土圧力 | U9: 節点番号 | V9: 水平ばね | W9: 有効抵抗土圧力
L10: 杭1本当り | M10: =+E5 -> 3 | R10: 上端 | S10: 下端 | W10: 上端 | X10: 下端
D11: ① | E11: 1.5 | F11: 15080 | G11: =+E3 -> 1.3 | I11: 98 | J11: 148 | K11: =+F11 -> 15080 | L11: =K11*E3 -> 19604 | M11: =L11*E5 -> 58812 | P11: =+I11 -> 98 | Q11: =+M11 -> 58812 | R11: =+'有効抵抗土圧(4P右)'!G200 -> 1163.0298 | S11: =+'有効抵抗土圧(4P右)'!G201 -> 1307.4657 | U11: =+P11 -> 98 | V11: =+Q11 -> 58812 | W11: =+R61 -> 2907.5744 | X11: =+S61 -> 3268.6642
G12: =+G11 -> 1.3 | H12: =+E11-G11 -> 0.2 | I12: =+I11+1 -> 99 | J12: =+J11+1 -> 149 | K12: =(F11*H12+F13*H13)/G12 -> 69765.231 | L12: =K12*E3 -> 90694.8 | M12: =L12*E5 -> 272084.4 | P12: =+P11+1 -> 99 | Q12: =+M12 -> 272084.4 | R12: =+'有効抵抗土圧(4P右)'!G202 -> 1989.0401 | S12: =+'有効抵抗土圧(4P右)'!G203 -> 1989.0401 | U12: =+P12 -> 99 | V12: =+Q12 -> 272084.4 | W12: =+R62 -> 4972.6003 | X12: =+S62 -> 4972.6003
D13: ② | E13: 1.3 | F13: 79708 | H13: =+G12-H12 -> 1.1 | P13: =+P12+1 -> 100 | Q13: =+M14 -> 141501.9 | R13: =+'有効抵抗土圧(4P右)'!G204 -> 907.71051 | S13: =+'有効抵抗土圧(4P右)'!G205 -> 907.71051 | U13: =+P13 -> 100 | V13: =+Q13 -> 141501.9 | W13: =+R63 -> 2269.2763 | X13: =+S63 -> 2269.2763
G14: =+G12 -> 1.3 | H14: =+E13-H13 -> 0.2 | I14: =+I12+1 -> 100 | J14: =+J12+1 -> 150 | K14: =(F13*H14+F15*H15)/G14 -> 36282.538 | L14: =K14*E3 -> 47167.3 | M14: =L14*E5 -> 141501.9 | P14: =+P13+1 -> 101 | Q14: =+M16 -> 110709.3 | R14: =+'有効抵抗土圧(4P右)'!G206 -> 669.006 | S14: =+'有効抵抗土圧(4P右)'!G207 -> 669.006 | U14: =+P14 -> 101 | V14: =+Q14 -> 110709.3 | W14: =+R64 -> 1672.515 | X14: =+S64 -> 1672.515
D15: ③ | E15: 2.9 | F15: 28387 | H15: =+G14-H14 -> 1.1 | P15: =+P14+1 -> 102 | Q15: =+M17 -> 165448.8 | R15: =+'有効抵抗土圧(4P右)'!G208 -> 1740.9709 | S15: =+'有効抵抗土圧(4P右)'!G209 -> 1740.9709 | U15: =+P15 -> 102 | V15: =+Q15 -> 165448.8 | W15: =+R65 -> 4352.4272 | X15: =+S65 -> 4352.4272
G16: =+G14 -> 1.3 | I16: =+I14+1 -> 101 | J16: =+J14+1 -> 151 | K16: =+F15 -> 28387 | L16: =K16*E3 -> 36903.1 | M16: =L16*E5 -> 110709.3 | P16: =+P15+1 -> 103 | Q16: =+M19 -> 268854.3 | R16: =+'有効抵抗土圧(4P右)'!G210 -> 2472.7948 | S16: =+'有効抵抗土圧(4P右)'!G211 -> 2673.794 | U16: =+P16 -> 103 | V16: =+Q16 -> 268854.3 | W16: =+R66 -> 6181.9871 | X16: =+S66 -> 6684.485
G17: =+G16 -> 1.3 | H17: =+E15-H15-G16 -> 0.5 | I17: =+I16+1 -> 102 | J17: =+J16+1 -> 152 | K17: =(F16*H17+F18*H18)/G17 -> 42422.769 | L17: =K17*E3 -> 55149.6 | M17: =L17*E5 -> 165448.8 | P17: =+P16+1 -> 104 | Q17: =+M20 -> 363439.5 | R17: =+'有効抵抗土圧(4P右)'!G212 -> 2640.6296 | S17: =+'有効抵抗土圧(4P右)'!G213 -> 2640.6296 | U17: =+P17 -> 104 | V17: =+Q17 -> 363439.5 | W17: =+R67 -> 6601.5739 | X17: =+S67 -> 6601.5739
D18: ④ | E18: 2.6 | F18: 68937 | H18: =+G17-H17 -> 0.8 | P18: =+P17+1 -> 105 | Q18: =+M23 -> 403279.5 | R18: =+'有効抵抗土圧(4P右)'!G214 -> 3142.5541 | S18: =+'有効抵抗土圧(4P右)'!G215 -> 3142.5541 | U18: =+P18 -> 105 | V18: =+Q18 -> 403279.5 | W18: =+R68 -> 7856.3853 | X18: =+S68 -> 7856.3853
G19: =+G17 -> 1.3 | I19: =+I17+1 -> 103 | J19: =+J17+1 -> 153 | K19: =+F18 -> 68937 | L19: =K19*E3 -> 89618.1 | M19: =L19*E5 -> 268854.3 | P19: =+P18+1 -> 106 | Q19: =+M24 -> 403279.5 | R19: =+'有効抵抗土圧(4P右)'!G216 -> 3190.7596 | S19: =+'有効抵抗土圧(4P右)'!G217 -> 3400.6897 | U19: =+P19 -> 106 | V19: =+Q19 -> 403279.5 | W19: =+R69 -> 7976.8989 | X19: =+S69 -> 8501.7243
G20: =+G19 -> 1.3 | H20: =+E18-H18-G19 -> 0.5 | I20: =+I19+1 -> 104 | J20: =+J19+1 -> 154 | K20: =(F18*H20+F21*H21+F22*H22)/G20 -> 93189.615 | L20: =K20*E3 -> 121146.5 | M20: =L20*E5 -> 363439.5 | P20: =+P19+1 -> 107 | Q20: =+M25 -> 403279.5 | R20: =+'有効抵抗土圧(4P右)'!G218 -> 3400.6897 | S20: =+'有効抵抗土圧(4P右)'!G219 -> 3610.6199 | U20: =+P20 -> 107 | V20: =+Q20 -> 403279.5 | W20: =+R70 -> 8501.7243 | X20: =+S70 -> 9026.5498
D21: ⑤ | E21: 0.6 | F21: 109995 | H21: =+E21 -> 0.6 | P21: =+P20+1 -> 108 | Q21: =+M26 -> 403279.5 | R21: =+'有効抵抗土圧(4P右)'!G220 -> 3610.6199 | S21: =+'有効抵抗土圧(4P右)'!G221 -> 3820.5501 | U21: =+P21 -> 108 | V21: =+Q21 -> 403279.5 | W21: =+R71 -> 9026.5498 | X21: =+S71 -> 9551.3752
D22: ⑥ | E22: 9.5 | F22: 103405 | H22: =+G20-H20-H21 -> 0.2 | P22: =+P21+1 -> 109 | Q22: =+M27 -> 403279.5 | R22: =+'有効抵抗土圧(4P右)'!G222 -> 3820.5501 | S22: =+'有効抵抗土圧(4P右)'!G223 -> 4030.4802 | U22: =+P22 -> 109 | V22: =+Q22 -> 403279.5 | W22: =+R72 -> 9551.3752 | X22: =+S72 -> 10076.201
G23: =+G20 -> 1.3 | I23: =+I20+1 -> 105 | J23: =+J20+1 -> 155 | K23: =+F22 -> 103405 | L23: =K23*E3 -> 134426.5 | M23: =L23*E5 -> 403279.5 | P23: =+P22+1 -> 110 | Q23: =+M28 -> 403279.5 | R23: =+'有効抵抗土圧(4P右)'!G224 -> 4030.4802 | S23: =+'有効抵抗土圧(4P右)'!G225 -> 4240.4104 | U23: =+P23 -> 110 | V23: =+Q23 -> 403279.5 | W23: =+R73 -> 10076.201 | X23: =+S73 -> 10601.026
G24: =+G23 -> 1.3 | I24: =+I23+1 -> 106 | J24: =+J23+1 -> 156 | K24: =+K23 -> 103405 | L24: =K24*E3 -> 134426.5 | M24: =L24*E5 -> 403279.5 | P24: =+P23+1 -> 111 | Q24: =+M29 -> 403279.5 | R24: =+'有効抵抗土圧(4P右)'!G226 -> 4240.4104 | S24: =+'有効抵抗土圧(4P右)'!G227 -> 4450.3406 | U24: =+P24 -> 111 | V24: =+Q24 -> 403279.5 | W24: =+R74 -> 10601.026 | X24: =+S74 -> 11125.851
G25: =+G24 -> 1.3 | I25: =+I24+1 -> 107 | J25: =+J24+1 -> 157 | K25: =+K24 -> 103405 | L25: =K25*E3 -> 134426.5 | M25: =L25*E5 -> 403279.5 | P25: =+P24+1 -> 112 | Q25: =+M30 -> 225970.5 | R25: =+'有効抵抗土圧(4P右)'!G228 -> 1683.4565 | S25: =+'有効抵抗土圧(4P右)'!G229 -> 1683.4565 | U25: =+P25 -> 112 | V25: =+Q25 -> 225970.5 | W25: =+R75 -> 4208.6412 | X25: =+S75 -> 4208.6412
G26: =+G25 -> 1.3 | I26: =+I25+1 -> 108 | J26: =+J25+1 -> 158 | K26: =+K25 -> 103405 | L26: =K26*E3 -> 134426.5 | M26: =L26*E5 -> 403279.5 | P26: =+P25+1 -> 113 | Q26: =+M32 -> 193732.5 | R26: =+'有効抵抗土圧(4P右)'!G230 -> 3088.8 | S26: =+'有効抵抗土圧(4P右)'!G231 -> 3088.8 | U26: =+P26 -> 113 | V26: =+Q26 -> 193732.5 | W26: =+R76 -> 3088.8 | X26: =+S76 -> 3088.8
G27: =+G26 -> 1.3 | I27: =+I26+1 -> 109 | J27: =+J26+1 -> 159 | K27: =+K26 -> 103405 | L27: =K27*E3 -> 134426.5 | M27: =L27*E5 -> 403279.5 | P27: =+P26+1 -> 114 | Q27: =+M33 -> 193732.5 | R27: =+'有効抵抗土圧(4P右)'!G232 -> 3088.8 | S27: =+'有効抵抗土圧(4P右)'!G233 -> 3088.8 | U27: =+P27 -> 114 | V27: =+Q27 -> 193732.5 | W27: =+R77 -> 3088.8 | X27: =+S77 -> 3088.8
G28: =+G27 -> 1.3 | I28: =+I27+1 -> 110 | J28: =+J27+1 -> 160 | K28: =+K27 -> 103405 | L28: =K28*E3 -> 134426.5 | M28: =L28*E5 -> 403279.5 | P28: =+P27+1 -> 115 | Q28: =+M34 -> 193732.5 | R28: =+'有効抵抗土圧(4P右)'!G234 -> 3088.8 | S28: =+'有効抵抗土圧(4P右)'!G235 -> 3088.8 | U28: =+P28 -> 115 | V28: =+Q28 -> 193732.5 | W28: =+R78 -> 3088.8 | X28: =+S78 -> 3088.8
G29: =+G28 -> 1.3 | I29: =+I28+1 -> 111 | J29: =+J28+1 -> 161 | K29: =+K28 -> 103405 | L29: =K29*E3 -> 134426.5 | M29: =L29*E5 -> 403279.5 | P29: =+P28+1 -> 116 | Q29: =+M35 -> 193732.5 | R29: =+'有効抵抗土圧(4P右)'!G236 -> 3088.8 | S29: =+'有効抵抗土圧(4P右)'!G237 -> 3088.8 | U29: =+P29 -> 116 | V29: =+Q29 -> 193732.5 | W29: =+R79 -> 3088.8 | X29: =+S79 -> 3088.8
G30: =+G29 -> 1.3 | H30: =+E22-H22-G23-G24-G25-G26-G27-G28-G29 -> 0.2 | I30: =+I29+1 -> 112 | J30: =+J29+1 -> 162 | K30: =(F22*H30+F31*H31)/G30 -> 57941.154 | L30: =K30*E3 -> 75323.5 | M30: =L30*E5 -> 225970.5 | P30: =+P29+1 -> 117 | Q30: =+M36 -> 193732.5 | R30: =+'有効抵抗土圧(4P右)'!G238 -> 3088.8 | S30: =+'有効抵抗土圧(4P右)'!G239 -> 3088.8 | U30: =+P30 -> 117 | V30: =+Q30 -> 193732.5 | W30: =+R80 -> 3088.8 | X30: =+S80 -> 3088.8
D31: ⑦ | E31: 12.6 | F31: 49675 | H31: =+G30-H30 -> 1.1 | P31: =+P30+1 -> 118 | Q31: =+M37 -> 193732.5 | R31: =+'有効抵抗土圧(4P右)'!G240 -> 3088.8 | S31: =+'有効抵抗土圧(4P右)'!G241 -> 3088.8 | U31: =+P31 -> 118 | V31: =+Q31 -> 193732.5 | W31: =+R81 -> 3088.8 | X31: =+S81 -> 3088.8
G32: =+G30 -> 1.3 | I32: =+I30+1 -> 113 | J32: =+J30+1 -> 163 | K32: =+F31 -> 49675 | L32: =K32*E3 -> 64577.5 | M32: =L32*E5 -> 193732.5 | P32: =+P31+1 -> 119 | Q32: =+M38 -> 193732.5 | R32: =+'有効抵抗土圧(4P右)'!G242 -> 3088.8 | S32: =+'有効抵抗土圧(4P右)'!G243 -> 3088.8 | U32: =+P32 -> 119 | V32: =+Q32 -> 193732.5 | W32: =+R82 -> 3088.8 | X32: =+S82 -> 3088.8
G33: =+G32 -> 1.3 | I33: =+I32+1 -> 114 | J33: =+J32+1 -> 164 | K33: =+K32 -> 49675 | L33: =K33*E3 -> 64577.5 | M33: =L33*E5 -> 193732.5 | P33: =+P32+1 -> 120 | Q33: =+M39 -> 193732.5 | R33: =+'有効抵抗土圧(4P右)'!G244 -> 3088.8 | S33: =+'有効抵抗土圧(4P右)'!G245 -> 3088.8 | U33: =+P33 -> 120 | V33: =+Q33 -> 193732.5 | W33: =+R83 -> 3088.8 | X33: =+S83 -> 3088.8
G34: =+G33 -> 1.3 | I34: =+I33+1 -> 115 | J34: =+J33+1 -> 165 | K34: =+K33 -> 49675 | L34: =K34*E3 -> 64577.5 | M34: =L34*E5 -> 193732.5 | P34: =+P33+1 -> 121 | Q34: =+M40 -> 193732.5 | R34: =+'有効抵抗土圧(4P右)'!G246 -> 3088.8 | S34: =+'有効抵抗土圧(4P右)'!G247 -> 3088.8 | U34: =+P34 -> 121 | V34: =+Q34 -> 193732.5 | W34: =+R84 -> 3088.8 | X34: =+S84 -> 3088.8
G35: =+G34 -> 1.3 | I35: =+I34+1 -> 116 | J35: =+J34+1 -> 166 | K35: =+K34 -> 49675 | L35: =K35*E3 -> 64577.5 | M35: =L35*E5 -> 193732.5
G36: =+G35 -> 1.3 | I36: =+I35+1 -> 117 | J36: =+J35+1 -> 167 | K36: =+K35 -> 49675 | L36: =K36*E3 -> 64577.5 | M36: =L36*E5 -> 193732.5 | P36: =+I54 -> 123 | Q36: =+M54 -> 39208 | R36: =+'有効抵抗土圧(4P右)'!H200 -> 1004.7861 | S36: =+'有効抵抗土圧(4P右)'!H201 -> 1129.5699 | U36: =+P36 -> 123 | V36: =+Q36 -> 39208 | W36: =+R36 -> 1004.7861 | X36: =+S36 -> 1129.5699
G37: =+G36 -> 1.3 | I37: =+I36+1 -> 118 | J37: =+J36+1 -> 168 | K37: =+K36 -> 49675 | L37: =K37*E3 -> 64577.5 | M37: =L37*E5 -> 193732.5 | P37: =+P36+1 -> 124 | Q37: =+M55 -> 181389.6 | R37: =+'有効抵抗土圧(4P右)'!H202 -> 1718.4082 | S37: =+'有効抵抗土圧(4P右)'!H203 -> 1718.4082 | U37: =+P37 -> 124 | V37: =+Q37 -> 181389.6 | W37: =+R37 -> 1718.4082 | X37: =+S37 -> 1718.4082
G38: =+G37 -> 1.3 | I38: =+I37+1 -> 119 | J38: =+J37+1 -> 169 | K38: =+K37 -> 49675 | L38: =K38*E3 -> 64577.5 | M38: =L38*E5 -> 193732.5 | P38: =+P37+1 -> 125 | Q38: =+M57 -> 94334.6 | R38: =+'有効抵抗土圧(4P右)'!H204 -> 784.206 | S38: =+'有効抵抗土圧(4P右)'!H205 -> 784.206 | U38: =+P38 -> 125 | V38: =+Q38 -> 94334.6 | W38: =+R38 -> 784.206 | X38: =+S38 -> 784.206
G39: =+G38 -> 1.3 | I39: =+I38+1 -> 120 | J39: =+J38+1 -> 170 | K39: =+K38 -> 49675 | L39: =K39*E3 -> 64577.5 | M39: =L39*E5 -> 193732.5 | P39: =+P38+1 -> 126 | Q39: =+M59 -> 73806.2 | R39: =+'有効抵抗土圧(4P右)'!H206 -> 577.98 | S39: =+'有効抵抗土圧(4P右)'!H207 -> 577.98 | U39: =+P39 -> 126 | V39: =+Q39 -> 73806.2 | W39: =+R39 -> 577.98 | X39: =+S39 -> 577.98
G40: =E31-H31-SUM(G32:H39) -> 1.1 | I40: =+I39+1 -> 121 | J40: =+J39+1 -> 171 | K40: =+K39 -> 49675 | L40: =K40*E3 -> 64577.5 | M40: =L40*E5 -> 193732.5 | P40: =+P39+1 -> 127 | Q40: =+M60 -> 110299.2 | R40: =+'有効抵抗土圧(4P右)'!H208 -> 1504.0917 | S40: =+'有効抵抗土圧(4P右)'!H209 -> 1504.0917 | U40: =+P40 -> 127 | V40: =+Q40 -> 110299.2 | W40: =+R40 -> 1504.0917 | X40: =+S40 -> 1504.0917
D41: Σ | E41: =SUM(E11:E40) -> 31 | G41: =SUM(G11:G40) -> 31 | P41: =+P40+1 -> 128 | Q41: =+M62 -> 179236.2 | R41: =+'有効抵抗土圧(4P右)'!H210 -> 2136.3425 | S41: =+'有効抵抗土圧(4P右)'!H211 -> 2309.9934 | U41: =+P41 -> 128 | V41: =+Q41 -> 179236.2 | W41: =+R41 -> 2136.3425 | X41: =+S41 -> 2309.9934
P42: =+P41+1 -> 129 | Q42: =+M63 -> 242293 | R42: =+'有効抵抗土圧(4P右)'!H212 -> 2281.3414 | S42: =+'有効抵抗土圧(4P右)'!H213 -> 2281.3414 | U42: =+P42 -> 129 | V42: =+Q42 -> 242293 | W42: =+R42 -> 2281.3414 | X42: =+S42 -> 2281.3414
P43: =+P42+1 -> 130 | Q43: =+M66 -> 268853 | R43: =+'有効抵抗土圧(4P右)'!H214 -> 2714.9733 | S43: =+'有効抵抗土圧(4P右)'!H215 -> 2714.9733 | U43: =+P43 -> 130 | V43: =+Q43 -> 268853 | W43: =+R43 -> 2714.9733 | X43: =+S43 -> 2714.9733
...

Sheet 鉛直せん断地盤ばね定数(4P左)
C2: 2) | D2: 鉛直せん断地盤ばね定数（節点ばね）
C3: ※ | D3: 安全側を考慮して【押込み側】で計算を行う。
C4: a) | D4: 4P左(1,3列目)
D5: 杭径 | E5: 1.3 | F5: m
D6: 周長 | E6: =+PI()*E5 -> 4.0840704 | F6: m
D7: 杭全長 | E7: 31 | F7: m
D8: 1/β | E8: 4.891 | F8: m
D9: 杭本数 | E9: 2 | F9: 本
D10: 層番号 | E10: 層厚 (m) | F10: 鉛直せん断地盤ばねを考慮する層厚(m) | G10: 鉛直地盤 反力係数 kfv (kN/m3) | H10: 分布幅 (m) | J10: 1/βを考慮 した分布幅 (m) | L10: 節点番号 | N10: 分布幅の鉛直地盤反力係数 kfv (kN/m2) | O10: 各節点の鉛直ばね定数 Kfv (kN/m) | S10: 節点番号 | T10: 拘束方向 | U10: 第1勾配 | X10: 第2勾配 | AA10: 第3勾配 | AB10: 第1勾配 | AC10: 第2勾配 | AD10: 第3勾配
U11: 鉛直ばね | V11: 制限値 | X11: 鉛直ばね | Y11: 制限値 | AA11: 鉛直ばね | AB11: 鉛直ばね | AC11: 鉛直ばね | AD11: 鉛直ばね
U12: ＋側 | V12: ＋側 | W12: －側 | X12: ＋側 | Y12: ＋側 | Z12: －側 | AA12: ＋側 | AB12: －側 | AC12: －側 | AD12: －側
S13: =+L15 -> 17
O14: 杭1本当り | P14: =+E9 -> 2 | S14: =+S13+1 -> 18
D15: ① | E15: 3.3 | F15: － | G15: 2000 | H15: =+E5/2 -> 0.65 | J15: － | K15: － | L15: 17 | M15: 67 | N15: － | O15: － | P15: － | S15: =+S14+1 -> 19
H16: =+E5 -> 1.3 | J16: － | K16: － | L16: =+L15+1 -> 18 | M16: =+M15+1 -> 68 | N16: － | O16: － | P16: － | S16: =+S15+1 -> 20
S17: =+S16+1 -> 21 | T17: Y | U17: =+P22 -> 29492.175 | V17: =+'周面支持力(4P左)'!P22 -> 156.66494 | W17: =+V17 -> 156.66494 | X17: =+U17 -> 29492.175 | Y17: =+V17 -> 156.66494 | Z17: =+Y17 -> 156.66494 | AA17: =+X17 -> 29492.175 | AB17: =+AA17 -> 29492.175 | AC17: =+AB17 -> 29492.175 | AD17: =+AC17 -> 29492.175
H18: =+H16 -> 1.3 | J18: － | K18: － | L18: =+L16+1 -> 19 | M18: =+M16+1 -> 69 | N18: － | O18: － | P18: － | S18: =+S17+1 -> 22 | T18: Y | U18: =+P24 -> 39978.966 | V18: =+'周面支持力(4P左)'!P24 -> 212.37166 | W18: =+V18 -> 212.37166 | X18: =+U18 -> 39978.966 | Y18: =+V18 -> 212.37166 | Z18: =+Y18 -> 212.37166 | AA18: =+X18 -> 39978.966 | AB18: =+AA18 -> 39978.966 | AC18: =+AB18 -> 39978.966 | AD18: =+AC18 -> 39978.966
S19: =+S18+1 -> 23 | T19: Y | U19: =+P26 -> 81710.814 | V19: =+'周面支持力(4P左)'!P26 -> 802.11144 | W19: =+V19 -> 802.11144 | X19: =+U19 -> 81710.814 | Y19: =+V19 -> 802.11144 | Z19: =+Y19 -> 802.11144 | AA19: =+X19 -> 81710.814 | AB19: =+AA19 -> 81710.814 | AC19: =+AB19 -> 81710.814 | AD19: =+AC19 -> 81710.814
H20: =+H18 -> 1.3 | I20: =+E15-H15-H16-H18 -> 0.05 | J20: － | K20: － | L20: =+L18+1 -> 20 | M20: =+M18+1 -> 70 | N20: － | O20: － | P20: － | S20: =+S19+1 -> 24 | T20: Y | U20: =+P28 -> 97085.706 | V20: =+'周面支持力(4P左)'!P28 -> 1019.384 | W20: =+V20 -> 1019.384 | X20: =+U20 -> 97085.706 | Y20: =+V20 -> 1019.384 | Z20: =+Y20 -> 1019.384 | AA20: =+X20 -> 97085.706 | AB20: =+AA20 -> 97085.706 | AC20: =+AB20 -> 97085.706 | AD20: =+AC20 -> 97085.706
D21: ② | E21: 1.3 | F21: － | G21: 10571 | I21: =+H20-I20 -> 1.25 | K21: － | S21: =+S20+1 -> 25 | T21: Y | U21: =+P30 -> 136838.82 | V21: =+'周面支持力(4P左)'!P30 -> 1066.4325 | W21: =+V21 -> 1066.4325 | X21: =+U21 -> 136838.82 | Y21: =+V21 -> 1066.4325 | Z21: =+Y21 -> 1066.4325 | AA21: =+X21 -> 136838.82 | AB21: =+AA21 -> 136838.82 | AC21: =+AB21 -> 136838.82 | AD21: =+AC21 -> 136838.82
H22: =+H20 -> 1.3 | I22: =+E21-I21 -> 0.05 | J22: － | K22: － | L22: =+L20+1 -> 21 | M22: =+M20+1 -> 71 | N22: =+G23*K23 -> 3610.635 | O22: =+E6*N22 -> 14746.088 | P22: =+E9*O22 -> 29492.175 | S22: =+S21+1 -> 26 | T22: Y | U22: =+P33 -> 145623.25 | V22: =+'周面支持力(4P左)'!P33 -> 1529.076 | W22: =+V22 -> 1529.076 | X22: =+U22 -> 145623.25 | Y22: =+V22 -> 1529.076 | Z22: =+Y22 -> 1529.076 | AA22: =+X22 -> 145623.25 | AB22: =+AA22 -> 145623.25 | AC22: =+AB22 -> 145623.25 | AD22: =+AC22 -> 145623.25
D23: ③ | E23: 2.9 | F23: =+E15+E21+E23-E8 -> 2.609 | G23: 3765 | I23: =+H22-I22 -> 1.25 | K23: =+F23-K26-J24 -> 0.959 | S23: =+S22+1 -> 27 | T23: Y | U23: =+P35 -> 145623.25 | V23: =+'周面支持力(4P左)'!P35 -> 1529.076 | W23: =+V23 -> 1529.076 | X23: =+U23 -> 145623.25 | Y23: =+V23 -> 1529.076 | Z23: =+Y23 -> 1529.076 | AA23: =+X23 -> 145623.25 | AB23: =+AA23 -> 145623.25 | AC23: =+AB23 -> 145623.25 | AD23: =+AC23 -> 145623.25
H24: =+H22 -> 1.3 | J24: =+H24 -> 1.3 | L24: =+L22+1 -> 22 | M24: =+M22+1 -> 72 | N24: =+G23*J24 -> 4894.5 | O24: =+E6*N24 -> 19989.483 | P24: =+E9*O24 -> 39978.966 | S24: =+S23+1 -> 28 | T24: Y | U24: =+P37 -> 145623.25 | V24: =+'周面支持力(4P左)'!P37 -> 1529.076 | W24: =+V24 -> 1529.076 | X24: =+U24 -> 145623.25 | Y24: =+V24 -> 1529.076 | Z24: =+Y24 -> 1529.076 | AA24: =+X24 -> 145623.25 | AB24: =+AA24 -> 145623.25 | AC24: =+AB24 -> 145623.25 | AD24: =+AC24 -> 145623.25
S25: =+S24+1 -> 29 | T25: Y | U25: =+P39 -> 145623.25 | V25: =+'周面支持力(4P左)'!P39 -> 1529.076 | W25: =+V25 -> 1529.076 | X25: =+U25 -> 145623.25 | Y25: =+V25 -> 1529.076 | Z25: =+Y25 -> 1529.076 | AA25: =+X25 -> 145623.25 | AB25: =+AA25 -> 145623.25 | AC25: =+AB25 -> 145623.25 | AD25: =+AC25 -> 145623.25
H26: =+H24 -> 1.3 | I26: =+E23-I23-H24 -> 0.35 | J26: =+K26+K27 -> 1.3 | K26: =+I26 -> 0.35 | L26: =+L24+1 -> 23 | M26: =+M24+1 -> 73 | N26: =+G23*K26+G27*K27 -> 10003.6 | O26: =+E6*N26 -> 40855.407 | P26: =+E9*O26 -> 81710.814 | S26: =+S25+1 -> 30 | T26: Y | U26: =+P41 -> 145623.25 | V26: =+'周面支持力(4P左)'!P41 -> 1529.076 | W26: =+V26 -> 1529.076 | X26: =+U26 -> 145623.25 | Y26: =+V26 -> 1529.076 | Z26: =+Y26 -> 1529.076 | AA26: =+X26 -> 145623.25 | AB26: =+AA26 -> 145623.25 | AC26: =+AB26 -> 145623.25 | AD26: =+AC26 -> 145623.25
D27: ④ | E27: 2.6 | F27: =+E27 -> 2.6 | G27: 9143 | I27: =+H26-I26 -> 0.95 | K27: =+I27 -> 0.95 | S27: =+S26+1 -> 31 | T27: Y | U27: =+P43 -> 145623.25 | V27: =+'周面支持力(4P左)'!P43 -> 1529.076 | W27: =+V27 -> 1529.076 | X27: =+U27 -> 145623.25 | Y27: =+V27 -> 1529.076 | Z27: =+Y27 -> 1529.076 | AA27: =+X27 -> 145623.25 | AB27: =+AA27 -> 145623.25 | AC27: =+AB27 -> 145623.25 | AD27: =+AC27 -> 145623.25
H28: =+H26 -> 1.3 | J28: =+E5 -> 1.3 | L28: =+L26+1 -> 24 | M28: =+M26+1 -> 74 | N28: =+G27*J28 -> 11885.9 | O28: =+E6*N28 -> 48542.853 | P28: =+E9*O28 -> 97085.706 | S28: =+S27+1 -> 32 | T28: Y | U28: =+P45 -> 145623.25 | V28: =+'周面支持力(4P左)'!P45 -> 1529.076 | W28: =+V28 -> 1529.076 | X28: =+U28 -> 145623.25 | Y28: =+V28 -> 1529.076 | Z28: =+Y28 -> 1529.076 | AA28: =+X28 -> 145623.25 | AB28: =+AA28 -> 145623.25 | AC28: =+AB28 -> 145623.25 | AD28: =+AC28 -> 145623.25
S29: =+S28+1 -> 33 | T29: Y | U29: =+P47 -> 72865.535 | V29: =+'周面支持力(4P左)'!P47 -> 418.20881 | W29: =+V29 -> 418.20881 | X29: =+U29 -> 72865.535 | Y29: =+V29 -> 418.20881 | Z29: =+Y29 -> 418.20881 | AA29: =+X29 -> 72865.535 | AB29: =+AA29 -> 72865.535 | AC29: =+AB29 -> 72865.535 | AD29: =+AC29 -> 72865.535
H30: =+H28 -> 1.3 | I30: =+E27-I27-H28 -> 0.35 | J30: =+J28 -> 1.3 | K30: =+F27-K27-J28 -> 0.35 | L30: =+L28+1 -> 25 | M30: =+M28+1 -> 75 | N30: =+G27*K30+G31*K31+G32*K32 -> 16752.75 | O30: =+E6*N30 -> 68419.411 | P30: =+E9*O30 -> 136838.82 | S30: =+S29+1 -> 34 | T30: Y | U30: =+P49 -> 69955.226 | V30: =+'周面支持力(4P左)'!P49 -> 373.77413 | W30: =+V30 -> 373.77413 | X30: =+U30 -> 69955.226 | Y30: =+V30 -> 373.77413 | Z30: =+Y30 -> 373.77413 | AA30: =+X30 -> 69955.226 | AB30: =+AA30 -> 69955.226 | AC30: =+AB30 -> 69955.226 | AD30: =+AC30 -> 69955.226
D31: ⑤ | E31: 0.6 | F31: =+E31 -> 0.6 | G31: 14588 | I31: =+E31 -> 0.6 | K31: =+F31 -> 0.6 | S31: =+S30+1 -> 35 | T31: Y | U31: =+P51 -> 69955.226 | V31: =+'周面支持力(4P左)'!P51 -> 373.77413 | W31: =+V31 -> 373.77413 | X31: =+U31 -> 69955.226 | Y31: =+V31 -> 373.77413 | Z31: =+Y31 -> 373.77413 | AA31: =+X31 -> 69955.226 | AB31: =+AA31 -> 69955.226 | AC31: =+AB31 -> 69955.226 | AD31: =+AC31 -> 69955.226
D32: ⑥ | E32: 9.5 | F32: =+E32 -> 9.5 | G32: 13714 | I32: =+H30-I30-I31 -> 0.35 | K32: =+J30-K30-K31 -> 0.35 | S32: =+S31+1 -> 36 | T32: Y | U32: =+P53 -> 69955.226 | V32: =+'周面支持力(4P左)'!P53 -> 373.77413 | W32: =+V32 -> 373.77413 | X32: =+U32 -> 69955.226 | Y32: =+V32 -> 373.77413 | Z32: =+Y32 -> 373.77413 | AA32: =+X32 -> 69955.226 | AB32: =+AA32 -> 69955.226 | AC32: =+AB32 -> 69955.226 | AD32: =+AC32 -> 69955.226
H33: =+H30 -> 1.3 | J33: =+J30 -> 1.3 | L33: =+L30+1 -> 26 | M33: =+M30+1 -> 76 | N33: =+G32*J33 -> 17828.2 | O33: =+E6*N33 -> 72811.625 | P33: =+E9*O33 -> 145623.25 | S33: =+S32+1 -> 37 | T33: Y | U33: =+P55 -> 69955.226 | V33: =+'周面支持力(4P左)'!P55 -> 373.77413 | W33: =+V33 -> 373.77413 | X33: =+U33 -> 69955.226 | Y33: =+V33 -> 373.77413 | Z33: =+Y33 -> 373.77413 | AA33: =+X33 -> 69955.226 | AB33: =+AA33 -> 69955.226 | AC33: =+AB33 -> 69955.226 | AD33: =+AC33 -> 69955.226
S34: =+S33+1 -> 38 | T34: Y | U34: =+P57 -> 69955.226 | V34: =+'周面支持力(4P左)'!P57 -> 373.77413 | W34: =+V34 -> 373.77413 | X34: =+U34 -> 69955.226 | Y34: =+V34 -> 373.77413 | Z34: =+Y34 -> 373.77413 | AA34: =+X34 -> 69955.226 | AB34: =+AA34 -> 69955.226 | AC34: =+AB34 -> 69955.226 | AD34: =+AC34 -> 69955.226
H35: =+H33 -> 1.3 | J35: =+J33 -> 1.3 | L35: =+L33+1 -> 27 | M35: =+M33+1 -> 77 | N35: =+G32*J35 -> 17828.2 | O35: =+E6*N35 -> 72811.625 | P35: =+E9*O35 -> 145623.25 | S35: =+S34+1 -> 39 | T35: Y | U35: =+P59 -> 69955.226 | V35: =+'周面支持力(4P左)'!P59 -> 373.77413 | W35: =+V35 -> 373.77413 | X35: =+U35 -> 69955.226 | Y35: =+V35 -> 373.77413 | Z35: =+Y35 -> 373.77413 | AA35: =+X35 -> 69955.226 | AB35: =+AA35 -> 69955.226 | AC35: =+AB35 -> 69955.226 | AD35: =+AC35 -> 69955.226
S36: =+S35+1 -> 40 | T36: Y | U36: =+P61 -> 24215.271 | V36: =+'周面支持力(4P左)'!P61 -> 129.38335 | W36: =+V36 -> 129.38335 | X36: =+U36 -> 24215.271 | Y36: =+V36 -> 129.38335 | Z36: =+Y36 -> 129.38335 | AA36: =+X36 -> 24215.271 | AB36: =+AA36 -> 24215.271 | AC36: =+AB36 -> 24215.271 | AD36: =+AC36 -> 24215.271
H37: =+H35 -> 1.3 | J37: =+J35 -> 1.3 | L37: =+L35+1 -> 28 | M37: =+M35+1 -> 78 | N37: =+G32*J37 -> 17828.2 | O37: =+E6*N37 -> 72811.625 | P37: =+E9*O37 -> 145623.25 | S37: =+S36+1 -> 41
H39: =+H37 -> 1.3 | J39: =+J37 -> 1.3 | L39: =+L37+1 -> 29 | M39: =+M37+1 -> 79 | N39: =+G32*J39 -> 17828.2 | O39: =+E6*N39 -> 72811.625 | P39: =+E9*O39 -> 145623.25
H41: =+H39 -> 1.3 | J41: =+J39 -> 1.3 | L41: =+L39+1 -> 30 | M41: =+M39+1 -> 80 | N41: =+G32*J41 -> 17828.2 | O41: =+E6*N41 -> 72811.625 | P41: =+E9*O41 -> 145623.25
H43: =+H41 -> 1.3 | J43: =+J41 -> 1.3 | L43: =+L41+1 -> 31 | M43: =+M41+1 -> 81 | N43: =+G32*J43 -> 17828.2 | O43: =+E6*N43 -> 72811.625 | P43: =+E9*O43 -> 145623.25
H45: =+H43 -> 1.3 | J45: =+J43 -> 1.3 | L45: =+L43+1 -> 32 | M45: =+M43+1 -> 82 | N45: =+G32*J45 -> 17828.2 | O45: =+E6*N45 -> 72811.625 | P45: =+E9*O45 -> 145623.25
...

Sheet 鉛直せん断地盤ばね定数(4P右)
C2: c) | D2: 4P右(1,3列目)
D3: 杭径 | E3: 1.3 | F3: m
D4: 周長 | E4: =+PI()*E3 -> 4.0840704 | F4: m
D5: 杭全長 | E5: 31 | F5: m
D6: 1/β | E6: 4.945 | F6: m
D7: 杭本数 | E7: 3 | F7: 本
D8: 層番号 | E8: 層厚 (m) | F8: 鉛直せん断地盤ばねを考慮する層厚(m) | G8: 鉛直地盤 反力係数 kfv (kN/m3) | H8: 分布幅 (m) | J8: 1/βを考慮 した分布幅 (m) | L8: 節点番号 | N8: 分布幅の鉛直地盤反力係数 kfv (kN/m2) | O8: 各節点の鉛直ばね定数 Kfv (kN/m) | S8: 節点番号 | T8: 拘束方向 | U8: 第1勾配 | X8: 第2勾配 | AA8: 第3勾配 | AB8: 第1勾配 | AC8: 第2勾配 | AD8: 第3勾配
U9: 鉛直ばね | V9: 制限値 | X9: 鉛直ばね | Y9: 制限値 | AA9: 鉛直ばね | AB9: 鉛直ばね | AC9: 鉛直ばね | AD9: 鉛直ばね
U10: ＋側 | V10: ＋側 | W10: －側 | X10: ＋側 | Y10: ＋側 | Z10: －側 | AA10: ＋側 | AB10: －側 | AC10: －側 | AD10: －側
S11: =+L13 -> 98
O12: 杭1本当り | P12: =+E7 -> 3 | S12: =+S11+1 -> 99
D13: ① | E13: 1.5 | F13: － | G13: 2000 | H13: =+E3/2 -> 0.65 | J13: － | K13: － | L13: 98 | M13: 148 | N13: － | O13: － | P13: － | S13: =+S12+1 -> 100
H14: =+E3 -> 1.3 | I14: =+E13-H13 -> 0.85 | J14: － | K14: － | L14: =+L13+1 -> 99 | M14: =+M13+1 -> 149 | N14: － | O14: － | P14: － | S14: =+S13+1 -> 101
D15: ② | E15: 1.3 | F15: － | G15: 10571 | I15: =+H14-I14 -> 0.45 | K15: － | S15: =+S14+1 -> 102 | T15: Y | U15: =+P20 -> 51631.125 | V15: =+'周面支持力(4P右)'!P20 -> 361.44023 | W15: =+V15 -> 361.44023 | X15: =+U15 -> 51631.125 | Y15: =+V15 -> 361.44023 | Z15: =+Y15 -> 361.44023 | AA15: =+X15 -> 51631.125 | AB15: =+AA15 -> 51631.125 | AC15: =+AB15 -> 51631.125 | AD15: =+AC15 -> 51631.125
H16: =+H14 -> 1.3 | I16: =+E15-I15 -> 0.85 | J16: － | K16: － | L16: =+L14+1 -> 100 | M16: =+M14+1 -> 150 | N16: － | O16: － | P16: － | S16: =+S15+1 -> 103 | T16: Y | U16: =+P22 -> 145628.56 | V16: =+'周面支持力(4P右)'!P22 -> 1529.076 | W16: =+V16 -> 1529.076 | X16: =+U16 -> 145628.56 | Y16: =+V16 -> 1529.076 | Z16: =+Y16 -> 1529.076 | AA16: =+X16 -> 145628.56 | AB16: =+AA16 -> 145628.56 | AC16: =+AB16 -> 145628.56 | AD16: =+AC16 -> 145628.56
D17: ③ | E17: 2.9 | F17: =+E13+E15+E17-E6 -> 0.755 | G17: 3765 | I17: =+H16-I16 -> 0.45 | K17: － | S17: =+S16+1 -> 104 | T17: Y | U17: =+P24 -> 155635.55 | V17: =+'周面支持力(4P右)'!P24 -> 1495.2599 | W17: =+V17 -> 1495.2599 | X17: =+U17 -> 155635.55 | Y17: =+V17 -> 1495.2599 | Z17: =+Y17 -> 1495.2599 | AA17: =+X17 -> 155635.55 | AB17: =+AA17 -> 155635.55 | AC17: =+AB17 -> 155635.55 | AD17: =+AC17 -> 155635.55
H18: =+H16 -> 1.3 | J18: － | L18: =+L16+1 -> 101 | M18: =+M16+1 -> 151 | N18: － | O18: － | P18: － | S18: =+S17+1 -> 105 | T18: Y | U18: =+P26 -> 223253.67 | V18: =+'周面支持力(4P右)'!P26 -> 1927.5179 | W18: =+V18 -> 1927.5179 | X18: =+U18 -> 223253.67 | Y18: =+V18 -> 1927.5179 | Z18: =+Y18 -> 1927.5179 | AA18: =+X18 -> 223253.67 | AB18: =+AA18 -> 223253.67 | AC18: =+AB18 -> 223253.67 | AD18: =+AC18 -> 223253.67
S19: =+S18+1 -> 106 | T19: Y | U19: =+P28 -> 218434.87 | V19: =+'周面支持力(4P右)'!P28 -> 2293.614 | W19: =+V19 -> 2293.614 | X19: =+U19 -> 218434.87 | Y19: =+V19 -> 2293.614 | Z19: =+Y19 -> 2293.614 | AA19: =+X19 -> 218434.87 | AB19: =+AA19 -> 218434.87 | AC19: =+AB19 -> 218434.87 | AD19: =+AC19 -> 218434.87
H20: =+H18 -> 1.3 | I20: =+E17-I17-H18 -> 1.15 | J20: =+E3 -> 1.3 | K20: =+F17 -> 0.755 | L20: =+L18+1 -> 102 | M20: =+M18+1 -> 152 | N20: =+G17*K20+G21*K21 -> 4214.025 | O20: =+E4*N20 -> 17210.375 | P20: =+E7*O20 -> 51631.125 | S20: =+S19+1 -> 107 | T20: Y | U20: =+P30 -> 218434.87 | V20: =+'周面支持力(4P右)'!P30 -> 2293.614 | W20: =+V20 -> 2293.614 | X20: =+U20 -> 218434.87 | Y20: =+V20 -> 2293.614 | Z20: =+Y20 -> 2293.614 | AA20: =+X20 -> 218434.87 | AB20: =+AA20 -> 218434.87 | AC20: =+AB20 -> 218434.87 | AD20: =+AC20 -> 218434.87
D21: ④ | E21: 2.6 | F21: =+E21 -> 2.6 | G21: 9143 | I21: =+H20-I20 -> 0.15 | K21: =+I21 -> 0.15 | S21: =+S20+1 -> 108 | T21: Y | U21: =+P32 -> 218434.87 | V21: =+'周面支持力(4P右)'!P32 -> 2293.614 | W21: =+V21 -> 2293.614 | X21: =+U21 -> 218434.87 | Y21: =+V21 -> 2293.614 | Z21: =+Y21 -> 2293.614 | AA21: =+X21 -> 218434.87 | AB21: =+AA21 -> 218434.87 | AC21: =+AB21 -> 218434.87 | AD21: =+AC21 -> 218434.87
H22: =+H20 -> 1.3 | J22: =+J20 -> 1.3 | L22: =+L20+1 -> 103 | M22: =+M20+1 -> 153 | N22: =+G21*J22 -> 11885.9 | O22: =+E4*N22 -> 48542.853 | P22: =+E7*O22 -> 145628.56 | S22: =+S21+1 -> 109 | T22: Y | U22: =+P34 -> 218434.87 | V22: =+'周面支持力(4P右)'!P34 -> 2293.614 | W22: =+V22 -> 2293.614 | X22: =+U22 -> 218434.87 | Y22: =+V22 -> 2293.614 | Z22: =+Y22 -> 2293.614 | AA22: =+X22 -> 218434.87 | AB22: =+AA22 -> 218434.87 | AC22: =+AB22 -> 218434.87 | AD22: =+AC22 -> 218434.87
S23: =+S22+1 -> 110 | T23: Y | U23: =+P36 -> 218434.87 | V23: =+'周面支持力(4P右)'!P36 -> 2293.614 | W23: =+V23 -> 2293.614 | X23: =+U23 -> 218434.87 | Y23: =+V23 -> 2293.614 | Z23: =+Y23 -> 2293.614 | AA23: =+X23 -> 218434.87 | AB23: =+AA23 -> 218434.87 | AC23: =+AB23 -> 218434.87 | AD23: =+AC23 -> 218434.87
H24: =+H22 -> 1.3 | I24: =+E21-I21-H22 -> 1.15 | J24: =+J22 -> 1.3 | K24: =+I24 -> 1.15 | L24: =+L22+1 -> 104 | M24: =+M22+1 -> 154 | N24: =+G21*K24+G25*K25 -> 12702.65 | O24: =+E4*N24 -> 51878.517 | P24: =+E7*O24 -> 155635.55 | S24: =+S23+1 -> 111 | T24: Y | U24: =+P38 -> 218434.87 | V24: =+'周面支持力(4P右)'!P38 -> 2293.614 | W24: =+V24 -> 2293.614 | X24: =+U24 -> 218434.87 | Y24: =+V24 -> 2293.614 | Z24: =+Y24 -> 2293.614 | AA24: =+X24 -> 218434.87 | AB24: =+AA24 -> 218434.87 | AC24: =+AB24 -> 218434.87 | AD24: =+AC24 -> 218434.87
