Workbook

Sheet 変換結果
A1: 変換結果
A2: 計算確認・モデル未保存 2026-09-17T20:39:45.520468+09:00
A3: 青文字：原値 黄色：変換時の実入力（固定） 数式：再計算値。条件変更時はアプリから再実行してください。
A5: モデル: C:\Users\sasai\Documents\structural-design\test\今町橋りょう4P(C方向･右押し→).ndu
A6: 計算対象 207件 変更 0件 追加 0件 同値 207件 保留 0件
A7: 周面の抵抗0による除外: 12節点
A9: 部材の実入力
A10: 計算明細 | B10: KG | C10: 列 | D10: 部材 | E10: 上端節点 | F10: 下端節点 | G10: 水平ばね (kN/m²) | H10: 上端土圧 (kN/m) | I10: 下端土圧 (kN/m) | J10: NDU行
A11: 部材98 | B11: 4 | C11: 1 | D11: 98 | E11: 98 | F11: 99 | G11: 58812 | H11: 1162.9 | I11: 1307.5 | J11: 656
A12: 部材99 | B12: 4 | C12: 1 | D12: 99 | E12: 99 | F12: 100 | G12: 272086 | H12: 1989 | I12: 1989 | J12: 657
A13: 部材100 | B13: 4 | C13: 1 | D13: 100 | E13: 100 | F13: 101 | G13: 141501 | H13: 1826.6 | I13: 1826.6 | J13: 658
A14: 部材101 | B14: 4 | C14: 1 | D14: 101 | E14: 101 | F14: 102 | G14: 110708 | H14: 1755 | I14: 1755 | J14: 659
A15: 部材102 | B15: 4 | C15: 1 | D15: 102 | E15: 102 | F15: 103 | G15: 208029 | H15: 2158.6 | I15: 2158.6 | J15: 660
A16: 部材103 | B16: 4 | C16: 1 | D16: 103 | E16: 103 | F16: 104 | G16: 268854 | H16: 2472.8 | I16: 2673.7 | J16: 661
A17: 部材104 | B17: 4 | C17: 1 | D17: 104 | E17: 104 | F17: 105 | G17: 363440 | H17: 4642.1 | I17: 4642.1 | J17: 662
A18: 部材105 | B18: 4 | C18: 1 | D18: 105 | E18: 105 | F18: 106 | G18: 403280 | H18: 2980.8 | I18: 3190.7 | J18: 663
A19: 部材106 | B19: 4 | C19: 1 | D19: 106 | E19: 106 | F19: 107 | G19: 403280 | H19: 3190.7 | I19: 3400.6 | J19: 664
A20: 部材107 | B20: 4 | C20: 1 | D20: 107 | E20: 107 | F20: 108 | G20: 403280 | H20: 3400.6 | I20: 3610.5 | J20: 665
A21: 部材108 | B21: 4 | C21: 1 | D21: 108 | E21: 108 | F21: 109 | G21: 403280 | H21: 3610.5 | I21: 3820.5 | J21: 666
A22: 部材の実入力
A23: 計算明細 | B23: KG | C23: 列 | D23: 部材 | E23: 上端節点 | F23: 下端節点 | G23: 水平ばね (kN/m²) | H23: 上端土圧 (kN/m) | I23: 下端土圧 (kN/m) | J23: NDU行
A24: 部材109 | B24: 4 | C24: 1 | D24: 109 | E24: 109 | F24: 110 | G24: 403280 | H24: 3820.5 | I24: 4030.4 | J24: 667
A25: 部材110 | B25: 4 | C25: 1 | D25: 110 | E25: 110 | F25: 111 | G25: 403280 | H25: 4030.4 | I25: 4240.3 | J25: 668
A26: 部材111 | B26: 4 | C26: 1 | D26: 111 | E26: 111 | F26: 112 | G26: 403280 | H26: 4240.3 | I26: 4450.2 | J26: 669
A27: 部材112 | B27: 4 | C27: 1 | D27: 112 | E27: 112 | F27: 113 | G27: 225971 | H27: 3300.7 | I27: 3300.7 | J27: 670
A28: 部材113 | B28: 4 | C28: 1 | D28: 113 | E28: 113 | F28: 114 | G28: 193733 | H28: 3088.8 | I28: 3088.8 | J28: 671
A29: 部材114 | B29: 4 | C29: 1 | D29: 114 | E29: 114 | F29: 115 | G29: 193733 | H29: 3088.8 | I29: 3088.8 | J29: 672
A30: 部材115 | B30: 4 | C30: 1 | D30: 115 | E30: 115 | F30: 116 | G30: 193733 | H30: 3088.8 | I30: 3088.8 | J30: 673
A31: 部材116 | B31: 4 | C31: 1 | D31: 116 | E31: 116 | F31: 117 | G31: 193733 | H31: 3088.8 | I31: 3088.8 | J31: 674
A32: 部材117 | B32: 4 | C32: 1 | D32: 117 | E32: 117 | F32: 118 | G32: 193733 | H32: 3088.8 | I32: 3088.8 | J32: 675
A33: 部材118 | B33: 4 | C33: 1 | D33: 118 | E33: 118 | F33: 119 | G33: 193733 | H33: 3088.8 | I33: 3088.8 | J33: 676
A34: 部材119 | B34: 4 | C34: 1 | D34: 119 | E34: 119 | F34: 120 | G34: 193733 | H34: 3088.8 | I34: 3088.8 | J34: 677
A35: 部材120 | B35: 4 | C35: 1 | D35: 120 | E35: 120 | F35: 121 | G35: 193733 | H35: 3088.8 | I35: 3088.8 | J35: 678
... A38: 部材124 | B38: 5 | C38: 2 | D38: 124 | E38: 124 | F38: 125 | G38: 181391 | H38: 1719.1 | I38: 1719.1 | J38: 682
A39: 部材の実入力
A40: 計算明細 | B40: KG | C40: 列 | D40: 部材 | E40: 上端節点 | F40: 下端節点 | G40: 水平ばね (kN/m²) | H40: 上端土圧 (kN/m) | I40: 下端土圧 (kN/m) | J40: NDU行
A41: 部材125 | B41: 5 | C41: 2 | D41: 125 | E41: 125 | F41: 126 | G41: 94334 | H41: 1285.3 | I41: 1285.3 | J41: 683
A42: 部材126 | B42: 5 | C42: 2 | D42: 126 | E42: 126 | F42: 127 | G42: 73805 | H42: 1170 | I42: 1170 | J42: 684
A43: 部材127 | B43: 5 | C43: 2 | D43: 127 | E43: 127 | F43: 128 | G43: 138686 | H43: 1732.3 | I43: 1732.3 | J43: 685
A44: 部材128 | B44: 5 | C44: 2 | D44: 128 | E44: 128 | F44: 129 | G44: 179236 | H44: 2137.2 | I44: 2310.9 | J44: 686
...

Sheet 水平地盤ばね
A1: 水平地盤ばね | H1: 水平地盤ばね | O1: 水平地盤ばね
A2: 層番号 | B2: 層厚 (m) | C2: 水平地盤反力係数 Kh (kN/m²) | D2: 部材長 (m) | F2: 部材番号 | G2: 各部材の水平ばね定数 Kh (kN/m²) | H2: 層番号 | I2: 層厚 (m) | J2: 水平地盤反力係数 Kh (kN/m²) | K2: 部材長 (m) | M2: 部材番号 | N2: 各部材の水平ばね定数 Kh (kN/m²) | O2: 層番号 | P2: 層厚 (m) | Q2: 水平地盤反力係数 Kh (kN/m²) | R2: 部材長 (m) | T2: 部材番号 | U2: 各部材の水平ばね定数 Kh (kN/m²)
A3: 1 | B3: ='入力根拠'!G406 -> 1.5 | C3: ='入力根拠'!F36 -> 58812 | D3: ='入力根拠'!H434 -> 1.3 | F3: 98 | G3: =C3 -> 58812 | H3: 1 | I3: ='入力根拠'!G415 -> 1.5 | J3: ='入力根拠'!F45 -> 39208 | K3: ='入力根拠'!H462 -> 1.3 | M3: 123 | N3: =J3 -> 39208 | O3: 1 | P3: ='入力根拠'!G422 -> 1.5 | Q3: ='入力根拠'!F52 -> 58812 | R3: ='入力根拠'!H488 -> 1.3 | T3: 148 | U3: =Q3 -> 58812
C4: ='入力根拠'!F36 -> 58812 | D4: ='入力根拠'!H435 -> 1.3 | E4: =MAX(0,ROUND((MIN('入力根拠'!G435,'入力根拠'!F406)-MAX('入力根拠'!F435,'入力根拠'!E406)),4)) -> 0.2 | F4: 99 | G4: =(SUM((C4*E4),(C5*E5))/D4) -> 272085.92 | J4: ='入力根拠'!F45 -> 39208 | K4: ='入力根拠'!H463 -> 1.3 | L4: =MAX(0,ROUND((MIN('入力根拠'!G463,'入力根拠'!F415)-MAX('入力根拠'!F463,'入力根拠'!E415)),4)) -> 0.2 | M4: 124 | N4: =(SUM((J4*L4),(J5*L5))/K4) -> 181390.62 | Q4: ='入力根拠'!F52 -> 58812 | R4: ='入力根拠'!H489 -> 1.3 | S4: =MAX(0,ROUND((MIN('入力根拠'!G489,'入力根拠'!F422)-MAX('入力根拠'!F489,'入力根拠'!E422)),4)) -> 0.2 | T4: 149 | U4: =(SUM((Q4*S4),(Q5*S5))/R4) -> 272085.92
A5: 2 | B5: ='入力根拠'!G409 -> 1.3 | C5: ='入力根拠'!F39 -> 310863 | E5: =MAX(0,ROUND((MIN('入力根拠'!G435,'入力根拠'!F409)-MAX('入力根拠'!F435,'入力根拠'!E409)),4)) -> 1.1 | H5: 2 | I5: ='入力根拠'!G416 -> 1.3 | J5: ='入力根拠'!F46 -> 207242 | L5: =MAX(0,ROUND((MIN('入力根拠'!G463,'入力根拠'!F416)-MAX('入力根拠'!F463,'入力根拠'!E416)),4)) -> 1.1 | O5: 2 | P5: ='入力根拠'!G423 -> 1.3 | Q5: ='入力根拠'!F53 -> 310863 | S5: =MAX(0,ROUND((MIN('入力根拠'!G489,'入力根拠'!F423)-MAX('入力根拠'!F489,'入力根拠'!E423)),4)) -> 1.1
C6: ='入力根拠'!F39 -> 310863 | D6: ='入力根拠'!H436 -> 1.3 | E6: =MAX(0,ROUND((MIN('入力根拠'!G436,'入力根拠'!F409)-MAX('入力根拠'!F436,'入力根拠'!E409)),4)) -> 0.2 | F6: 100 | G6: =(SUM((C6*E6),(C7*E7))/D6) -> 141501.08 | J6: ='入力根拠'!F46 -> 207242 | K6: ='入力根拠'!H464 -> 1.3 | L6: =MAX(0,ROUND((MIN('入力根拠'!G464,'入力根拠'!F416)-MAX('入力根拠'!F464,'入力根拠'!E416)),4)) -> 0.2 | M6: 125 | N6: =(SUM((J6*L6),(J7*L7))/K6) -> 94333.769 | Q6: ='入力根拠'!F53 -> 310863 | R6: ='入力根拠'!H490 -> 1.3 | S6: =MAX(0,ROUND((MIN('入力根拠'!G490,'入力根拠'!F423)-MAX('入力根拠'!F490,'入力根拠'!E423)),4)) -> 0.2 | T6: 150 | U6: =(SUM((Q6*S6),(Q7*S7))/R6) -> 141501.08
A7: 3 | B7: ='入力根拠'!G410 -> 2.9 | C7: ='入力根拠'!F40 -> 110708 | E7: =MAX(0,ROUND((MIN('入力根拠'!G436,'入力根拠'!F410)-MAX('入力根拠'!F436,'入力根拠'!E410)),4)) -> 1.1 | H7: 3 | I7: ='入力根拠'!G417 -> 2.9 | J7: ='入力根拠'!F47 -> 73805 | L7: =MAX(0,ROUND((MIN('入力根拠'!G464,'入力根拠'!F417)-MAX('入力根拠'!F464,'入力根拠'!E417)),4)) -> 1.1 | O7: 3 | P7: ='入力根拠'!G426 -> 2.9 | Q7: ='入力根拠'!F56 -> 110708 | S7: =MAX(0,ROUND((MIN('入力根拠'!G490,'入力根拠'!F426)-MAX('入力根拠'!F490,'入力根拠'!E426)),4)) -> 1.1
C8: ='入力根拠'!F40 -> 110708 | D8: ='入力根拠'!H437 -> 1.3 | F8: 101 | G8: =C8 -> 110708 | J8: ='入力根拠'!F47 -> 73805 | K8: ='入力根拠'!H465 -> 1.3 | M8: 126 | N8: =J8 -> 73805 | Q8: ='入力根拠'!F56 -> 110708 | R8: ='入力根拠'!H493 -> 1.3 | T8: 151 | U8: =Q8 -> 110708
C9: ='入力根拠'!F40 -> 110708 | D9: ='入力根拠'!H438 -> 1.3 | E9: =MAX(0,ROUND((MIN('入力根拠'!G438,'入力根拠'!F410)-MAX('入力根拠'!F438,'入力根拠'!E410)),4)) -> 0.5 | F9: 102 | G9: =(SUM((C9*E9),(C10*E10))/D9) -> 208028.62 | J9: ='入力根拠'!F47 -> 73805 | K9: ='入力根拠'!H466 -> 1.3 | L9: =MAX(0,ROUND((MIN('入力根拠'!G466,'入力根拠'!F417)-MAX('入力根拠'!F466,'入力根拠'!E417)),4)) -> 0.5 | M9: 127 | N9: =(SUM((J9*L9),(J10*L10))/K9) -> 138685.62 | Q9: ='入力根拠'!F56 -> 110708 | R9: ='入力根拠'!H494 -> 1.3 | S9: =MAX(0,ROUND((MIN('入力根拠'!G494,'入力根拠'!F426)-MAX('入力根拠'!F494,'入力根拠'!E426)),4)) -> 0.5 | T9: 152 | U9: =(SUM((Q9*S9),(Q10*S10))/R9) -> 208028.62
A10: 4 | B10: ='入力根拠'!G411 -> 2.6 | C10: ='入力根拠'!F41 -> 268854 | E10: =MAX(0,ROUND((MIN('入力根拠'!G438,'入力根拠'!F411)-MAX('入力根拠'!F438,'入力根拠'!E411)),4)) -> 0.8 | H10: 4 | I10: ='入力根拠'!G418 -> 2.6 | J10: ='入力根拠'!F48 -> 179236 | L10: =MAX(0,ROUND((MIN('入力根拠'!G466,'入力根拠'!F418)-MAX('入力根拠'!F466,'入力根拠'!E418)),4)) -> 0.8 | O10: 4 | P10: ='入力根拠'!G427 -> 2.6 | Q10: ='入力根拠'!F57 -> 268854 | S10: =MAX(0,ROUND((MIN('入力根拠'!G494,'入力根拠'!F427)-MAX('入力根拠'!F494,'入力根拠'!E427)),4)) -> 0.8
C11: ='入力根拠'!F41 -> 268854 | D11: ='入力根拠'!H439 -> 1.3 | F11: 103 | G11: =C11 -> 268854 | J11: ='入力根拠'!F48 -> 179236 | K11: ='入力根拠'!H467 -> 1.3 | M11: 128 | N11: =J11 -> 179236 | Q11: ='入力根拠'!F57 -> 268854 | R11: ='入力根拠'!H495 -> 1.3 | T11: 153 | U11: =Q11 -> 268854
C12: ='入力根拠'!F41 -> 268854 | D12: ='入力根拠'!H442 -> 1.3 | E12: =MAX(0,ROUND((MIN('入力根拠'!G442,'入力根拠'!F411)-MAX('入力根拠'!F442,'入力根拠'!E411)),4)) -> 0.5 | F12: 104 | G12: =(SUM((C12*E12),(C13*E13),(C14*E14))/D12) -> 363439.69 | J12: ='入力根拠'!F48 -> 179236 | K12: ='入力根拠'!H468 -> 1.3 | L12: =MAX(0,ROUND((MIN('入力根拠'!G468,'入力根拠'!F418)-MAX('入力根拠'!F468,'入力根拠'!E418)),4)) -> 0.5 | M12: 129 | N12: =(SUM((J12*L12),(J13*L13),(J14*L14))/K12) -> 242293.08 | Q12: ='入力根拠'!F57 -> 268854 | R12: ='入力根拠'!H496 -> 1.3 | S12: =MAX(0,ROUND((MIN('入力根拠'!G496,'入力根拠'!F427)-MAX('入力根拠'!F496,'入力根拠'!E427)),4)) -> 0.5 | T12: 154 | U12: =(SUM((Q12*S12),(Q13*S13),(Q14*S14))/R12) -> 363439.69
A13: 5 | B13: ='入力根拠'!G412 -> 0.6 | C13: ='入力根拠'!F42 -> 428981 | E13: =MAX(0,ROUND((MIN('入力根拠'!G442,'入力根拠'!F412)-MAX('入力根拠'!F442,'入力根拠'!E412)),4)) -> 0.6 | H13: 5 | I13: ='入力根拠'!G419 -> 0.6 | J13: ='入力根拠'!F49 -> 285987 | L13: =MAX(0,ROUND((MIN('入力根拠'!G468,'入力根拠'!F419)-MAX('入力根拠'!F468,'入力根拠'!E419)),4)) -> 0.6 | O13: 5 | P13: ='入力根拠'!G428 -> 0.6 | Q13: ='入力根拠'!F58 -> 428981 | S13: =MAX(0,ROUND((MIN('入力根拠'!G496,'入力根拠'!F428)-MAX('入力根拠'!F496,'入力根拠'!E428)),4)) -> 0.6
A14: 6 | B14: ='入力根拠'!G413 -> 9.5 | C14: ='入力根拠'!F43 -> 403280 | E14: =MAX(0,ROUND((MIN('入力根拠'!G442,'入力根拠'!F413)-MAX('入力根拠'!F442,'入力根拠'!E413)),4)) -> 0.2 | H14: 6 | I14: ='入力根拠'!G420 -> 9.5 | J14: ='入力根拠'!F50 -> 268854 | L14: =MAX(0,ROUND((MIN('入力根拠'!G468,'入力根拠'!F420)-MAX('入力根拠'!F468,'入力根拠'!E420)),4)) -> 0.2 | O14: 6 | P14: ='入力根拠'!G429 -> 9.5 | Q14: ='入力根拠'!F59 -> 403280 | S14: =MAX(0,ROUND((MIN('入力根拠'!G496,'入力根拠'!F429)-MAX('入力根拠'!F496,'入力根拠'!E429)),4)) -> 0.2
C15: ='入力根拠'!F43 -> 403280 | D15: ='入力根拠'!H443 -> 1.3 | F15: 105 | G15: =C15 -> 403280 | J15: ='入力根拠'!F50 -> 268854 | K15: ='入力根拠'!H469 -> 1.3 | M15: 130 | N15: =J15 -> 268854 | Q15: ='入力根拠'!F59 -> 403280 | R15: ='入力根拠'!H497 -> 1.3 | T15: 155 | U15: =Q15 -> 403280
C16: ='入力根拠'!F43 -> 403280 | D16: ='入力根拠'!H444 -> 1.3 | F16: 106 | G16: =C16 -> 403280 | J16: ='入力根拠'!F50 -> 268854 | K16: ='入力根拠'!H470 -> 1.3 | M16: 131 | N16: =J16 -> 268854 | Q16: ='入力根拠'!F59 -> 403280 | R16: ='入力根拠'!H498 -> 1.3 | T16: 156 | U16: =Q16 -> 403280
C17: ='入力根拠'!F43 -> 403280 | D17: ='入力根拠'!H445 -> 1.3 | F17: 107 | G17: =C17 -> 403280 | J17: ='入力根拠'!F50 -> 268854 | K17: ='入力根拠'!H471 -> 1.3 | M17: 132 | N17: =J17 -> 268854 | Q17: ='入力根拠'!F59 -> 403280 | R17: ='入力根拠'!H499 -> 1.3 | T17: 157 | U17: =Q17 -> 403280
C18: ='入力根拠'!F43 -> 403280 | D18: ='入力根拠'!H446 -> 1.3 | F18: 108 | G18: =C18 -> 403280 | J18: ='入力根拠'!F50 -> 268854 | K18: ='入力根拠'!H472 -> 1.3 | M18: 133 | N18: =J18 -> 268854 | Q18: ='入力根拠'!F59 -> 403280 | R18: ='入力根拠'!H500 -> 1.3 | T18: 158 | U18: =Q18 -> 403280
C19: ='入力根拠'!F43 -> 403280 | D19: ='入力根拠'!H447 -> 1.3 | F19: 109 | G19: =C19 -> 403280 | J19: ='入力根拠'!F50 -> 268854 | K19: ='入力根拠'!H473 -> 1.3 | M19: 134 | N19: =J19 -> 268854 | Q19: ='入力根拠'!F59 -> 403280 | R19: ='入力根拠'!H501 -> 1.3 | T19: 159 | U19: =Q19 -> 403280
C20: ='入力根拠'!F43 -> 403280 | D20: ='入力根拠'!H448 -> 1.3 | F20: 110 | G20: =C20 -> 403280 | J20: ='入力根拠'!F50 -> 268854 | K20: ='入力根拠'!H476 -> 1.3 | M20: 135 | N20: =J20 -> 268854 | Q20: ='入力根拠'!F59 -> 403280 | R20: ='入力根拠'!H502 -> 1.3 | T20: 160 | U20: =Q20 -> 403280
C21: ='入力根拠'!F43 -> 403280 | D21: ='入力根拠'!H449 -> 1.3 | F21: 111 | G21: =C21 -> 403280 | J21: ='入力根拠'!F50 -> 268854 | K21: ='入力根拠'!H477 -> 1.3 | M21: 136 | N21: =J21 -> 268854 | Q21: ='入力根拠'!F59 -> 403280 | R21: ='入力根拠'!H503 -> 1.3 | T21: 161 | U21: =Q21 -> 403280
C22: ='入力根拠'!F43 -> 403280 | D22: ='入力根拠'!H450 -> 1.3 | E22: =MAX(0,ROUND((MIN('入力根拠'!G450,'入力根拠'!F413)-MAX('入力根拠'!F450,'入力根拠'!E413)),4)) -> 0.2 | F22: 112 | G22: =(SUM((C22*E22),(C23*E23))/D22) -> 225971 | J22: ='入力根拠'!F50 -> 268854 | K22: ='入力根拠'!H478 -> 1.3 | L22: =MAX(0,ROUND((MIN('入力根拠'!G478,'入力根拠'!F420)-MAX('入力根拠'!F478,'入力根拠'!E420)),4)) -> 0.2 | M22: 137 | N22: =(SUM((J22*L22),(J23*L23))/K22) -> 150647.15 | Q22: ='入力根拠'!F59 -> 403280 | R22: ='入力根拠'!H504 -> 1.3 | S22: =MAX(0,ROUND((MIN('入力根拠'!G504,'入力根拠'!F429)-MAX('入力根拠'!F504,'入力根拠'!E429)),4)) -> 0.2 | T22: 162 | U22: =(SUM((Q22*S22),(Q23*S23))/R22) -> 225971
A23: 7 | B23: ='入力根拠'!G414 -> 12.6 | C23: ='入力根拠'!F44 -> 193733 | E23: =MAX(0,ROUND((MIN('入力根拠'!G450,'入力根拠'!F414)-MAX('入力根拠'!F450,'入力根拠'!E414)),4)) -> 1.1 | H23: 7 | I23: ='入力根拠'!G421 -> 12.6 | J23: ='入力根拠'!F51 -> 129155 | L23: =MAX(0,ROUND((MIN('入力根拠'!G478,'入力根拠'!F421)-MAX('入力根拠'!F478,'入力根拠'!E421)),4)) -> 1.1 | O23: 7 | P23: ='入力根拠'!G430 -> 12.6 | Q23: ='入力根拠'!F60 -> 193733 | S23: =MAX(0,ROUND((MIN('入力根拠'!G504,'入力根拠'!F430)-MAX('入力根拠'!F504,'入力根拠'!E430)),4)) -> 1.1
C24: ='入力根拠'!F44 -> 193733 | D24: ='入力根拠'!H451 -> 1.3 | F24: 113 | G24: =C24 -> 193733 | J24: ='入力根拠'!F51 -> 129155 | K24: ='入力根拠'!H479 -> 1.3 | M24: 138 | N24: =J24 -> 129155 | Q24: ='入力根拠'!F60 -> 193733 | R24: ='入力根拠'!H505 -> 1.3 | T24: 163 | U24: =Q24 -> 193733
C25: ='入力根拠'!F44 -> 193733 | D25: ='入力根拠'!H452 -> 1.3 | F25: 114 | G25: =C25 -> 193733 | J25: ='入力根拠'!F51 -> 129155 | K25: ='入力根拠'!H480 -> 1.3 | M25: 139 | N25: =J25 -> 129155 | Q25: ='入力根拠'!F60 -> 193733 | R25: ='入力根拠'!H506 -> 1.3 | T25: 164 | U25: =Q25 -> 193733
C26: ='入力根拠'!F44 -> 193733 | D26: ='入力根拠'!H453 -> 1.3 | F26: 115 | G26: =C26 -> 193733 | J26: ='入力根拠'!F51 -> 129155 | K26: ='入力根拠'!H481 -> 1.3 | M26: 140 | N26: =J26 -> 129155 | Q26: ='入力根拠'!F60 -> 193733 | R26: ='入力根拠'!H507 -> 1.3 | T26: 165 | U26: =Q26 -> 193733
C27: ='入力根拠'!F44 -> 193733 | D27: ='入力根拠'!H454 -> 1.3 | F27: 116 | G27: =C27 -> 193733 | J27: ='入力根拠'!F51 -> 129155 | K27: ='入力根拠'!H482 -> 1.3 | M27: 141 | N27: =J27 -> 129155 | Q27: ='入力根拠'!F60 -> 193733 | R27: ='入力根拠'!H510 -> 1.3 | T27: 166 | U27: =Q27 -> 193733
C28: ='入力根拠'!F44 -> 193733 | D28: ='入力根拠'!H455 -> 1.3 | F28: 117 | G28: =C28 -> 193733 | J28: ='入力根拠'!F51 -> 129155 | K28: ='入力根拠'!H483 -> 1.3 | M28: 142 | N28: =J28 -> 129155 | Q28: ='入力根拠'!F60 -> 193733 | R28: ='入力根拠'!H511 -> 1.3 | T28: 167 | U28: =Q28 -> 193733
C29: ='入力根拠'!F44 -> 193733 | D29: ='入力根拠'!H456 -> 1.3 | F29: 118 | G29: =C29 -> 193733 | J29: ='入力根拠'!F51 -> 129155 | K29: ='入力根拠'!H484 -> 1.3 | M29: 143 | N29: =J29 -> 129155 | Q29: ='入力根拠'!F60 -> 193733 | R29: ='入力根拠'!H512 -> 1.3 | T29: 168 | U29: =Q29 -> 193733
C30: ='入力根拠'!F44 -> 193733 | D30: ='入力根拠'!H459 -> 1.3 | F30: 119 | G30: =C30 -> 193733 | J30: ='入力根拠'!F51 -> 129155 | K30: ='入力根拠'!H485 -> 1.3 | M30: 144 | N30: =J30 -> 129155 | Q30: ='入力根拠'!F60 -> 193733 | R30: ='入力根拠'!H513 -> 1.3 | T30: 169 | U30: =Q30 -> 193733
C31: ='入力根拠'!F44 -> 193733 | D31: ='入力根拠'!H460 -> 1.3 | F31: 120 | G31: =C31 -> 193733 | J31: ='入力根拠'!F51 -> 129155 | K31: ='入力根拠'!H486 -> 1.3 | M31: 145 | N31: =J31 -> 129155 | Q31: ='入力根拠'!F60 -> 193733 | R31: ='入力根拠'!H514 -> 1.3 | T31: 170 | U31: =Q31 -> 193733
C32: ='入力根拠'!F44 -> 193733 | D32: ='入力根拠'!H461 -> 1.1 | F32: 121 | G32: =C32 -> 193733 | J32: ='入力根拠'!F51 -> 129155 | K32: ='入力根拠'!H487 -> 1.1 | M32: 146 | N32: =J32 -> 129155 | Q32: ='入力根拠'!F60 -> 193733 | R32: ='入力根拠'!H515 -> 1.1 | T32: 171 | U32: =Q32 -> 193733
A33: Σ | B33: =SUM(B3,B5,B7,B10,B13,B14,B23) -> 31 | D33: =SUM(D3,D4,D6,D8,D9,D11,D12,D15,D16,D17,D18,D19,D20,D21,D22,D24,D25,D26,D27,D28,D29,D30,D31,D32) -> 31 | H33: Σ | I33: =SUM(I3,I5,I7,I10,I13,I14,I23) -> 31 | K33: =SUM(K3,K4,K6,K8,K9,K11,K12,K15,K16,K17,K18,K19,K20,K21,K22,K24,K25,K26,K27,K28,K29,K30,K31,K32) -> 31 | O33: Σ | P33: =SUM(P3,P5,P7,P10,P13,P14,P23) -> 31 | R33: =SUM(R3,R4,R6,R8,R9,R11,R12,R15,R16,R17,R18,R19,R20,R21,R22,R24,R25,R26,R27,R28,R29,R30,R31,R32) -> 31

Sheet 有効抵抗土圧
A1: 有効抵抗土圧
A2: 計算確認・モデル未保存 2026-09-17T20:39:45.520468+09:00
A3: 青文字：原値 黄色：変換時の実入力（固定） 数式：再計算値。条件変更時はアプリから再実行してください。
A6: 部材別の結果
A7: KG | B7: モデル列 | C7: 部材 | D7: 方法 | E7: 土圧列 | F7: 上端再計算 (kN/m) | G7: 上端実入力 (kN/m) | H7: 上端差 | I7: 下端再計算 (kN/m) | J7: 下端実入力 (kN/m) | K7: 下端差
A8: 4 | B8: 1 | C8: 98 | D8: 層内線形補間 | E8: 3 | F8: =ROUND(F277,1) -> 1162.9 | G8: 1162.9 | H8: =(F8-G8) -> 0 | I8: =ROUND(G277,1) -> 1307.5 | J8: 1307.5 | K8: =(I8-J8) -> 0
A9: 4 | B9: 1 | C9: 99 | D9: 積分平均 | E9: 3 | F9: =ROUND((SUM(I278,I279)/H92),1) -> 1989 | G9: 1989 | H9: =(F9-G9) -> 0 | I9: =ROUND((SUM(I278,I279)/H92),1) -> 1989 | J9: 1989 | K9: =(I9-J9) -> 0
A10: 4 | B10: 1 | C10: 100 | D10: 積分平均 | E10: 3 | F10: =ROUND((SUM(I280,I281)/H93),1) -> 1826.6 | G10: 1826.6 | H10: =(F10-G10) -> 0 | I10: =ROUND((SUM(I280,I281)/H93),1) -> 1826.6 | J10: 1826.6 | K10: =(I10-J10) -> 0
A11: 4 | B11: 1 | C11: 101 | D11: 層内線形補間 | E11: 3 | F11: =ROUND(F282,1) -> 1755 | G11: 1755 | H11: =(F11-G11) -> 0 | I11: =ROUND(G282,1) -> 1755 | J11: 1755 | K11: =(I11-J11) -> 0
A12: 4 | B12: 1 | C12: 102 | D12: 積分平均 | E12: 3 | F12: =ROUND((SUM(I283,I284)/H95),1) -> 2158.6 | G12: 2158.6 | H12: =(F12-G12) -> 0 | I12: =ROUND((SUM(I283,I284)/H95),1) -> 2158.6 | J12: 2158.6 | K12: =(I12-J12) -> 0
A13: 4 | B13: 1 | C13: 103 | D13: 層内線形補間 | E13: 3 | F13: =ROUND(F285,1) -> 2472.8 | G13: 2472.8 | H13: =(F13-G13) -> 0 | I13: =ROUND(G285,1) -> 2673.7 | J13: 2673.7 | K13: =(I13-J13) -> 0
A14: 4 | B14: 1 | C14: 104 | D14: 積分平均 | E14: 3 | F14: =ROUND((SUM(I286,I287,I288)/H97),1) -> 4642.1 | G14: 4642.1 | H14: =(F14-G14) -> 0 | I14: =ROUND((SUM(I286,I287,I288)/H97),1) -> 4642.1 | J14: 4642.1 | K14: =(I14-J14) -> 0
A15: 4 | B15: 1 | C15: 105 | D15: 層内線形補間 | E15: 3 | F15: =ROUND(F289,1) -> 2980.8 | G15: 2980.8 | H15: =(F15-G15) -> 0 | I15: =ROUND(G289,1) -> 3190.7 | J15: 3190.7 | K15: =(I15-J15) -> 0
A16: 4 | B16: 1 | C16: 106 | D16: 層内線形補間 | E16: 3 | F16: =ROUND(F290,1) -> 3190.7 | G16: 3190.7 | H16: =(F16-G16) -> 0 | I16: =ROUND(G290,1) -> 3400.6 | J16: 3400.6 | K16: =(I16-J16) -> 0
A17: 4 | B17: 1 | C17: 107 | D17: 層内線形補間 | E17: 3 | F17: =ROUND(F293,1) -> 3400.6 | G17: 3400.6 | H17: =(F17-G17) -> 0 | I17: =ROUND(G293,1) -> 3610.5 | J17: 3610.5 | K17: =(I17-J17) -> 0
A18: 4 | B18: 1 | C18: 108 | D18: 層内線形補間 | E18: 3 | F18: =ROUND(F294,1) -> 3610.5 | G18: 3610.5 | H18: =(F18-G18) -> 0 | I18: =ROUND(G294,1) -> 3820.5 | J18: 3820.5 | K18: =(I18-J18) -> 0
A19: 4 | B19: 1 | C19: 109 | D19: 層内線形補間 | E19: 3 | F19: =ROUND(F295,1) -> 3820.5 | G19: 3820.5 | H19: =(F19-G19) -> 0 | I19: =ROUND(G295,1) -> 4030.4 | J19: 4030.4 | K19: =(I19-J19) -> 0
A20: 4 | B20: 1 | C20: 110 | D20: 層内線形補間 | E20: 3 | F20: =ROUND(F296,1) -> 4030.4 | G20: 4030.4 | H20: =(F20-G20) -> 0 | I20: =ROUND(G296,1) -> 4240.3 | J20: 4240.3 | K20: =(I20-J20) -> 0
A21: 4 | B21: 1 | C21: 111 | D21: 層内線形補間 | E21: 3 | F21: =ROUND(F297,1) -> 4240.3 | G21: 4240.3 | H21: =(F21-G21) -> 0 | I21: =ROUND(G297,1) -> 4450.2 | J21: 4450.2 | K21: =(I21-J21) -> 0
A22: 部材別の結果
A23: KG | B23: モデル列 | C23: 部材 | D23: 方法 | E23: 土圧列 | F23: 上端再計算 (kN/m) | G23: 上端実入力 (kN/m) | H23: 上端差 | I23: 下端再計算 (kN/m) | J23: 下端実入力 (kN/m) | K23: 下端差
A24: 4 | B24: 1 | C24: 112 | D24: 積分平均 | E24: 3 | F24: =ROUND((SUM(I298,I299)/H105),1) -> 3300.7 | G24: 3300.7 | H24: =(F24-G24) -> 0 | I24: =ROUND((SUM(I298,I299)/H105),1) -> 3300.7 | J24: 3300.7 | K24: =(I24-J24) -> 0
A25: 4 | B25: 1 | C25: 113 | D25: 層内線形補間 | E25: 3 | F25: =ROUND(F300,1) -> 3088.8 | G25: 3088.8 | H25: =(F25-G25) -> 0 | I25: =ROUND(G300,1) -> 3088.8 | J25: 3088.8 | K25: =(I25-J25) -> 0
A26: 4 | B26: 1 | C26: 114 | D26: 層内線形補間 | E26: 3 | F26: =ROUND(F301,1) -> 3088.8 | G26: 3088.8 | H26: =(F26-G26) -> 0 | I26: =ROUND(G301,1) -> 3088.8 | J26: 3088.8 | K26: =(I26-J26) -> 0
A27: 4 | B27: 1 | C27: 115 | D27: 層内線形補間 | E27: 3 | F27: =ROUND(F302,1) -> 3088.8 | G27: 3088.8 | H27: =(F27-G27) -> 0 | I27: =ROUND(G302,1) -> 3088.8 | J27: 3088.8 | K27: =(I27-J27) -> 0
A28: 4 | B28: 1 | C28: 116 | D28: 層内線形補間 | E28: 3 | F28: =ROUND(F303,1) -> 3088.8 | G28: 3088.8 | H28: =(F28-G28) -> 0 | I28: =ROUND(G303,1) -> 3088.8 | J28: 3088.8 | K28: =(I28-J28) -> 0
A29: 4 | B29: 1 | C29: 117 | D29: 層内線形補間 | E29: 3 | F29: =ROUND(F304,1) -> 3088.8 | G29: 3088.8 | H29: =(F29-G29) -> 0 | I29: =ROUND(G304,1) -> 3088.8 | J29: 3088.8 | K29: =(I29-J29) -> 0
A30: 4 | B30: 1 | C30: 118 | D30: 層内線形補間 | E30: 3 | F30: =ROUND(F305,1) -> 3088.8 | G30: 3088.8 | H30: =(F30-G30) -> 0 | I30: =ROUND(G305,1) -> 3088.8 | J30: 3088.8 | K30: =(I30-J30) -> 0
A31: 4 | B31: 1 | C31: 119 | D31: 層内線形補間 | E31: 3 | F31: =ROUND(F306,1) -> 3088.8 | G31: 3088.8 | H31: =(F31-G31) -> 0 | I31: =ROUND(G306,1) -> 3088.8 | J31: 3088.8 | K31: =(I31-J31) -> 0
A32: 4 | B32: 1 | C32: 120 | D32: 層内線形補間 | E32: 3 | F32: =ROUND(F307,1) -> 3088.8 | G32: 3088.8 | H32: =(F32-G32) -> 0 | I32: =ROUND(G307,1) -> 3088.8 | J32: 3088.8 | K32: =(I32-J32) -> 0
A33: 4 | B33: 1 | C33: 121 | D33: 層内線形補間 | E33: 3 | F33: =ROUND(F310,1) -> 3088.8 | G33: 3088.8 | H33: =(F33-G33) -> 0 | I33: =ROUND(G310,1) -> 3088.8 | J33: 3088.8 | K33: =(I33-J33) -> 0
A34: 5 | B34: 2 | C34: 123 | D34: 層内線形補間 | E34: 2 | F34: =ROUND(F311,1) -> 1005.1 | G34: 1005.1 | H34: =(F34-G34) -> 0 | I34: =ROUND(G311,1) -> 1130.1 | J34: 1130.1 | K34: =(I34-J34) -> 0
A35: 5 | B35: 2 | C35: 124 | D35: 積分平均 | E35: 2 | F35: =ROUND((SUM(I312,I313)/H118),1) -> 1719.1 | G35: 1719.1 | H35: =(F35-G35) -> 0 | I35: =ROUND((SUM(I312,I313)/H118),1) -> 1719.1 | J35: 1719.1 | K35: =(I35-J35) -> 0
A36: 5 | B36: 2 | C36: 125 | D36: 積分平均 | E36: 2 | F36: =ROUND((SUM(I314,I315)/H119),1) -> 1285.3 | G36: 1285.3 | H36: =(F36-G36) -> 0 | I36: =ROUND((SUM(I314,I315)/H119),1) -> 1285.3 | J36: 1285.3 | K36: =(I36-J36) -> 0
A37: 5 | B37: 2 | C37: 126 | D37: 層内線形補間 | E37: 2 | F37: =ROUND(F316,1) -> 1170 | G37: 1170 | H37: =(F37-G37) -> 0 | I37: =ROUND(G316,1) -> 1170 | J37: 1170 | K37: =(I37-J37) -> 0
A38: 5 | B38: 2 | C38: 127 | D38: 積分平均 | E38: 2 | F38: =ROUND((SUM(I317,I318)/H121),1) -> 1732.3 | G38: 1732.3 | H38: =(F38-G38) -> 0 | I38: =ROUND((SUM(I317,I318)/H121),1) -> 1732.3 | J38: 1732.3 | K38: =(I38-J38) -> 0
A39: 部材別の結果
A40: KG | B40: モデル列 | C40: 部材 | D40: 方法 | E40: 土圧列 | F40: 上端再計算 (kN/m) | G40: 上端実入力 (kN/m) | H40: 上端差 | I40: 下端再計算 (kN/m) | J40: 下端実入力 (kN/m) | K40: 下端差
A41: 5 | B41: 2 | C41: 128 | D41: 層内線形補間 | E41: 2 | F41: =ROUND(F319,1) -> 2137.2 | G41: 2137.2 | H41: =(F41-G41) -> 0 | I41: =ROUND(G319,1) -> 2310.9 | J41: 2310.9 | K41: =(I41-J41) -> 0
A42: 5 | B42: 2 | C42: 129 | D42: 積分平均 | E42: 2 | F42: =ROUND((SUM(I320,I321,I322)/H125),1) -> 3391.1 | G42: 3391.1 | H42: =(F42-G42) -> 0 | I42: =ROUND((SUM(I320,I321,I322)/H125),1) -> 3391.1 | J42: 3391.1 | K42: =(I42-J42) -> 0
...

Sheet 杭周面ばね
A1: 杭周面ばね
A2: 計算確認・モデル未保存 2026-09-17T20:39:45.520468+09:00
A3: 青文字：原値 黄色：変換時の実入力（固定） 数式：再計算値。条件変更時はアプリから再実行してください。
A5: 既存画面方式：押込みK1/Fyを正負へ配置。長さ積分後に丸め、平均の除算・1.2補正・本数の追加乗算はしません。
A7: 節点別の結果
A8: KG | B8: 列 | C8: 節点 | D8: 有効長 (m) | E8: K丸め前 (kN/m) | F8: K再計算 (kN/m) | G8: K実入力 (kN/m) | H8: K差 | I8: F丸め前 (kN) | J8: F再計算 (kN) | K8: F実入力 (kN) | L8: F差
A9: 4 | B9: 1 | C9: 102 | D9: =SUM(K155,K158) -> 0.905 | E9: =SUM(I240,I241) -> 51628.885 | F9: =ROUND(E9,0) -> 51629 | G9: 51629 | H9: =(F9-G9) -> 0 | I9: =SUM(J240,J241) -> 433.7705 | J9: =ROUND(I9,1) -> 433.8 | K9: 433.8 | L9: =(J9-K9) -> 0
A10: 4 | B10: 1 | C10: 103 | D10: =SUM(K159) -> 1.3 | E10: =SUM(I242) -> 145626 | F10: =ROUND(E10,0) -> 145626 | G10: 145626 | H10: =(F10-G10) -> 0 | I10: =SUM(J242) -> 1834.95 | J10: =ROUND(I10,1) -> 1835 | K10: 1835 | L10: =(J10-K10) -> 0
A11: 4 | B11: 1 | C11: 104 | D11: =SUM(K160,K161) -> 1.3 | E11: =SUM(I243,I244) -> 155633.7 | F11: =ROUND(E11,0) -> 155634 | G11: 155634 | H11: =(F11-G11) -> 0 | I11: =SUM(J243,J244) -> 1794.36 | J11: =ROUND(I11,1) -> 1794.4 | K11: 1794.4 | L11: =(J11-K11) -> 0
A12: 4 | B12: 1 | C12: 105 | D12: =SUM(K162,K163) -> 1.3 | E12: =SUM(I245,I246) -> 223256.75 | F12: =ROUND(E12,0) -> 223257 | G12: 223257 | H12: =(F12-G12) -> 0 | I12: =SUM(J245,J246) -> 2313.025 | J12: =ROUND(I12,1) -> 2313 | K12: 2313 | L12: =(J12-K12) -> 0
A13: 4 | B13: 1 | C13: 106 | D13: =SUM(K164) -> 1.3 | E13: =SUM(I247) -> 218437.7 | F13: =ROUND(E13,0) -> 218438 | G13: 218438 | H13: =(F13-G13) -> 0 | I13: =SUM(J247) -> 2752.36 | J13: =ROUND(I13,1) -> 2752.4 | K13: 2752.4 | L13: =(J13-K13) -> 0
A14: 4 | B14: 1 | C14: 107 | D14: =SUM(K165) -> 1.3 | E14: =SUM(I248) -> 218437.7 | F14: =ROUND(E14,0) -> 218438 | G14: 218438 | H14: =(F14-G14) -> 0 | I14: =SUM(J248) -> 2752.36 | J14: =ROUND(I14,1) -> 2752.4 | K14: 2752.4 | L14: =(J14-K14) -> 0
A15: 4 | B15: 1 | C15: 108 | D15: =SUM(K166) -> 1.3 | E15: =SUM(I249) -> 218437.7 | F15: =ROUND(E15,0) -> 218438 | G15: 218438 | H15: =(F15-G15) -> 0 | I15: =SUM(J249) -> 2752.36 | J15: =ROUND(I15,1) -> 2752.4 | K15: 2752.4 | L15: =(J15-K15) -> 0
A16: 4 | B16: 1 | C16: 109 | D16: =SUM(K167) -> 1.3 | E16: =SUM(I250) -> 218437.7 | F16: =ROUND(E16,0) -> 218438 | G16: 218438 | H16: =(F16-G16) -> 0 | I16: =SUM(J250) -> 2752.36 | J16: =ROUND(I16,1) -> 2752.4 | K16: 2752.4 | L16: =(J16-K16) -> 0
A17: 4 | B17: 1 | C17: 110 | D17: =SUM(K168) -> 1.3 | E17: =SUM(I251) -> 218437.7 | F17: =ROUND(E17,0) -> 218438 | G17: 218438 | H17: =(F17-G17) -> 0 | I17: =SUM(J251) -> 2752.36 | J17: =ROUND(I17,1) -> 2752.4 | K17: 2752.4 | L17: =(J17-K17) -> 0
A18: 4 | B18: 1 | C18: 111 | D18: =SUM(K169) -> 1.3 | E18: =SUM(I252) -> 218437.7 | F18: =ROUND(E18,0) -> 218438 | G18: 218438 | H18: =(F18-G18) -> 0 | I18: =SUM(J252) -> 2752.36 | J18: =ROUND(I18,1) -> 2752.4 | K18: 2752.4 | L18: =(J18-K18) -> 0
A19: 4 | B19: 1 | C19: 112 | D19: =SUM(K170,K171) -> 1.3 | E19: =SUM(I253,I254) -> 179148.65 | F19: =ROUND(E19,0) -> 179149 | G19: 179149 | H19: =(F19-G19) -> 0 | I19: =SUM(J253,J254) -> 2032.495 | J19: =ROUND(I19,1) -> 2032.5 | K19: 2032.5 | L19: =(J19-K19) -> 0
A20: 4 | B20: 1 | C20: 113 | D20: =SUM(K172) -> 1.3 | E20: =SUM(I257) -> 104936 | F20: =ROUND(E20,0) -> 104936 | G20: 104936 | H20: =(F20-G20) -> 0 | I20: =SUM(J257) -> 672.75 | J20: =ROUND(I20,1) -> 672.8 | K20: 672.8 | L20: =(J20-K20) -> 0
A21: 4 | B21: 1 | C21: 114 | D21: =SUM(K175) -> 1.3 | E21: =SUM(I258) -> 104936 | F21: =ROUND(E21,0) -> 104936 | G21: 104936 | H21: =(F21-G21) -> 0 | I21: =SUM(J258) -> 672.75 | J21: =ROUND(I21,1) -> 672.8 | K21: 672.8 | L21: =(J21-K21) -> 0
A22: 節点別の結果
A23: KG | B23: 列 | C23: 節点 | D23: 有効長 (m) | E23: K丸め前 (kN/m) | F23: K再計算 (kN/m) | G23: K実入力 (kN/m) | H23: K差 | I23: F丸め前 (kN) | J23: F再計算 (kN) | K23: F実入力 (kN) | L23: F差
A24: 4 | B24: 1 | C24: 115 | D24: =SUM(K176) -> 1.3 | E24: =SUM(I259) -> 104936 | F24: =ROUND(E24,0) -> 104936 | G24: 104936 | H24: =(F24-G24) -> 0 | I24: =SUM(J259) -> 672.75 | J24: =ROUND(I24,1) -> 672.8 | K24: 672.8 | L24: =(J24-K24) -> 0
A25: 4 | B25: 1 | C25: 116 | D25: =SUM(K177) -> 1.3 | E25: =SUM(I260) -> 104936 | F25: =ROUND(E25,0) -> 104936 | G25: 104936 | H25: =(F25-G25) -> 0 | I25: =SUM(J260) -> 672.75 | J25: =ROUND(I25,1) -> 672.8 | K25: 672.8 | L25: =(J25-K25) -> 0
A26: 4 | B26: 1 | C26: 117 | D26: =SUM(K178) -> 1.3 | E26: =SUM(I261) -> 104936 | F26: =ROUND(E26,0) -> 104936 | G26: 104936 | H26: =(F26-G26) -> 0 | I26: =SUM(J261) -> 672.75 | J26: =ROUND(I26,1) -> 672.8 | K26: 672.8 | L26: =(J26-K26) -> 0
A27: 4 | B27: 1 | C27: 118 | D27: =SUM(K179) -> 1.3 | E27: =SUM(I262) -> 104936 | F27: =ROUND(E27,0) -> 104936 | G27: 104936 | H27: =(F27-G27) -> 0 | I27: =SUM(J262) -> 672.75 | J27: =ROUND(I27,1) -> 672.8 | K27: 672.8 | L27: =(J27-K27) -> 0
A28: 4 | B28: 1 | C28: 119 | D28: =SUM(K180) -> 1.3 | E28: =SUM(I263) -> 104936 | F28: =ROUND(E28,0) -> 104936 | G28: 104936 | H28: =(F28-G28) -> 0 | I28: =SUM(J263) -> 672.75 | J28: =ROUND(I28,1) -> 672.8 | K28: 672.8 | L28: =(J28-K28) -> 0
A29: 4 | B29: 1 | C29: 120 | D29: =SUM(K181) -> 1.3 | E29: =SUM(I264) -> 104936 | F29: =ROUND(E29,0) -> 104936 | G29: 104936 | H29: =(F29-G29) -> 0 | I29: =SUM(J264) -> 672.75 | J29: =ROUND(I29,1) -> 672.8 | K29: 672.8 | L29: =(J29-K29) -> 0
A30: 4 | B30: 1 | C30: 121 | D30: =SUM(K182) -> 0.45 | E30: =SUM(I265) -> 36324 | F30: =ROUND(E30,0) -> 36324 | G30: 36324 | H30: =(F30-G30) -> 0 | I30: =SUM(J265) -> 232.875 | J30: =ROUND(I30,1) -> 232.9 | K30: 232.9 | L30: =(J30-K30) -> 0
A31: 5 | B31: 2 | C31: 127 | D31: =SUM(K183,K184) -> 0.905 | E31: =SUM(I266,I267) -> 34419.005 | F31: =ROUND(E31,0) -> 34419 | G31: 34419 | H31: =(F31-G31) -> 0 | I31: =SUM(J266,J267) -> 289.13 | J31: =ROUND(I31,1) -> 289.1 | K31: 289.1 | L31: =(J31-K31) -> 0
A32: 5 | B32: 2 | C32: 128 | D32: =SUM(K185) -> 1.3 | E32: =SUM(I268) -> 97084 | F32: =ROUND(E32,0) -> 97084 | G32: 97084 | H32: =(F32-G32) -> 0 | I32: =SUM(J268) -> 1223.3 | J32: =ROUND(I32,1) -> 1223.3 | K32: 1223.3 | L32: =(J32-K32) -> 0
A33: 5 | B33: 2 | C33: 129 | D33: =SUM(K186,K187) -> 1.3 | E33: =SUM(I269,I270) -> 103755.7 | F33: =ROUND(E33,0) -> 103756 | G33: 103756 | H33: =(F33-G33) -> 0 | I33: =SUM(J269,J270) -> 1196.24 | J33: =ROUND(I33,1) -> 1196.2 | K33: 1196.2 | L33: =(J33-K33) -> 0
A34: 5 | B34: 2 | C34: 130 | D34: =SUM(K188,K189) -> 1.3 | E34: =SUM(I271,I274) -> 148838.1 | F34: =ROUND(E34,0) -> 148838 | G34: 148838 | H34: =(F34-G34) -> 0 | I34: =SUM(J271,J274) -> 1542.045 | J34: =ROUND(I34,1) -> 1542 | K34: 1542 | L34: =(J34-K34) -> 0
A35: 5 | B35: 2 | C35: 131 | D35: =SUM(K192) -> 1.3 | E35: =SUM(I275) -> 145626 | F35: =ROUND(E35,0) -> 145626 | G35: 145626 | H35: =(F35-G35) -> 0 | I35: =SUM(J275) -> 1834.95 | J35: =ROUND(I35,1) -> 1835 | K35: 1835 | L35: =(J35-K35) -> 0
A36: 5 | B36: 2 | C36: 132 | D36: =SUM(K193) -> 1.3 | E36: =SUM(I276) -> 145626 | F36: =ROUND(E36,0) -> 145626 | G36: 145626 | H36: =(F36-G36) -> 0 | I36: =SUM(J276) -> 1834.95 | J36: =ROUND(I36,1) -> 1835 | K36: 1835 | L36: =(J36-K36) -> 0
A37: 5 | B37: 2 | C37: 133 | D37: =SUM(K194) -> 1.3 | E37: =SUM(I277) -> 145626 | F37: =ROUND(E37,0) -> 145626 | G37: 145626 | H37: =(F37-G37) -> 0 | I37: =SUM(J277) -> 1834.95 | J37: =ROUND(I37,1) -> 1835 | K37: 1835 | L37: =(J37-K37) -> 0
A38: 5 | B38: 2 | C38: 134 | D38: =SUM(K195) -> 1.3 | E38: =SUM(I278) -> 145626 | F38: =ROUND(E38,0) -> 145626 | G38: 145626 | H38: =(F38-G38) -> 0 | I38: =SUM(J278) -> 1834.95 | J38: =ROUND(I38,1) -> 1835 | K38: 1835 | L38: =(J38-K38) -> 0
A39: 節点別の結果
A40: KG | B40: 列 | C40: 節点 | D40: 有効長 (m) | E40: K丸め前 (kN/m) | F40: K再計算 (kN/m) | G40: K実入力 (kN/m) | H40: K差 | I40: F丸め前 (kN) | J40: F再計算 (kN) | K40: F実入力 (kN) | L40: F差
A41: 5 | B41: 2 | C41: 135 | D41: =SUM(K196) -> 1.3 | E41: =SUM(I279) -> 145626 | F41: =ROUND(E41,0) -> 145626 | G41: 145626 | H41: =(F41-G41) -> 0 | I41: =SUM(J279) -> 1834.95 | J41: =ROUND(I41,1) -> 1835 | K41: 1835 | L41: =(J41-K41) -> 0
A42: 5 | B42: 2 | C42: 136 | D42: =SUM(K197) -> 1.3 | E42: =SUM(I280) -> 145626 | F42: =ROUND(E42,0) -> 145626 | G42: 145626 | H42: =(F42-G42) -> 0 | I42: =SUM(J280) -> 1834.95 | J42: =ROUND(I42,1) -> 1835 | K42: 1835 | L42: =(J42-K42) -> 0
...

Sheet 杭先端ばね
A1: 杭先端ばね
A2: 計算確認・モデル未保存 2026-09-17T20:39:45.520468+09:00
A3: 青文字：原値 黄色：変換時の実入力（固定） 数式：再計算値。条件変更時はアプリから再実行してください。
A5: SDCの短期K1/K2・押込みFy/Fuを転記。負側制限値F1−/F2−は空欄のまま転記します。
A7: 杭先端の結果
A8: KG | B8: 列 | C8: 先端節点 | D8: K1再計算 (kN/m) | E8: K1実入力 (kN/m) | F8: K2再計算 (kN/m) | G8: K2実入力 (kN/m) | H8: Fy再計算 (kN) | I8: Fy実入力 (kN) | J8: Fu再計算 (kN) | K8: Fu実入力 (kN)
A9: 4 | B9: 1 | C9: 122 | D9: ='入力根拠'!F143 -> 327072 | E9: 327072 | F9: ='入力根拠'!F144 -> 88418 | G9: 88418 | H9: ='入力根拠'!F145 -> 7167.5 | I9: 7167.5 | J9: ='入力根拠'!F146 -> 16724.3 | K9: 16724.3
A10: 5 | B10: 2 | C10: 147 | D10: ='入力根拠'!F147 -> 218048 | E10: 218048 | F10: ='入力根拠'!F148 -> 58945 | G10: 58945 | H10: ='入力根拠'!F149 -> 4778.4 | I10: 4778.4 | J10: ='入力根拠'!F150 -> 11149.5 | K10: 11149.5
A11: 6 | B11: 3 | C11: 172 | D11: ='入力根拠'!F151 -> 327072 | E11: 327072 | F11: ='入力根拠'!F152 -> 88418 | G11: 88418 | H11: ='入力根拠'!F153 -> 7167.5 | I11: 7167.5 | J11: ='入力根拠'!F154 -> 16724.3 | K11: 16724.3
A13: 杭頭・最深節点と杭長
A14: KG | B14: 列 | C14: 杭頭節点 | D14: 先端節点 | E14: x座標 (m) | F14: 杭頭y (m) | G14: 先端y (m) | H14: 座標差 (m) | I14: SDC杭長 (m)
A15: 4 | B15: 1 | C15: 98 | D15: 122 | E15: 29.8 | F15: 13.041 | G15: 44.041 | H15: =ROUND((G15-F15),4) -> 31 | I15: 31
A16: 5 | B16: 2 | C16: 123 | D16: 147 | E16: 33.5 | F16: 13.041 | G16: 44.041 | H16: =ROUND((G16-F16),4) -> 31 | I16: 31
A17: 6 | B17: 3 | C17: 148 | D17: 172 | E17: 37.2 | F17: 13.041 | G17: 44.041 | H17: =ROUND((G17-F17),4) -> 31 | I17: 31
A19: ばね実入力 (kN/m)
A20: KG | B20: 列 | C20: 節点 | D20: 支点項目 | E20: K1+ | F20: K2+ | G20: K3+ | H20: K1- | I20: K2- | J20: K3-
A21: 4 | B21: 1 | C21: 122 | D21: 61 | E21: 327072 | F21: 88418 | G21: 88418 | H21: 327072 | I21: 88418 | J21: 88418
A22: 5 | B22: 2 | C22: 147 | D22: 62 | E22: 218048 | F22: 58945 | G22: 58945 | H22: 218048 | I22: 58945 | J22: 58945
A23: 6 | B23: 3 | C23: 172 | D23: 63 | E23: 327072 | F23: 88418 | G23: 88418 | H23: 327072 | I23: 88418 | J23: 88418
A25: 制限値実入力 (kN)
A26: KG | B26: 列 | C26: 節点 | D26: 支点項目 | E26: F1+ | F26: F1- | G26: F2+ | H26: F2-
A27: 4 | B27: 1 | C27: 122 | D27: 61 | E27: 7167.5 | G27: 16724.3
A28: 5 | B28: 2 | C28: 147 | D28: 62 | E28: 4778.4 | G28: 11149.5
A29: 6 | B29: 3 | C29: 172 | D29: 63 | E29: 7167.5 | G29: 16724.3
A31: Python Decimalの丸め前文字列
A32: KG | B32: 対象 | C32: 項目 | D32: 正確な計算記録
A33: KG4 122 k1_kN_per_m: 327072
A34: Python Decimalの丸め前文字列
A35: KG | B35: 対象 | C35: 項目 | D35: 正確な計算記録
A36: KG4 122 k2_kN_per_m: 88418
A37: KG4 122 fy_kN: 7167.5
A38: KG4 122 fu_kN: 16724.3
A39: KG5 147 k1_kN_per_m: 218048
A40: KG5 147 k2_kN_per_m: 58945
A41: KG5 147 fy_kN: 4778.4
A42: KG5 147 fu_kN: 11149.5
A43: KG6 172 k1_kN_per_m: 327072
A44: KG6 172 k2_kN_per_m: 88418
A45: KG6 172 fy_kN: 7167.5
A46: KG6 172 fu_kN: 16724.3

Sheet 入力根拠
A1: 入力根拠
A2: 計算確認・モデル未保存 2026-09-17T20:39:45.520468+09:00
A3: 青文字：原値 黄色：変換時の実入力（固定） 数式：再計算値。条件変更時はアプリから再実行してください。
A6: 実行・ファイル情報
A7: 項目 | B7: 値
A8: 実行ID: 91599c2d83ee45bcb009aa4d9a63066d
A9: アプリ: SDCConverter 1.1.0
A10: 帳票スキーマ: 1
A11: 対象モデル: C:\Users\sasai\Documents\structural-design\test\今町橋りょう4P(C方向･右押し→).ndu
A12: 状態: 計算確認・モデル未保存
A13: モデル出力: 未保存
A14: 出力予定SHA-256: 31e9e85971d07ae1a0b21273f500b0d8d039184ecf9febb6db642fbfabfbd22a
A15: JSON: 未保存
A16: Excel: C:\Users\sasai\Documents\structural-design\outputs\horizontal-spring-review-20260917-203945\今町橋りょう4P_計算過程_水平地盤ばね修正版.xlsx
A17: バックアップ: なし
A18: 杭対応: 4:1 5:2 6:3
A19: 土圧方向: right
... A21: 実行・ファイル情報
A22: 項目 | B22: 値
A23: 水平境界: length-weighted
A24: 土圧境界: integral-average
A25: 土圧小数桁: 1
A26: 周面K小数桁: 0
A27: 周面F小数桁: 1
A28: 丸め: ROUND_HALF_UP（先端・水平単一層は原値）
A29: 入力: C:\Users\sasai\Documents\structural-design\test\今町橋りょう4P(右).sdc
A30: SHA-256: 9b9aed2461b87acb5193c8eac79cf07b6d9824bdbd80e096416e197f324f64a7
A31: 入力: C:\Users\sasai\Documents\structural-design\test\今町橋りょう4P(C方向･右押し→).ndu
A32: SHA-256: 31e9e85971d07ae1a0b21273f500b0d8d039184ecf9febb6db642fbfabfbd22a
A34: 採用したSDC原値
A35: 処理 | B35: SDC行 | C35: CSV欄 | D35: 項目 | E35: 単位 | F35: 原値 | G35: 正確な十進文字列
A36: 水平地盤ばね | B36: 174 | C36: 9 | D36: 1列目 短期(非線形) | E36: kN/m² | F36: 58812 | G36: 58812
A37: 採用したSDC原値
A38: 処理 | B38: SDC行 | C38: CSV欄 | D38: 項目 | E38: 単位 | F38: 原値 | G38: 正確な十進文字列
A39: 水平地盤ばね | B39: 175 | C39: 9 | D39: 1列目 短期(非線形) | E39: kN/m² | F39: 310863 | G39: 310863
A40: 水平地盤ばね | B40: 176 | C40: 9 | D40: 1列目 短期(非線形) | E40: kN/m² | F40: 110708 | G40: 110708
A41: 水平地盤ばね | B41: 177 | C41: 9 | D41: 1列目 短期(非線形) | E41: kN/m² | F41: 268854 | G41: 268854
A42: 水平地盤ばね | B42: 178 | C42: 9 | D42: 1列目 短期(非線形) | E42: kN/m² | F42: 428981 | G42: 428981
A43: 水平地盤ばね | B43: 179 | C43: 9 | D43: 1列目 短期(非線形) | E43: kN/m² | F43: 403280 | G43: 403280
A44: 水平地盤ばね | B44: 180 | C44: 9 | D44: 1列目 短期(非線形) | E44: kN/m² | F44: 193733 | G44: 193733
...
