Workbook

Sheet 変換結果
A1: 変換結果
A2: 計算確認・モデル未保存 2026-09-18T00:52:32.060467+09:00
A3: 青文字：原値 黄色：変換時の実入力（固定） 数式：再計算値。条件変更時はアプリから再実行してください。
A5: モデル: C:\Users\sasai\Documents\structural-design\test\今町橋りょう4P(C方向･右押し→).ndu
A6: 計算対象 207件 変更 0件 追加 0件 同値 207件 保留 0件
A7: 周面の抵抗0による除外: 12節点
A9: 部材の実入力
A10: 計算明細 | B10: KG | C10: 列 | D10: 部材 | E10: 上端節点 | F10: 下端節点 | G10: 水平ばね (kN/m²) | H10: 上端土圧 (kN/m) | I10: 下端土圧 (kN/m) | J10: NDU行 | K10: 土圧明細
A11: 部材98 | B11: 4 | C11: 1 | D11: 98 | E11: 98 | F11: 99 | G11: 58812 | H11: 1162.9 | I11: 1307.5 | J11: 656 | K11: 土圧98
A12: 部材99 | B12: 4 | C12: 1 | D12: 99 | E12: 99 | F12: 100 | G12: 272086 | H12: 1989 | I12: 1989 | J12: 657 | K12: 土圧99
A13: 部材100 | B13: 4 | C13: 1 | D13: 100 | E13: 100 | F13: 101 | G13: 141501 | H13: 1826.6 | I13: 1826.6 | J13: 658 | K13: 土圧100
A14: 部材101 | B14: 4 | C14: 1 | D14: 101 | E14: 101 | F14: 102 | G14: 110708 | H14: 1755 | I14: 1755 | J14: 659 | K14: 土圧101
A15: 部材102 | B15: 4 | C15: 1 | D15: 102 | E15: 102 | F15: 103 | G15: 208029 | H15: 2158.6 | I15: 2158.6 | J15: 660 | K15: 土圧102
A16: 部材103 | B16: 4 | C16: 1 | D16: 103 | E16: 103 | F16: 104 | G16: 268854 | H16: 2472.8 | I16: 2673.7 | J16: 661 | K16: 土圧103
A17: 部材104 | B17: 4 | C17: 1 | D17: 104 | E17: 104 | F17: 105 | G17: 363440 | H17: 4642.1 | I17: 4642.1 | J17: 662 | K17: 土圧104
A18: 部材105 | B18: 4 | C18: 1 | D18: 105 | E18: 105 | F18: 106 | G18: 403280 | H18: 2980.8 | I18: 3190.7 | J18: 663 | K18: 土圧105
A19: 部材106 | B19: 4 | C19: 1 | D19: 106 | E19: 106 | F19: 107 | G19: 403280 | H19: 3190.7 | I19: 3400.6 | J19: 664 | K19: 土圧106
A20: 部材107 | B20: 4 | C20: 1 | D20: 107 | E20: 107 | F20: 108 | G20: 403280 | H20: 3400.6 | I20: 3610.5 | J20: 665 | K20: 土圧107
A21: 部材108 | B21: 4 | C21: 1 | D21: 108 | E21: 108 | F21: 109 | G21: 403280 | H21: 3610.5 | I21: 3820.5 | J21: 666 | K21: 土圧108
A22: 部材の実入力
A23: 計算明細 | B23: KG | C23: 列 | D23: 部材 | E23: 上端節点 | F23: 下端節点 | G23: 水平ばね (kN/m²) | H23: 上端土圧 (kN/m) | I23: 下端土圧 (kN/m) | J23: NDU行 | K23: 土圧明細
A24: 部材109 | B24: 4 | C24: 1 | D24: 109 | E24: 109 | F24: 110 | G24: 403280 | H24: 3820.5 | I24: 4030.4 | J24: 667 | K24: 土圧109
A25: 部材110 | B25: 4 | C25: 1 | D25: 110 | E25: 110 | F25: 111 | G25: 403280 | H25: 4030.4 | I25: 4240.3 | J25: 668 | K25: 土圧110
A26: 部材111 | B26: 4 | C26: 1 | D26: 111 | E26: 111 | F26: 112 | G26: 403280 | H26: 4240.3 | I26: 4450.2 | J26: 669 | K26: 土圧111
A27: 部材112 | B27: 4 | C27: 1 | D27: 112 | E27: 112 | F27: 113 | G27: 225971 | H27: 3300.7 | I27: 3300.7 | J27: 670 | K27: 土圧112
A28: 部材113 | B28: 4 | C28: 1 | D28: 113 | E28: 113 | F28: 114 | G28: 193733 | H28: 3088.8 | I28: 3088.8 | J28: 671 | K28: 土圧113
A29: 部材114 | B29: 4 | C29: 1 | D29: 114 | E29: 114 | F29: 115 | G29: 193733 | H29: 3088.8 | I29: 3088.8 | J29: 672 | K29: 土圧114
A30: 部材115 | B30: 4 | C30: 1 | D30: 115 | E30: 115 | F30: 116 | G30: 193733 | H30: 3088.8 | I30: 3088.8 | J30: 673 | K30: 土圧115
A31: 部材116 | B31: 4 | C31: 1 | D31: 116 | E31: 116 | F31: 117 | G31: 193733 | H31: 3088.8 | I31: 3088.8 | J31: 674 | K31: 土圧116
A32: 部材117 | B32: 4 | C32: 1 | D32: 117 | E32: 117 | F32: 118 | G32: 193733 | H32: 3088.8 | I32: 3088.8 | J32: 675 | K32: 土圧117
A33: 部材118 | B33: 4 | C33: 1 | D33: 118 | E33: 118 | F33: 119 | G33: 193733 | H33: 3088.8 | I33: 3088.8 | J33: 676 | K33: 土圧118
A34: 部材119 | B34: 4 | C34: 1 | D34: 119 | E34: 119 | F34: 120 | G34: 193733 | H34: 3088.8 | I34: 3088.8 | J34: 677 | K34: 土圧119
A35: 部材120 | B35: 4 | C35: 1 | D35: 120 | E35: 120 | F35: 121 | G35: 193733 | H35: 3088.8 | I35: 3088.8 | J35: 678 | K35: 土圧120
... A38: 部材124 | B38: 5 | C38: 2 | D38: 124 | E38: 124 | F38: 125 | G38: 181391 | H38: 1719.1 | I38: 1719.1 | J38: 682 | K38: 土圧124
A39: 部材の実入力
A40: 計算明細 | B40: KG | C40: 列 | D40: 部材 | E40: 上端節点 | F40: 下端節点 | G40: 水平ばね (kN/m²) | H40: 上端土圧 (kN/m) | I40: 下端土圧 (kN/m) | J40: NDU行 | K40: 土圧明細
A41: 部材125 | B41: 5 | C41: 2 | D41: 125 | E41: 125 | F41: 126 | G41: 94334 | H41: 1285.3 | I41: 1285.3 | J41: 683 | K41: 土圧125
A42: 部材126 | B42: 5 | C42: 2 | D42: 126 | E42: 126 | F42: 127 | G42: 73805 | H42: 1170 | I42: 1170 | J42: 684 | K42: 土圧126
A43: 部材127 | B43: 5 | C43: 2 | D43: 127 | E43: 127 | F43: 128 | G43: 138686 | H43: 1732.3 | I43: 1732.3 | J43: 685 | K43: 土圧127
A44: 部材128 | B44: 5 | C44: 2 | D44: 128 | E44: 128 | F44: 129 | G44: 179236 | H44: 2137.2 | I44: 2310.9 | J44: 686 | K44: 土圧128
...

Sheet 水平地盤ばね
A1: 水平地盤ばね | H1: 水平地盤ばね | O1: 水平地盤ばね
A2: 層番号 | B2: 層厚 (m) | C2: 水平地盤反力係数 Kh (kN/m²) | D2: 部材長 (m) | F2: 部材番号 | G2: 各部材の水平ばね定数 Kh (kN/m²) | H2: 層番号 | I2: 層厚 (m) | J2: 水平地盤反力係数 Kh (kN/m²) | K2: 部材長 (m) | M2: 部材番号 | N2: 各部材の水平ばね定数 Kh (kN/m²) | O2: 層番号 | P2: 層厚 (m) | Q2: 水平地盤反力係数 Kh (kN/m²) | R2: 部材長 (m) | T2: 部材番号 | U2: 各部材の水平ばね定数 Kh (kN/m²)
A3: 1 | B3: ='入力根拠'!G424 -> 1.5 | C3: ='入力根拠'!F36 -> 58812 | D3: ='入力根拠'!H450 -> 1.3 | F3: 98 | G3: =C3 -> 58812 | H3: 1 | I3: ='入力根拠'!G431 -> 1.5 | J3: ='入力根拠'!F45 -> 39208 | K3: ='入力根拠'!H478 -> 1.3 | M3: 123 | N3: =J3 -> 39208 | O3: 1 | P3: ='入力根拠'!G438 -> 1.5 | Q3: ='入力根拠'!F52 -> 58812 | R3: ='入力根拠'!H504 -> 1.3 | T3: 148 | U3: =Q3 -> 58812
C4: ='入力根拠'!F36 -> 58812 | D4: ='入力根拠'!H451 -> 1.3 | E4: =MAX(0,ROUND((MIN('入力根拠'!G451,'入力根拠'!F424)-MAX('入力根拠'!F451,'入力根拠'!E424)),4)) -> 0.2 | F4: 99 | G4: =(SUM((C4*E4),(C5*E5))/D4) -> 272085.92 | J4: ='入力根拠'!F45 -> 39208 | K4: ='入力根拠'!H479 -> 1.3 | L4: =MAX(0,ROUND((MIN('入力根拠'!G479,'入力根拠'!F431)-MAX('入力根拠'!F479,'入力根拠'!E431)),4)) -> 0.2 | M4: 124 | N4: =(SUM((J4*L4),(J5*L5))/K4) -> 181390.62 | Q4: ='入力根拠'!F52 -> 58812 | R4: ='入力根拠'!H505 -> 1.3 | S4: =MAX(0,ROUND((MIN('入力根拠'!G505,'入力根拠'!F438)-MAX('入力根拠'!F505,'入力根拠'!E438)),4)) -> 0.2 | T4: 149 | U4: =(SUM((Q4*S4),(Q5*S5))/R4) -> 272085.92
A5: 2 | B5: ='入力根拠'!G425 -> 1.3 | C5: ='入力根拠'!F39 -> 310863 | E5: =MAX(0,ROUND((MIN('入力根拠'!G451,'入力根拠'!F425)-MAX('入力根拠'!F451,'入力根拠'!E425)),4)) -> 1.1 | H5: 2 | I5: ='入力根拠'!G432 -> 1.3 | J5: ='入力根拠'!F46 -> 207242 | L5: =MAX(0,ROUND((MIN('入力根拠'!G479,'入力根拠'!F432)-MAX('入力根拠'!F479,'入力根拠'!E432)),4)) -> 1.1 | O5: 2 | P5: ='入力根拠'!G441 -> 1.3 | Q5: ='入力根拠'!F53 -> 310863 | S5: =MAX(0,ROUND((MIN('入力根拠'!G505,'入力根拠'!F441)-MAX('入力根拠'!F505,'入力根拠'!E441)),4)) -> 1.1
C6: ='入力根拠'!F39 -> 310863 | D6: ='入力根拠'!H452 -> 1.3 | E6: =MAX(0,ROUND((MIN('入力根拠'!G452,'入力根拠'!F425)-MAX('入力根拠'!F452,'入力根拠'!E425)),4)) -> 0.2 | F6: 100 | G6: =(SUM((C6*E6),(C7*E7))/D6) -> 141501.08 | J6: ='入力根拠'!F46 -> 207242 | K6: ='入力根拠'!H480 -> 1.3 | L6: =MAX(0,ROUND((MIN('入力根拠'!G480,'入力根拠'!F432)-MAX('入力根拠'!F480,'入力根拠'!E432)),4)) -> 0.2 | M6: 125 | N6: =(SUM((J6*L6),(J7*L7))/K6) -> 94333.769 | Q6: ='入力根拠'!F53 -> 310863 | R6: ='入力根拠'!H508 -> 1.3 | S6: =MAX(0,ROUND((MIN('入力根拠'!G508,'入力根拠'!F441)-MAX('入力根拠'!F508,'入力根拠'!E441)),4)) -> 0.2 | T6: 150 | U6: =(SUM((Q6*S6),(Q7*S7))/R6) -> 141501.08
A7: 3 | B7: ='入力根拠'!G426 -> 2.9 | C7: ='入力根拠'!F40 -> 110708 | E7: =MAX(0,ROUND((MIN('入力根拠'!G452,'入力根拠'!F426)-MAX('入力根拠'!F452,'入力根拠'!E426)),4)) -> 1.1 | H7: 3 | I7: ='入力根拠'!G433 -> 2.9 | J7: ='入力根拠'!F47 -> 73805 | L7: =MAX(0,ROUND((MIN('入力根拠'!G480,'入力根拠'!F433)-MAX('入力根拠'!F480,'入力根拠'!E433)),4)) -> 1.1 | O7: 3 | P7: ='入力根拠'!G442 -> 2.9 | Q7: ='入力根拠'!F56 -> 110708 | S7: =MAX(0,ROUND((MIN('入力根拠'!G508,'入力根拠'!F442)-MAX('入力根拠'!F508,'入力根拠'!E442)),4)) -> 1.1
C8: ='入力根拠'!F40 -> 110708 | D8: ='入力根拠'!H453 -> 1.3 | F8: 101 | G8: =C8 -> 110708 | J8: ='入力根拠'!F47 -> 73805 | K8: ='入力根拠'!H481 -> 1.3 | M8: 126 | N8: =J8 -> 73805 | Q8: ='入力根拠'!F56 -> 110708 | R8: ='入力根拠'!H509 -> 1.3 | T8: 151 | U8: =Q8 -> 110708
C9: ='入力根拠'!F40 -> 110708 | D9: ='入力根拠'!H454 -> 1.3 | E9: =MAX(0,ROUND((MIN('入力根拠'!G454,'入力根拠'!F426)-MAX('入力根拠'!F454,'入力根拠'!E426)),4)) -> 0.5 | F9: 102 | G9: =(SUM((C9*E9),(C10*E10))/D9) -> 208028.62 | J9: ='入力根拠'!F47 -> 73805 | K9: ='入力根拠'!H482 -> 1.3 | L9: =MAX(0,ROUND((MIN('入力根拠'!G482,'入力根拠'!F433)-MAX('入力根拠'!F482,'入力根拠'!E433)),4)) -> 0.5 | M9: 127 | N9: =(SUM((J9*L9),(J10*L10))/K9) -> 138685.62 | Q9: ='入力根拠'!F56 -> 110708 | R9: ='入力根拠'!H510 -> 1.3 | S9: =MAX(0,ROUND((MIN('入力根拠'!G510,'入力根拠'!F442)-MAX('入力根拠'!F510,'入力根拠'!E442)),4)) -> 0.5 | T9: 152 | U9: =(SUM((Q9*S9),(Q10*S10))/R9) -> 208028.62
A10: 4 | B10: ='入力根拠'!G427 -> 2.6 | C10: ='入力根拠'!F41 -> 268854 | E10: =MAX(0,ROUND((MIN('入力根拠'!G454,'入力根拠'!F427)-MAX('入力根拠'!F454,'入力根拠'!E427)),4)) -> 0.8 | H10: 4 | I10: ='入力根拠'!G434 -> 2.6 | J10: ='入力根拠'!F48 -> 179236 | L10: =MAX(0,ROUND((MIN('入力根拠'!G482,'入力根拠'!F434)-MAX('入力根拠'!F482,'入力根拠'!E434)),4)) -> 0.8 | O10: 4 | P10: ='入力根拠'!G443 -> 2.6 | Q10: ='入力根拠'!F57 -> 268854 | S10: =MAX(0,ROUND((MIN('入力根拠'!G510,'入力根拠'!F443)-MAX('入力根拠'!F510,'入力根拠'!E443)),4)) -> 0.8
C11: ='入力根拠'!F41 -> 268854 | D11: ='入力根拠'!H457 -> 1.3 | F11: 103 | G11: =C11 -> 268854 | J11: ='入力根拠'!F48 -> 179236 | K11: ='入力根拠'!H483 -> 1.3 | M11: 128 | N11: =J11 -> 179236 | Q11: ='入力根拠'!F57 -> 268854 | R11: ='入力根拠'!H511 -> 1.3 | T11: 153 | U11: =Q11 -> 268854
C12: ='入力根拠'!F41 -> 268854 | D12: ='入力根拠'!H458 -> 1.3 | E12: =MAX(0,ROUND((MIN('入力根拠'!G458,'入力根拠'!F427)-MAX('入力根拠'!F458,'入力根拠'!E427)),4)) -> 0.5 | F12: 104 | G12: =(SUM((C12*E12),(C13*E13),(C14*E14))/D12) -> 363439.69 | J12: ='入力根拠'!F48 -> 179236 | K12: ='入力根拠'!H484 -> 1.3 | L12: =MAX(0,ROUND((MIN('入力根拠'!G484,'入力根拠'!F434)-MAX('入力根拠'!F484,'入力根拠'!E434)),4)) -> 0.5 | M12: 129 | N12: =(SUM((J12*L12),(J13*L13),(J14*L14))/K12) -> 242293.08 | Q12: ='入力根拠'!F57 -> 268854 | R12: ='入力根拠'!H512 -> 1.3 | S12: =MAX(0,ROUND((MIN('入力根拠'!G512,'入力根拠'!F443)-MAX('入力根拠'!F512,'入力根拠'!E443)),4)) -> 0.5 | T12: 154 | U12: =(SUM((Q12*S12),(Q13*S13),(Q14*S14))/R12) -> 363439.69
A13: 5 | B13: ='入力根拠'!G428 -> 0.6 | C13: ='入力根拠'!F42 -> 428981 | E13: =MAX(0,ROUND((MIN('入力根拠'!G458,'入力根拠'!F428)-MAX('入力根拠'!F458,'入力根拠'!E428)),4)) -> 0.6 | H13: 5 | I13: ='入力根拠'!G435 -> 0.6 | J13: ='入力根拠'!F49 -> 285987 | L13: =MAX(0,ROUND((MIN('入力根拠'!G484,'入力根拠'!F435)-MAX('入力根拠'!F484,'入力根拠'!E435)),4)) -> 0.6 | O13: 5 | P13: ='入力根拠'!G444 -> 0.6 | Q13: ='入力根拠'!F58 -> 428981 | S13: =MAX(0,ROUND((MIN('入力根拠'!G512,'入力根拠'!F444)-MAX('入力根拠'!F512,'入力根拠'!E444)),4)) -> 0.6
A14: 6 | B14: ='入力根拠'!G429 -> 9.5 | C14: ='入力根拠'!F43 -> 403280 | E14: =MAX(0,ROUND((MIN('入力根拠'!G458,'入力根拠'!F429)-MAX('入力根拠'!F458,'入力根拠'!E429)),4)) -> 0.2 | H14: 6 | I14: ='入力根拠'!G436 -> 9.5 | J14: ='入力根拠'!F50 -> 268854 | L14: =MAX(0,ROUND((MIN('入力根拠'!G484,'入力根拠'!F436)-MAX('入力根拠'!F484,'入力根拠'!E436)),4)) -> 0.2 | O14: 6 | P14: ='入力根拠'!G445 -> 9.5 | Q14: ='入力根拠'!F59 -> 403280 | S14: =MAX(0,ROUND((MIN('入力根拠'!G512,'入力根拠'!F445)-MAX('入力根拠'!F512,'入力根拠'!E445)),4)) -> 0.2
C15: ='入力根拠'!F43 -> 403280 | D15: ='入力根拠'!H459 -> 1.3 | F15: 105 | G15: =C15 -> 403280 | J15: ='入力根拠'!F50 -> 268854 | K15: ='入力根拠'!H485 -> 1.3 | M15: 130 | N15: =J15 -> 268854 | Q15: ='入力根拠'!F59 -> 403280 | R15: ='入力根拠'!H513 -> 1.3 | T15: 155 | U15: =Q15 -> 403280
C16: ='入力根拠'!F43 -> 403280 | D16: ='入力根拠'!H460 -> 1.3 | F16: 106 | G16: =C16 -> 403280 | J16: ='入力根拠'!F50 -> 268854 | K16: ='入力根拠'!H486 -> 1.3 | M16: 131 | N16: =J16 -> 268854 | Q16: ='入力根拠'!F59 -> 403280 | R16: ='入力根拠'!H514 -> 1.3 | T16: 156 | U16: =Q16 -> 403280
C17: ='入力根拠'!F43 -> 403280 | D17: ='入力根拠'!H461 -> 1.3 | F17: 107 | G17: =C17 -> 403280 | J17: ='入力根拠'!F50 -> 268854 | K17: ='入力根拠'!H487 -> 1.3 | M17: 132 | N17: =J17 -> 268854 | Q17: ='入力根拠'!F59 -> 403280 | R17: ='入力根拠'!H515 -> 1.3 | T17: 157 | U17: =Q17 -> 403280
C18: ='入力根拠'!F43 -> 403280 | D18: ='入力根拠'!H462 -> 1.3 | F18: 108 | G18: =C18 -> 403280 | J18: ='入力根拠'!F50 -> 268854 | K18: ='入力根拠'!H488 -> 1.3 | M18: 133 | N18: =J18 -> 268854 | Q18: ='入力根拠'!F59 -> 403280 | R18: ='入力根拠'!H516 -> 1.3 | T18: 158 | U18: =Q18 -> 403280
C19: ='入力根拠'!F43 -> 403280 | D19: ='入力根拠'!H463 -> 1.3 | F19: 109 | G19: =C19 -> 403280 | J19: ='入力根拠'!F50 -> 268854 | K19: ='入力根拠'!H491 -> 1.3 | M19: 134 | N19: =J19 -> 268854 | Q19: ='入力根拠'!F59 -> 403280 | R19: ='入力根拠'!H517 -> 1.3 | T19: 159 | U19: =Q19 -> 403280
C20: ='入力根拠'!F43 -> 403280 | D20: ='入力根拠'!H464 -> 1.3 | F20: 110 | G20: =C20 -> 403280 | J20: ='入力根拠'!F50 -> 268854 | K20: ='入力根拠'!H492 -> 1.3 | M20: 135 | N20: =J20 -> 268854 | Q20: ='入力根拠'!F59 -> 403280 | R20: ='入力根拠'!H518 -> 1.3 | T20: 160 | U20: =Q20 -> 403280
C21: ='入力根拠'!F43 -> 403280 | D21: ='入力根拠'!H465 -> 1.3 | F21: 111 | G21: =C21 -> 403280 | J21: ='入力根拠'!F50 -> 268854 | K21: ='入力根拠'!H493 -> 1.3 | M21: 136 | N21: =J21 -> 268854 | Q21: ='入力根拠'!F59 -> 403280 | R21: ='入力根拠'!H519 -> 1.3 | T21: 161 | U21: =Q21 -> 403280
C22: ='入力根拠'!F43 -> 403280 | D22: ='入力根拠'!H466 -> 1.3 | E22: =MAX(0,ROUND((MIN('入力根拠'!G466,'入力根拠'!F429)-MAX('入力根拠'!F466,'入力根拠'!E429)),4)) -> 0.2 | F22: 112 | G22: =(SUM((C22*E22),(C23*E23))/D22) -> 225971 | J22: ='入力根拠'!F50 -> 268854 | K22: ='入力根拠'!H494 -> 1.3 | L22: =MAX(0,ROUND((MIN('入力根拠'!G494,'入力根拠'!F436)-MAX('入力根拠'!F494,'入力根拠'!E436)),4)) -> 0.2 | M22: 137 | N22: =(SUM((J22*L22),(J23*L23))/K22) -> 150647.15 | Q22: ='入力根拠'!F59 -> 403280 | R22: ='入力根拠'!H520 -> 1.3 | S22: =MAX(0,ROUND((MIN('入力根拠'!G520,'入力根拠'!F445)-MAX('入力根拠'!F520,'入力根拠'!E445)),4)) -> 0.2 | T22: 162 | U22: =(SUM((Q22*S22),(Q23*S23))/R22) -> 225971
A23: 7 | B23: ='入力根拠'!G430 -> 12.6 | C23: ='入力根拠'!F44 -> 193733 | E23: =MAX(0,ROUND((MIN('入力根拠'!G466,'入力根拠'!F430)-MAX('入力根拠'!F466,'入力根拠'!E430)),4)) -> 1.1 | H23: 7 | I23: ='入力根拠'!G437 -> 12.6 | J23: ='入力根拠'!F51 -> 129155 | L23: =MAX(0,ROUND((MIN('入力根拠'!G494,'入力根拠'!F437)-MAX('入力根拠'!F494,'入力根拠'!E437)),4)) -> 1.1 | O23: 7 | P23: ='入力根拠'!G446 -> 12.6 | Q23: ='入力根拠'!F60 -> 193733 | S23: =MAX(0,ROUND((MIN('入力根拠'!G520,'入力根拠'!F446)-MAX('入力根拠'!F520,'入力根拠'!E446)),4)) -> 1.1
C24: ='入力根拠'!F44 -> 193733 | D24: ='入力根拠'!H467 -> 1.3 | F24: 113 | G24: =C24 -> 193733 | J24: ='入力根拠'!F51 -> 129155 | K24: ='入力根拠'!H495 -> 1.3 | M24: 138 | N24: =J24 -> 129155 | Q24: ='入力根拠'!F60 -> 193733 | R24: ='入力根拠'!H521 -> 1.3 | T24: 163 | U24: =Q24 -> 193733
C25: ='入力根拠'!F44 -> 193733 | D25: ='入力根拠'!H468 -> 1.3 | F25: 114 | G25: =C25 -> 193733 | J25: ='入力根拠'!F51 -> 129155 | K25: ='入力根拠'!H496 -> 1.3 | M25: 139 | N25: =J25 -> 129155 | Q25: ='入力根拠'!F60 -> 193733 | R25: ='入力根拠'!H522 -> 1.3 | T25: 164 | U25: =Q25 -> 193733
C26: ='入力根拠'!F44 -> 193733 | D26: ='入力根拠'!H469 -> 1.3 | F26: 115 | G26: =C26 -> 193733 | J26: ='入力根拠'!F51 -> 129155 | K26: ='入力根拠'!H497 -> 1.3 | M26: 140 | N26: =J26 -> 129155 | Q26: ='入力根拠'!F60 -> 193733 | R26: ='入力根拠'!H525 -> 1.3 | T26: 165 | U26: =Q26 -> 193733
C27: ='入力根拠'!F44 -> 193733 | D27: ='入力根拠'!H470 -> 1.3 | F27: 116 | G27: =C27 -> 193733 | J27: ='入力根拠'!F51 -> 129155 | K27: ='入力根拠'!H498 -> 1.3 | M27: 141 | N27: =J27 -> 129155 | Q27: ='入力根拠'!F60 -> 193733 | R27: ='入力根拠'!H526 -> 1.3 | T27: 166 | U27: =Q27 -> 193733
C28: ='入力根拠'!F44 -> 193733 | D28: ='入力根拠'!H471 -> 1.3 | F28: 117 | G28: =C28 -> 193733 | J28: ='入力根拠'!F51 -> 129155 | K28: ='入力根拠'!H499 -> 1.3 | M28: 142 | N28: =J28 -> 129155 | Q28: ='入力根拠'!F60 -> 193733 | R28: ='入力根拠'!H527 -> 1.3 | T28: 167 | U28: =Q28 -> 193733
C29: ='入力根拠'!F44 -> 193733 | D29: ='入力根拠'!H474 -> 1.3 | F29: 118 | G29: =C29 -> 193733 | J29: ='入力根拠'!F51 -> 129155 | K29: ='入力根拠'!H500 -> 1.3 | M29: 143 | N29: =J29 -> 129155 | Q29: ='入力根拠'!F60 -> 193733 | R29: ='入力根拠'!H528 -> 1.3 | T29: 168 | U29: =Q29 -> 193733
C30: ='入力根拠'!F44 -> 193733 | D30: ='入力根拠'!H475 -> 1.3 | F30: 119 | G30: =C30 -> 193733 | J30: ='入力根拠'!F51 -> 129155 | K30: ='入力根拠'!H501 -> 1.3 | M30: 144 | N30: =J30 -> 129155 | Q30: ='入力根拠'!F60 -> 193733 | R30: ='入力根拠'!H529 -> 1.3 | T30: 169 | U30: =Q30 -> 193733
C31: ='入力根拠'!F44 -> 193733 | D31: ='入力根拠'!H476 -> 1.3 | F31: 120 | G31: =C31 -> 193733 | J31: ='入力根拠'!F51 -> 129155 | K31: ='入力根拠'!H502 -> 1.3 | M31: 145 | N31: =J31 -> 129155 | Q31: ='入力根拠'!F60 -> 193733 | R31: ='入力根拠'!H530 -> 1.3 | T31: 170 | U31: =Q31 -> 193733
C32: ='入力根拠'!F44 -> 193733 | D32: ='入力根拠'!H477 -> 1.1 | F32: 121 | G32: =C32 -> 193733 | J32: ='入力根拠'!F51 -> 129155 | K32: ='入力根拠'!H503 -> 1.1 | M32: 146 | N32: =J32 -> 129155 | Q32: ='入力根拠'!F60 -> 193733 | R32: ='入力根拠'!H531 -> 1.1 | T32: 171 | U32: =Q32 -> 193733
A33: Σ | B33: =SUM(B3,B5,B7,B10,B13,B14,B23) -> 31 | D33: =SUM(D3,D4,D6,D8,D9,D11,D12,D15,D16,D17,D18,D19,D20,D21,D22,D24,D25,D26,D27,D28,D29,D30,D31,D32) -> 31 | H33: Σ | I33: =SUM(I3,I5,I7,I10,I13,I14,I23) -> 31 | K33: =SUM(K3,K4,K6,K8,K9,K11,K12,K15,K16,K17,K18,K19,K20,K21,K22,K24,K25,K26,K27,K28,K29,K30,K31,K32) -> 31 | O33: Σ | P33: =SUM(P3,P5,P7,P10,P13,P14,P23) -> 31 | R33: =SUM(R3,R4,R6,R8,R9,R11,R12,R15,R16,R17,R18,R19,R20,R21,R22,R24,R25,R26,R27,R28,R29,R30,R31,R32) -> 31

Sheet 有効抵抗土圧
A1: 有効抵抗土圧 | J1: 有効抵抗土圧 | S1: 有効抵抗土圧
A2: 層番号 | B2: 層厚 (m) | C2: 有効抵抗 土圧力 pe(z) (kN/m) | D2: 部材長 (m) | F2: 深さ z (m) | G2: 有効抵抗 土圧力 pe(z) (kN/m) | H2: 部材 番号 | I2: 有効抵抗 土圧力 pe(z) (kN/m) | J2: 層番号 | K2: 層厚 (m) | L2: 有効抵抗 土圧力 pe(z) (kN/m) | M2: 部材長 (m) | O2: 深さ z (m) | P2: 有効抵抗 土圧力 pe(z) (kN/m) | Q2: 部材 番号 | R2: 有効抵抗 土圧力 pe(z) (kN/m) | S2: 層番号 | T2: 層厚 (m) | U2: 有効抵抗 土圧力 pe(z) (kN/m) | V2: 部材長 (m) | X2: 深さ z (m) | Y2: 有効抵抗 土圧力 pe(z) (kN/m) | Z2: 部材 番号 | AA2: 有効抵抗 土圧力 pe(z) (kN/m)
A3: 1 | B3: ='入力根拠'!H705 -> 1.5 | C3: ='入力根拠'!I705 -> 1162.9 | D3: ='入力根拠'!H732 -> 1.3 | F3: ='入力根拠'!E817 -> 0 | G3: =(C3+(((C6-C3)*(F3-'入力根拠'!F705))/B3)) -> 1162.9 | H3: 98 | I3: =G3 -> 1162.9 | J3: 1 | K3: ='入力根拠'!H712 -> 1.5 | L3: ='入力根拠'!I712 -> 1005.1 | M3: ='入力根拠'!H760 -> 1.3 | O3: ='入力根拠'!E851 -> 0 | P3: =(L3+(((L6-L3)*(O3-'入力根拠'!F712))/K3)) -> 1005.1 | Q3: 123 | R3: =P3 -> 1005.1 | S3: 1 | T3: ='入力根拠'!H719 -> 1.5 | U3: ='入力根拠'!I719 -> 2907.3 | V3: ='入力根拠'!H786 -> 1.3 | X3: ='入力根拠'!E885 -> 0 | Y3: =(U3+(((U6-U3)*(X3-'入力根拠'!F719))/T3)) -> 2907.3 | Z3: 148 | AA3: =Y3 -> 2907.3
F4: ='入力根拠'!F817 -> 1.3 | G4: =(C3+(((C6-C3)*(F4-'入力根拠'!F705))/B3)) -> 1307.46 | I4: =G4 -> 1307.46 | O4: ='入力根拠'!F851 -> 1.3 | P4: =(L3+(((L6-L3)*(O4-'入力根拠'!F712))/K3)) -> 1130.0733 | R4: =P4 -> 1130.0733 | X4: ='入力根拠'!F885 -> 1.3 | Y4: =(U3+(((U6-U3)*(X4-'入力根拠'!F719))/T3)) -> 3268.7 | AA4: =Y4 -> 3268.7
D5: ='入力根拠'!H733 -> 1.3 | E5: ='入力根拠'!G818 -> 0.2 | F5: ='入力根拠'!E818 -> 1.3 | G5: =(C3+(((C6-C3)*(F5-'入力根拠'!F705))/B3)) -> 1307.46 | H5: 99 | I5: =(SUM('入力根拠'!L818,'入力根拠'!L819)/D5) -> 1988.9883 | M5: ='入力根拠'!H761 -> 1.3 | N5: ='入力根拠'!G852 -> 0.2 | O5: ='入力根拠'!E852 -> 1.3 | P5: =(L3+(((L6-L3)*(O5-'入力根拠'!F712))/K3)) -> 1130.0733 | Q5: 124 | R5: =(SUM('入力根拠'!L852,'入力根拠'!L853)/M5) -> 1719.0725 | V5: ='入力根拠'!H789 -> 1.3 | W5: ='入力根拠'!G886 -> 0.2 | X5: ='入力根拠'!E886 -> 1.3 | Y5: =(U3+(((U6-U3)*(X5-'入力根拠'!F719))/T3)) -> 3268.7 | Z5: 149 | AA5: =(SUM('入力根拠'!L886,'入力根拠'!L887)/V5) -> 4972.4899
C6: ='入力根拠'!J705 -> 1329.7 | F6: ='入力根拠'!F818 -> 1.5 | G6: =(C3+(((C6-C3)*(F6-'入力根拠'!F705))/B3)) -> 1329.7 | L6: ='入力根拠'!J712 -> 1149.3 | O6: ='入力根拠'!F852 -> 1.5 | P6: =(L3+(((L6-L3)*(O6-'入力根拠'!F712))/K3)) -> 1149.3 | U6: ='入力根拠'!J719 -> 3324.3 | X6: ='入力根拠'!F886 -> 1.5 | Y6: =(U3+(((U6-U3)*(X6-'入力根拠'!F719))/T3)) -> 3324.3
A7: 2 | B7: ='入力根拠'!H706 -> 1.3 | C7: ='入力根拠'!I706 -> 2018.1 | E7: ='入力根拠'!G819 -> 1.1 | F7: ='入力根拠'!E819 -> 1.5 | G7: =(C7+(((C10-C7)*(F7-'入力根拠'!F706))/B7)) -> 2018.1 | J7: 2 | K7: ='入力根拠'!H713 -> 1.3 | L7: ='入力根拠'!I713 -> 1744.2 | N7: ='入力根拠'!G853 -> 1.1 | O7: ='入力根拠'!E853 -> 1.5 | P7: =(L7+(((L10-L7)*(O7-'入力根拠'!F713))/K7)) -> 1744.2 | S7: 2 | T7: ='入力根拠'!H722 -> 1.3 | U7: ='入力根拠'!I722 -> 5045.2 | W7: ='入力根拠'!G887 -> 1.1 | X7: ='入力根拠'!E887 -> 1.5 | Y7: =(U7+(((U10-U7)*(X7-'入力根拠'!F722))/T7)) -> 5045.2
F8: ='入力根拠'!F819 -> 2.6 | G8: =(C7+(((C10-C7)*(F8-'入力根拠'!F706))/B7)) -> 2203.6615 | I8: =I5 -> 1988.9883 | O8: ='入力根拠'!F853 -> 2.6 | P8: =(L7+(((L10-L7)*(O8-'入力根拠'!F713))/K7)) -> 1904.6308 | R8: =R5 -> 1719.0725 | X8: ='入力根拠'!F887 -> 2.6 | Y8: =(U7+(((U10-U7)*(X8-'入力根拠'!F722))/T7)) -> 5509.2308 | AA8: =AA5 -> 4972.4899
D9: ='入力根拠'!H734 -> 1.3 | E9: ='入力根拠'!G822 -> 0.2 | F9: ='入力根拠'!E822 -> 2.6 | G9: =(C7+(((C10-C7)*(F9-'入力根拠'!F706))/B7)) -> 2203.6615 | H9: 100 | I9: =(SUM('入力根拠'!L822,'入力根拠'!L823)/D9) -> 1826.6201 | M9: ='入力根拠'!H762 -> 1.3 | N9: ='入力根拠'!G856 -> 0.2 | O9: ='入力根拠'!E856 -> 2.6 | P9: =(L7+(((L10-L7)*(O9-'入力根拠'!F713))/K7)) -> 1904.6308 | Q9: 125 | R9: =(SUM('入力根拠'!L856,'入力根拠'!L857)/M9) -> 1285.2639 | V9: ='入力根拠'!H790 -> 1.3 | W9: ='入力根拠'!G890 -> 0.2 | X9: ='入力根拠'!E890 -> 2.6 | Y9: =(U7+(((U10-U7)*(X9-'入力根拠'!F722))/T7)) -> 5509.2308 | Z9: 150 | AA9: =(SUM('入力根拠'!L890,'入力根拠'!L891)/V9) -> 2339.0639
C10: ='入力根拠'!J706 -> 2237.4 | F10: ='入力根拠'!F822 -> 2.8 | G10: =(C7+(((C10-C7)*(F10-'入力根拠'!F706))/B7)) -> 2237.4 | L10: ='入力根拠'!J713 -> 1933.8 | O10: ='入力根拠'!F856 -> 2.8 | P10: =(L7+(((L10-L7)*(O10-'入力根拠'!F713))/K7)) -> 1933.8 | U10: ='入力根拠'!J722 -> 5593.6 | X10: ='入力根拠'!F890 -> 2.8 | Y10: =(U7+(((U10-U7)*(X10-'入力根拠'!F722))/T7)) -> 5593.6
A11: 3 | B11: ='入力根拠'!H707 -> 2.9 | C11: ='入力根拠'!I707 -> 1755 | E11: ='入力根拠'!G823 -> 1.1 | F11: ='入力根拠'!E823 -> 2.8 | G11: =(C11+(((C16-C11)*(F11-'入力根拠'!F707))/B11)) -> 1755 | J11: 3 | K11: ='入力根拠'!H714 -> 2.9 | L11: ='入力根拠'!I714 -> 1170 | N11: ='入力根拠'!G857 -> 1.1 | O11: ='入力根拠'!E857 -> 2.8 | P11: =(L11+(((L16-L11)*(O11-'入力根拠'!F714))/K11)) -> 1170 | S11: 3 | T11: ='入力根拠'!H723 -> 2.9 | U11: ='入力根拠'!I723 -> 1755 | W11: ='入力根拠'!G891 -> 1.1 | X11: ='入力根拠'!E891 -> 2.8 | Y11: =(U11+(((U16-U11)*(X11-'入力根拠'!F723))/T11)) -> 1755
F12: ='入力根拠'!F823 -> 3.9 | G12: =(C11+(((C16-C11)*(F12-'入力根拠'!F707))/B11)) -> 1755 | I12: =I9 -> 1826.6201 | O12: ='入力根拠'!F857 -> 3.9 | P12: =(L11+(((L16-L11)*(O12-'入力根拠'!F714))/K11)) -> 1170 | R12: =R9 -> 1285.2639 | X12: ='入力根拠'!F891 -> 3.9 | Y12: =(U11+(((U16-U11)*(X12-'入力根拠'!F723))/T11)) -> 1755 | AA12: =AA9 -> 2339.0639
D13: ='入力根拠'!H735 -> 1.3 | F13: ='入力根拠'!E824 -> 3.9 | G13: =(C11+(((C16-C11)*(F13-'入力根拠'!F707))/B11)) -> 1755 | H13: 101 | I13: =G13 -> 1755 | M13: ='入力根拠'!H763 -> 1.3 | O13: ='入力根拠'!E858 -> 3.9 | P13: =(L11+(((L16-L11)*(O13-'入力根拠'!F714))/K11)) -> 1170 | Q13: 126 | R13: =P13 -> 1170 | V13: ='入力根拠'!H791 -> 1.3 | X13: ='入力根拠'!E892 -> 3.9 | Y13: =(U11+(((U16-U11)*(X13-'入力根拠'!F723))/T11)) -> 1755 | Z13: 151 | AA13: =Y13 -> 1755
F14: ='入力根拠'!F824 -> 5.2 | G14: =(C11+(((C16-C11)*(F14-'入力根拠'!F707))/B11)) -> 1755 | I14: =G14 -> 1755 | O14: ='入力根拠'!F858 -> 5.2 | P14: =(L11+(((L16-L11)*(O14-'入力根拠'!F714))/K11)) -> 1170 | R14: =P14 -> 1170 | X14: ='入力根拠'!F892 -> 5.2 | Y14: =(U11+(((U16-U11)*(X14-'入力根拠'!F723))/T11)) -> 1755 | AA14: =Y14 -> 1755
D15: ='入力根拠'!H738 -> 1.3 | E15: ='入力根拠'!G825 -> 0.5 | F15: ='入力根拠'!E825 -> 5.2 | G15: =(C11+(((C16-C11)*(F15-'入力根拠'!F707))/B11)) -> 1755 | H15: 102 | I15: =(SUM('入力根拠'!L825,'入力根拠'!L826)/D15) -> 2158.6497 | M15: ='入力根拠'!H764 -> 1.3 | N15: ='入力根拠'!G859 -> 0.5 | O15: ='入力根拠'!E859 -> 5.2 | P15: =(L11+(((L16-L11)*(O15-'入力根拠'!F714))/K11)) -> 1170 | Q15: 127 | R15: =(SUM('入力根拠'!L859,'入力根拠'!L860)/M15) -> 1732.3053 | V15: ='入力根拠'!H792 -> 1.3 | W15: ='入力根拠'!G893 -> 0.5 | X15: ='入力根拠'!E893 -> 5.2 | Y15: =(U11+(((U16-U11)*(X15-'入力根拠'!F723))/T11)) -> 1755 | Z15: 152 | AA15: =(SUM('入力根拠'!L893,'入力根拠'!L894)/V15) -> 4384.0556
C16: ='入力根拠'!J707 -> 1755 | F16: ='入力根拠'!F825 -> 5.7 | G16: =(C11+(((C16-C11)*(F16-'入力根拠'!F707))/B11)) -> 1755 | L16: ='入力根拠'!J714 -> 1170 | O16: ='入力根拠'!F859 -> 5.7 | P16: =(L11+(((L16-L11)*(O16-'入力根拠'!F714))/K11)) -> 1170 | U16: ='入力根拠'!J723 -> 1755 | X16: ='入力根拠'!F893 -> 5.7 | Y16: =(U11+(((U16-U11)*(X16-'入力根拠'!F723))/T11)) -> 1755
A17: 4 | B17: ='入力根拠'!H708 -> 2.6 | C17: ='入力根拠'!I708 -> 2349.1 | E17: ='入力根拠'!G826 -> 0.8 | F17: ='入力根拠'!E826 -> 5.7 | G17: =(C17+(((C22-C17)*(F17-'入力根拠'!F708))/B17)) -> 2349.1 | J17: 4 | K17: ='入力根拠'!H715 -> 2.6 | L17: ='入力根拠'!I715 -> 2030.3 | N17: ='入力根拠'!G860 -> 0.8 | O17: ='入力根拠'!E860 -> 5.7 | P17: =(L17+(((L22-L17)*(O17-'入力根拠'!F715))/K17)) -> 2030.3 | S17: 4 | T17: ='入力根拠'!H724 -> 2.6 | U17: ='入力根拠'!I724 -> 5872.6 | W17: ='入力根拠'!G894 -> 0.8 | X17: ='入力根拠'!E894 -> 5.7 | Y17: =(U17+(((U22-U17)*(X17-'入力根拠'!F724))/T17)) -> 5872.6
F18: ='入力根拠'!F826 -> 6.5 | G18: =(C17+(((C22-C17)*(F18-'入力根拠'!F708))/B17)) -> 2472.7615 | I18: =I15 -> 2158.6497 | O18: ='入力根拠'!F860 -> 6.5 | P18: =(L17+(((L22-L17)*(O18-'入力根拠'!F715))/K17)) -> 2137.1923 | R18: =R15 -> 1732.3053 | X18: ='入力根拠'!F894 -> 6.5 | Y18: =(U17+(((U22-U17)*(X18-'入力根拠'!F724))/T17)) -> 6181.8308 | AA18: =AA15 -> 4384.0556
D19: ='入力根拠'!H739 -> 1.3 | F19: ='入力根拠'!E827 -> 6.5 | G19: =(C17+(((C22-C17)*(F19-'入力根拠'!F708))/B17)) -> 2472.7615 | H19: 103 | I19: =G19 -> 2472.7615 | M19: ='入力根拠'!H765 -> 1.3 | O19: ='入力根拠'!E861 -> 6.5 | P19: =(L17+(((L22-L17)*(O19-'入力根拠'!F715))/K17)) -> 2137.1923 | Q19: 128 | R19: =P19 -> 2137.1923 | V19: ='入力根拠'!H793 -> 1.3 | X19: ='入力根拠'!E895 -> 6.5 | Y19: =(U17+(((U22-U17)*(X19-'入力根拠'!F724))/T17)) -> 6181.8308 | Z19: 153 | AA19: =Y19 -> 6181.8308
F20: ='入力根拠'!F827 -> 7.8 | G20: =(C17+(((C22-C17)*(F20-'入力根拠'!F708))/B17)) -> 2673.7115 | I20: =G20 -> 2673.7115 | O20: ='入力根拠'!F861 -> 7.8 | P20: =(L17+(((L22-L17)*(O20-'入力根拠'!F715))/K17)) -> 2310.8923 | R20: =P20 -> 2310.8923 | X20: ='入力根拠'!F895 -> 7.8 | Y20: =(U17+(((U22-U17)*(X20-'入力根拠'!F724))/T17)) -> 6684.3308 | AA20: =Y20 -> 6684.3308
D21: ='入力根拠'!H740 -> 1.3 | E21: ='入力根拠'!G828 -> 0.5 | F21: ='入力根拠'!E828 -> 7.8 | G21: =(C17+(((C22-C17)*(F21-'入力根拠'!F708))/B17)) -> 2673.7115 | H21: 104 | I21: =(SUM('入力根拠'!L828,'入力根拠'!L829,'入力根拠'!L830)/D21) -> 4642.1134 | M21: ='入力根拠'!H766 -> 1.3 | N21: ='入力根拠'!G862 -> 0.5 | O21: ='入力根拠'!E862 -> 7.8 | P21: =(L17+(((L22-L17)*(O21-'入力根拠'!F715))/K17)) -> 2310.8923 | Q21: 129 | R21: =(SUM('入力根拠'!L862,'入力根拠'!L863,'入力根拠'!L864)/M21) -> 3391.0609 | V21: ='入力根拠'!H794 -> 1.3 | W21: ='入力根拠'!G896 -> 0.5 | X21: ='入力根拠'!E896 -> 7.8 | Y21: =(U17+(((U22-U17)*(X21-'入力根拠'!F724))/T17)) -> 6684.3308 | Z21: 154 | AA21: =(SUM('入力根拠'!L896,'入力根拠'!L897,'入力根拠'!L898)/V21) -> 6891.1049
C22: ='入力根拠'!J708 -> 2751 | F22: ='入力根拠'!F828 -> 8.3 | G22: =(C17+(((C22-C17)*(F22-'入力根拠'!F708))/B17)) -> 2751 | L22: ='入力根拠'!J715 -> 2377.7 | O22: ='入力根拠'!F862 -> 8.3 | P22: =(L17+(((L22-L17)*(O22-'入力根拠'!F715))/K17)) -> 2377.7 | U22: ='入力根拠'!J724 -> 6877.6 | X22: ='入力根拠'!F896 -> 8.3 | Y22: =(U17+(((U22-U17)*(X22-'入力根拠'!F724))/T17)) -> 6877.6
A23: 5 | B23: ='入力根拠'!H709 -> 0.6 | C23: ='入力根拠'!I709 -> 6809.4 | E23: ='入力根拠'!G829 -> 0.6 | F23: ='入力根拠'!E829 -> 8.3 | G23: =(C23+(((C24-C23)*(F23-'入力根拠'!F709))/B23)) -> 6809.4 | J23: 5 | K23: ='入力根拠'!H716 -> 0.6 | L23: ='入力根拠'!I716 -> 4539.6 | N23: ='入力根拠'!G863 -> 0.6 | O23: ='入力根拠'!E863 -> 8.3 | P23: =(L23+(((L24-L23)*(O23-'入力根拠'!F716))/K23)) -> 4539.6 | S23: 5 | T23: ='入力根拠'!H725 -> 0.6 | U23: ='入力根拠'!I725 -> 6809.4 | W23: ='入力根拠'!G897 -> 0.6 | X23: ='入力根拠'!E897 -> 8.3 | Y23: =(U23+(((U24-U23)*(X23-'入力根拠'!F725))/T23)) -> 6809.4
C24: ='入力根拠'!J709 -> 6809.4 | F24: ='入力根拠'!F829 -> 8.9 | G24: =(C23+(((C24-C23)*(F24-'入力根拠'!F709))/B23)) -> 6809.4 | L24: ='入力根拠'!J716 -> 4539.6 | O24: ='入力根拠'!F863 -> 8.9 | P24: =(L23+(((L24-L23)*(O24-'入力根拠'!F716))/K23)) -> 4539.6 | U24: ='入力根拠'!J725 -> 6809.4 | X24: ='入力根拠'!F897 -> 8.9 | Y24: =(U23+(((U24-U23)*(X24-'入力根拠'!F725))/T23)) -> 6809.4
A25: 6 | B25: ='入力根拠'!H710 -> 9.5 | C25: ='入力根拠'!I710 -> 2948.5 | E25: ='入力根拠'!G830 -> 0.2 | F25: ='入力根拠'!E830 -> 8.9 | G25: =(C25+(((C42-C25)*(F25-'入力根拠'!F710))/B25)) -> 2948.5 | J25: 6 | K25: ='入力根拠'!H717 -> 9.5 | L25: ='入力根拠'!I717 -> 2548.4 | N25: ='入力根拠'!G864 -> 0.2 | O25: ='入力根拠'!E864 -> 8.9 | P25: =(L25+(((L42-L25)*(O25-'入力根拠'!F717))/K25)) -> 2548.4 | S25: 6 | T25: ='入力根拠'!H726 -> 9.5 | U25: ='入力根拠'!I726 -> 7371.2 | W25: ='入力根拠'!G898 -> 0.2 | X25: ='入力根拠'!E898 -> 8.9 | Y25: =(U25+(((U42-U25)*(X25-'入力根拠'!F726))/T25)) -> 7371.2
F26: ='入力根拠'!F830 -> 9.1 | G26: =(C25+(((C42-C25)*(F26-'入力根拠'!F710))/B25)) -> 2980.7947 | I26: =I21 -> 4642.1134 | O26: ='入力根拠'!F864 -> 9.1 | P26: =(L25+(((L42-L25)*(O26-'入力根拠'!F717))/K25)) -> 2576.3116 | R26: =R21 -> 3391.0609 | X26: ='入力根拠'!F898 -> 9.1 | Y26: =(U25+(((U42-U25)*(X26-'入力根拠'!F726))/T25)) -> 7451.9368 | AA26: =AA21 -> 6891.1049
D27: ='入力根拠'!H741 -> 1.3 | F27: ='入力根拠'!E831 -> 9.1 | G27: =(C25+(((C42-C25)*(F27-'入力根拠'!F710))/B25)) -> 2980.7947 | H27: 105 | I27: =G27 -> 2980.7947 | M27: ='入力根拠'!H767 -> 1.3 | O27: ='入力根拠'!E865 -> 9.1 | P27: =(L25+(((L42-L25)*(O27-'入力根拠'!F717))/K25)) -> 2576.3116 | Q27: 130 | R27: =P27 -> 2576.3116 | V27: ='入力根拠'!H795 -> 1.3 | X27: ='入力根拠'!E899 -> 9.1 | Y27: =(U25+(((U42-U25)*(X27-'入力根拠'!F726))/T25)) -> 7451.9368 | Z27: 155 | AA27: =Y27 -> 7451.9368
F28: ='入力根拠'!F831 -> 10.4 | G28: =(C25+(((C42-C25)*(F28-'入力根拠'!F710))/B25)) -> 3190.7105 | I28: =G28 -> 3190.7105 | O28: ='入力根拠'!F865 -> 10.4 | P28: =(L25+(((L42-L25)*(O28-'入力根拠'!F717))/K25)) -> 2757.7368 | R28: =P28 -> 2757.7368 | X28: ='入力根拠'!F899 -> 10.4 | Y28: =(U25+(((U42-U25)*(X28-'入力根拠'!F726))/T25)) -> 7976.7263 | AA28: =Y28 -> 7976.7263
D29: ='入力根拠'!H742 -> 1.3 | F29: ='入力根拠'!E832 -> 10.4 | G29: =(C25+(((C42-C25)*(F29-'入力根拠'!F710))/B25)) -> 3190.7105 | H29: 106 | I29: =G29 -> 3190.7105 | M29: ='入力根拠'!H768 -> 1.3 | O29: ='入力根拠'!E866 -> 10.4 | P29: =(L25+(((L42-L25)*(O29-'入力根拠'!F717))/K25)) -> 2757.7368 | Q29: 131 | R29: =P29 -> 2757.7368 | V29: ='入力根拠'!H796 -> 1.3 | X29: ='入力根拠'!E900 -> 10.4 | Y29: =(U25+(((U42-U25)*(X29-'入力根拠'!F726))/T25)) -> 7976.7263 | Z29: 156 | AA29: =Y29 -> 7976.7263
F30: ='入力根拠'!F832 -> 11.7 | G30: =(C25+(((C42-C25)*(F30-'入力根拠'!F710))/B25)) -> 3400.6263 | I30: =G30 -> 3400.6263 | O30: ='入力根拠'!F866 -> 11.7 | P30: =(L25+(((L42-L25)*(O30-'入力根拠'!F717))/K25)) -> 2939.1621 | R30: =P30 -> 2939.1621 | X30: ='入力根拠'!F900 -> 11.7 | Y30: =(U25+(((U42-U25)*(X30-'入力根拠'!F726))/T25)) -> 8501.5158 | AA30: =Y30 -> 8501.5158
D31: ='入力根拠'!H743 -> 1.3 | F31: ='入力根拠'!E833 -> 11.7 | G31: =(C25+(((C42-C25)*(F31-'入力根拠'!F710))/B25)) -> 3400.6263 | H31: 107 | I31: =G31 -> 3400.6263 | M31: ='入力根拠'!H769 -> 1.3 | O31: ='入力根拠'!E867 -> 11.7 | P31: =(L25+(((L42-L25)*(O31-'入力根拠'!F717))/K25)) -> 2939.1621 | Q31: 132 | R31: =P31 -> 2939.1621 | V31: ='入力根拠'!H797 -> 1.3 | X31: ='入力根拠'!E901 -> 11.7 | Y31: =(U25+(((U42-U25)*(X31-'入力根拠'!F726))/T25)) -> 8501.5158 | Z31: 157 | AA31: =Y31 -> 8501.5158
F32: ='入力根拠'!F833 -> 13 | G32: =(C25+(((C42-C25)*(F32-'入力根拠'!F710))/B25)) -> 3610.5421 | I32: =G32 -> 3610.5421 | O32: ='入力根拠'!F867 -> 13 | P32: =(L25+(((L42-L25)*(O32-'入力根拠'!F717))/K25)) -> 3120.5874 | R32: =P32 -> 3120.5874 | X32: ='入力根拠'!F901 -> 13 | Y32: =(U25+(((U42-U25)*(X32-'入力根拠'!F726))/T25)) -> 9026.3053 | AA32: =Y32 -> 9026.3053
D33: ='入力根拠'!H744 -> 1.3 | F33: ='入力根拠'!E834 -> 13 | G33: =(C25+(((C42-C25)*(F33-'入力根拠'!F710))/B25)) -> 3610.5421 | H33: 108 | I33: =G33 -> 3610.5421 | M33: ='入力根拠'!H772 -> 1.3 | O33: ='入力根拠'!E868 -> 13 | P33: =(L25+(((L42-L25)*(O33-'入力根拠'!F717))/K25)) -> 3120.5874 | Q33: 133 | R33: =P33 -> 3120.5874 | V33: ='入力根拠'!H798 -> 1.3 | X33: ='入力根拠'!E902 -> 13 | Y33: =(U25+(((U42-U25)*(X33-'入力根拠'!F726))/T25)) -> 9026.3053 | Z33: 158 | AA33: =Y33 -> 9026.3053
F34: ='入力根拠'!F834 -> 14.3 | G34: =(C25+(((C42-C25)*(F34-'入力根拠'!F710))/B25)) -> 3820.4579 | I34: =G34 -> 3820.4579 | O34: ='入力根拠'!F868 -> 14.3 | P34: =(L25+(((L42-L25)*(O34-'入力根拠'!F717))/K25)) -> 3302.0126 | R34: =P34 -> 3302.0126 | X34: ='入力根拠'!F902 -> 14.3 | Y34: =(U25+(((U42-U25)*(X34-'入力根拠'!F726))/T25)) -> 9551.0947 | AA34: =Y34 -> 9551.0947
D35: ='入力根拠'!H745 -> 1.3 | F35: ='入力根拠'!E835 -> 14.3 | G35: =(C25+(((C42-C25)*(F35-'入力根拠'!F710))/B25)) -> 3820.4579 | H35: 109 | I35: =G35 -> 3820.4579 | M35: ='入力根拠'!H773 -> 1.3 | O35: ='入力根拠'!E869 -> 14.3 | P35: =(L25+(((L42-L25)*(O35-'入力根拠'!F717))/K25)) -> 3302.0126 | Q35: 134 | R35: =P35 -> 3302.0126 | V35: ='入力根拠'!H799 -> 1.3 | X35: ='入力根拠'!E903 -> 14.3 | Y35: =(U25+(((U42-U25)*(X35-'入力根拠'!F726))/T25)) -> 9551.0947 | Z35: 159 | AA35: =Y35 -> 9551.0947
F36: ='入力根拠'!F835 -> 15.6 | G36: =(C25+(((C42-C25)*(F36-'入力根拠'!F710))/B25)) -> 4030.3737 | I36: =G36 -> 4030.3737 | O36: ='入力根拠'!F869 -> 15.6 | P36: =(L25+(((L42-L25)*(O36-'入力根拠'!F717))/K25)) -> 3483.4379 | R36: =P36 -> 3483.4379 | X36: ='入力根拠'!F903 -> 15.6 | Y36: =(U25+(((U42-U25)*(X36-'入力根拠'!F726))/T25)) -> 10075.884 | AA36: =Y36 -> 10075.884
D37: ='入力根拠'!H746 -> 1.3 | F37: ='入力根拠'!E836 -> 15.6 | G37: =(C25+(((C42-C25)*(F37-'入力根拠'!F710))/B25)) -> 4030.3737 | H37: 110 | I37: =G37 -> 4030.3737 | M37: ='入力根拠'!H774 -> 1.3 | O37: ='入力根拠'!E870 -> 15.6 | P37: =(L25+(((L42-L25)*(O37-'入力根拠'!F717))/K25)) -> 3483.4379 | Q37: 135 | R37: =P37 -> 3483.4379 | V37: ='入力根拠'!H800 -> 1.3 | X37: ='入力根拠'!E904 -> 15.6 | Y37: =(U25+(((U42-U25)*(X37-'入力根拠'!F726))/T25)) -> 10075.884 | Z37: 160 | AA37: =Y37 -> 10075.884
F38: ='入力根拠'!F836 -> 16.9 | G38: =(C25+(((C42-C25)*(F38-'入力根拠'!F710))/B25)) -> 4240.2895 | I38: =G38 -> 4240.2895 | O38: ='入力根拠'!F870 -> 16.9 | P38: =(L25+(((L42-L25)*(O38-'入力根拠'!F717))/K25)) -> 3664.8632 | R38: =P38 -> 3664.8632 | X38: ='入力根拠'!F904 -> 16.9 | Y38: =(U25+(((U42-U25)*(X38-'入力根拠'!F726))/T25)) -> 10600.674 | AA38: =Y38 -> 10600.674
D39: ='入力根拠'!H747 -> 1.3 | F39: ='入力根拠'!E839 -> 16.9 | G39: =(C25+(((C42-C25)*(F39-'入力根拠'!F710))/B25)) -> 4240.2895 | H39: 111 | I39: =G39 -> 4240.2895 | M39: ='入力根拠'!H775 -> 1.3 | O39: ='入力根拠'!E873 -> 16.9 | P39: =(L25+(((L42-L25)*(O39-'入力根拠'!F717))/K25)) -> 3664.8632 | Q39: 136 | R39: =P39 -> 3664.8632 | V39: ='入力根拠'!H801 -> 1.3 | X39: ='入力根拠'!E907 -> 16.9 | Y39: =(U25+(((U42-U25)*(X39-'入力根拠'!F726))/T25)) -> 10600.674 | Z39: 161 | AA39: =Y39 -> 10600.674
F40: ='入力根拠'!F839 -> 18.2 | G40: =(C25+(((C42-C25)*(F40-'入力根拠'!F710))/B25)) -> 4450.2053 | I40: =G40 -> 4450.2053 | O40: ='入力根拠'!F873 -> 18.2 | P40: =(L25+(((L42-L25)*(O40-'入力根拠'!F717))/K25)) -> 3846.2884 | R40: =P40 -> 3846.2884 | X40: ='入力根拠'!F907 -> 18.2 | Y40: =(U25+(((U42-U25)*(X40-'入力根拠'!F726))/T25)) -> 11125.463 | AA40: =Y40 -> 11125.463
...

Sheet 杭周面ばね
A1: 鉛直せん断地盤ばね定数 | H1: 鉛直せん断地盤ばね定数 | O1: 鉛直せん断地盤ばね定数
A2: 層番号 | B2: 層厚 (m) | C2: 鉛直せん断地盤ばね定数 Kv (kN/m²) | D2: 分布幅 (m) | F2: 節点番号 | G2: 各節点の鉛直ばね定数 Kv (kN/m) | H2: 層番号 | I2: 層厚 (m) | J2: 鉛直せん断地盤ばね定数 Kv (kN/m²) | K2: 分布幅 (m) | M2: 節点番号 | N2: 各節点の鉛直ばね定数 Kv (kN/m) | O2: 層番号 | P2: 層厚 (m) | Q2: 鉛直せん断地盤ばね定数 Kv (kN/m²) | R2: 分布幅 (m) | T2: 節点番号 | U2: 各節点の鉛直ばね定数 Kv (kN/m)
A3: 1 | B3: ='入力根拠'!G1140 -> 1.5 | C3: ='入力根拠'!H1140 -> 0 | D3: ='入力根拠'!K1174 -> 0.65 | F3: 98 | G3: =(C3*D3) -> 0 | H3: 1 | I3: ='入力根拠'!G1151 -> 1.5 | J3: ='入力根拠'!H1151 -> 0 | K3: ='入力根拠'!K1203 -> 0.65 | M3: 123 | N3: =(J3*K3) -> 0 | O3: 1 | P3: ='入力根拠'!G1160 -> 1.5 | Q3: ='入力根拠'!H1160 -> 0 | R3: ='入力根拠'!K1232 -> 0.65 | T3: 148 | U3: =(Q3*R3) -> 0
D4: ='入力根拠'!K1175 -> 1.3 | E4: ='入力根拠'!G1263 -> 0.85 | F4: 99 | G4: =SUM((C3*E4),(C5*E5)) -> 0 | K4: ='入力根拠'!K1204 -> 1.3 | L4: ='入力根拠'!G1300 -> 0.85 | M4: 124 | N4: =SUM((J3*L4),(J5*L5)) -> 0 | R4: ='入力根拠'!K1233 -> 1.3 | S4: ='入力根拠'!G1337 -> 0.85 | T4: 149 | U4: =SUM((Q3*S4),(Q5*S5)) -> 0
A5: 2 | B5: ='入力根拠'!G1141 -> 1.3 | C5: ='入力根拠'!H1141 -> 0 | E5: ='入力根拠'!G1264 -> 0.45 | H5: 2 | I5: ='入力根拠'!G1152 -> 1.3 | J5: ='入力根拠'!H1152 -> 0 | L5: ='入力根拠'!G1301 -> 0.45 | O5: 2 | P5: ='入力根拠'!G1161 -> 1.3 | Q5: ='入力根拠'!H1161 -> 0 | S5: ='入力根拠'!G1338 -> 0.45
D6: ='入力根拠'!K1176 -> 1.3 | E6: ='入力根拠'!G1265 -> 0.85 | F6: 100 | G6: =SUM((C5*E6),(C7*E7)) -> 0 | K6: ='入力根拠'!K1205 -> 1.3 | L6: ='入力根拠'!G1302 -> 0.85 | M6: 125 | N6: =SUM((J5*L6),(J7*L7)) -> 0 | R6: ='入力根拠'!K1234 -> 1.3 | S6: ='入力根拠'!G1339 -> 0.85 | T6: 150 | U6: =SUM((Q5*S6),(Q7*S7)) -> 0
A7: 3 | B7: ='入力根拠'!G1142 -> 2.145 | C7: ='入力根拠'!H1142 -> 0 | E7: ='入力根拠'!G1266 -> 0.45 | H7: 3 | I7: ='入力根拠'!G1153 -> 2.145 | J7: ='入力根拠'!H1153 -> 0 | L7: ='入力根拠'!G1303 -> 0.45 | O7: 3 | P7: ='入力根拠'!G1164 -> 2.145 | Q7: ='入力根拠'!H1164 -> 0 | S7: ='入力根拠'!G1340 -> 0.45
D8: ='入力根拠'!K1177 -> 1.3 | F8: 101 | G8: =(C7*D8) -> 0 | K8: ='入力根拠'!K1206 -> 1.3 | M8: 126 | N8: =(J7*K8) -> 0 | R8: ='入力根拠'!K1235 -> 1.3 | T8: 151 | U8: =(Q7*R8) -> 0
D9: ='入力根拠'!K1180 -> 1.3 | E9: ='入力根拠'!G1268 -> 0.395 | F9: 102 | G9: =SUM((C7*E9),(C10*E10),(C11*E11)) -> 51628.885 | K9: ='入力根拠'!K1207 -> 1.3 | L9: ='入力根拠'!G1305 -> 0.395 | M9: 127 | N9: =SUM((J7*L9),(J10*L10),(J11*L11)) -> 34419.005 | R9: ='入力根拠'!K1236 -> 1.3 | S9: ='入力根拠'!G1342 -> 0.395 | T9: 152 | U9: =SUM((Q7*S9),(Q10*S10),(Q11*S11)) -> 51628.885
B10: ='入力根拠'!G1143 -> 0.755 | C10: ='入力根拠'!H1143 -> 46127 | E10: ='入力根拠'!G1269 -> 0.755 | I10: ='入力根拠'!G1154 -> 0.755 | J10: ='入力根拠'!H1154 -> 30751 | L10: ='入力根拠'!G1306 -> 0.755 | P10: ='入力根拠'!G1165 -> 0.755 | Q10: ='入力根拠'!H1165 -> 46127 | S10: ='入力根拠'!G1343 -> 0.755
A11: 4 | B11: ='入力根拠'!G1144 -> 2.6 | C11: ='入力根拠'!H1144 -> 112020 | E11: ='入力根拠'!G1270 -> 0.15 | H11: 4 | I11: ='入力根拠'!G1155 -> 2.6 | J11: ='入力根拠'!H1155 -> 74680 | L11: ='入力根拠'!G1307 -> 0.15 | O11: 4 | P11: ='入力根拠'!G1166 -> 2.6 | Q11: ='入力根拠'!H1166 -> 112020 | S11: ='入力根拠'!G1344 -> 0.15
D12: ='入力根拠'!K1181 -> 1.3 | F12: 103 | G12: =(C11*D12) -> 145626 | K12: ='入力根拠'!K1208 -> 1.3 | M12: 128 | N12: =(J11*K12) -> 97084 | R12: ='入力根拠'!K1237 -> 1.3 | T12: 153 | U12: =(Q11*R12) -> 145626
D13: ='入力根拠'!K1182 -> 1.3 | E13: ='入力根拠'!G1272 -> 1.15 | F13: 104 | G13: =SUM((C11*E13),(C14*E14)) -> 155633.7 | K13: ='入力根拠'!K1209 -> 1.3 | L13: ='入力根拠'!G1309 -> 1.15 | M13: 129 | N13: =SUM((J11*L13),(J14*L14)) -> 103755.7 | R13: ='入力根拠'!K1238 -> 1.3 | S13: ='入力根拠'!G1348 -> 1.15 | T13: 154 | U13: =SUM((Q11*S13),(Q14*S14)) -> 155633.7
A14: 5 | B14: ='入力根拠'!G1147 -> 0.6 | C14: ='入力根拠'!H1147 -> 178738 | E14: ='入力根拠'!G1273 -> 0.15 | H14: 5 | I14: ='入力根拠'!G1156 -> 0.6 | J14: ='入力根拠'!H1156 -> 119158 | L14: ='入力根拠'!G1310 -> 0.15 | O14: 5 | P14: ='入力根拠'!G1167 -> 0.6 | Q14: ='入力根拠'!H1167 -> 178738 | S14: ='入力根拠'!G1349 -> 0.15
D15: ='入力根拠'!K1183 -> 1.3 | E15: ='入力根拠'!G1274 -> 0.45 | F15: 105 | G15: =SUM((C14*E15),(C16*E16)) -> 223256.75 | K15: ='入力根拠'!K1210 -> 1.3 | L15: ='入力根拠'!G1313 -> 0.45 | M15: 130 | N15: =SUM((J14*L15),(J16*L16)) -> 148838.1 | R15: ='入力根拠'!K1239 -> 1.3 | S15: ='入力根拠'!G1350 -> 0.45 | T15: 155 | U15: =SUM((Q14*S15),(Q16*S16)) -> 223256.75
A16: 6 | B16: ='入力根拠'!G1148 -> 9.5 | C16: ='入力根拠'!H1148 -> 168029 | E16: ='入力根拠'!G1275 -> 0.85 | H16: 6 | I16: ='入力根拠'!G1157 -> 9.5 | J16: ='入力根拠'!H1157 -> 112020 | L16: ='入力根拠'!G1314 -> 0.85 | O16: 6 | P16: ='入力根拠'!G1168 -> 9.5 | Q16: ='入力根拠'!H1168 -> 168029 | S16: ='入力根拠'!G1351 -> 0.85
D17: ='入力根拠'!K1184 -> 1.3 | F17: 106 | G17: =(C16*D17) -> 218437.7 | K17: ='入力根拠'!K1211 -> 1.3 | M17: 131 | N17: =(J16*K17) -> 145626 | R17: ='入力根拠'!K1240 -> 1.3 | T17: 156 | U17: =(Q16*R17) -> 218437.7
D18: ='入力根拠'!K1185 -> 1.3 | F18: 107 | G18: =(C16*D18) -> 218437.7 | K18: ='入力根拠'!K1214 -> 1.3 | M18: 132 | N18: =(J16*K18) -> 145626 | R18: ='入力根拠'!K1241 -> 1.3 | T18: 157 | U18: =(Q16*R18) -> 218437.7
D19: ='入力根拠'!K1186 -> 1.3 | F19: 108 | G19: =(C16*D19) -> 218437.7 | K19: ='入力根拠'!K1215 -> 1.3 | M19: 133 | N19: =(J16*K19) -> 145626 | R19: ='入力根拠'!K1242 -> 1.3 | T19: 158 | U19: =(Q16*R19) -> 218437.7
D20: ='入力根拠'!K1187 -> 1.3 | F20: 109 | G20: =(C16*D20) -> 218437.7 | K20: ='入力根拠'!K1216 -> 1.3 | M20: 134 | N20: =(J16*K20) -> 145626 | R20: ='入力根拠'!K1243 -> 1.3 | T20: 159 | U20: =(Q16*R20) -> 218437.7
D21: ='入力根拠'!K1188 -> 1.3 | F21: 110 | G21: =(C16*D21) -> 218437.7 | K21: ='入力根拠'!K1217 -> 1.3 | M21: 135 | N21: =(J16*K21) -> 145626 | R21: ='入力根拠'!K1244 -> 1.3 | T21: 160 | U21: =(Q16*R21) -> 218437.7
D22: ='入力根拠'!K1189 -> 1.3 | F22: 111 | G22: =(C16*D22) -> 218437.7 | K22: ='入力根拠'!K1218 -> 1.3 | M22: 136 | N22: =(J16*K22) -> 145626 | R22: ='入力根拠'!K1245 -> 1.3 | T22: 161 | U22: =(Q16*R22) -> 218437.7
D23: ='入力根拠'!K1190 -> 1.3 | E23: ='入力根拠'!G1284 -> 0.85 | F23: 112 | G23: =SUM((C16*E23),(C24*E24)) -> 179148.65 | K23: ='入力根拠'!K1219 -> 1.3 | L23: ='入力根拠'!G1321 -> 0.85 | M23: 137 | N23: =SUM((J16*L23),(J24*L24)) -> 119432.85 | R23: ='入力根拠'!K1248 -> 1.3 | S23: ='入力根拠'!G1358 -> 0.85 | T23: 162 | U23: =SUM((Q16*S23),(Q24*S24)) -> 179148.65
A24: 7 | B24: ='入力根拠'!G1149 -> 11.3 | C24: ='入力根拠'!H1149 -> 80720 | E24: ='入力根拠'!G1285 -> 0.45 | H24: 7 | I24: ='入力根拠'!G1158 -> 11.3 | J24: ='入力根拠'!H1158 -> 53813 | L24: ='入力根拠'!G1322 -> 0.45 | O24: 7 | P24: ='入力根拠'!G1169 -> 11.3 | Q24: ='入力根拠'!H1169 -> 80720 | S24: ='入力根拠'!G1359 -> 0.45
D25: ='入力根拠'!K1191 -> 1.3 | F25: 113 | G25: =(C24*D25) -> 104936 | K25: ='入力根拠'!K1220 -> 1.3 | M25: 138 | N25: =(J24*K25) -> 69956.9 | R25: ='入力根拠'!K1249 -> 1.3 | T25: 163 | U25: =(Q24*R25) -> 104936
D26: ='入力根拠'!K1192 -> 1.3 | F26: 114 | G26: =(C24*D26) -> 104936 | K26: ='入力根拠'!K1221 -> 1.3 | M26: 139 | N26: =(J24*K26) -> 69956.9 | R26: ='入力根拠'!K1250 -> 1.3 | T26: 164 | U26: =(Q24*R26) -> 104936
D27: ='入力根拠'!K1193 -> 1.3 | F27: 115 | G27: =(C24*D27) -> 104936 | K27: ='入力根拠'!K1222 -> 1.3 | M27: 140 | N27: =(J24*K27) -> 69956.9 | R27: ='入力根拠'!K1251 -> 1.3 | T27: 165 | U27: =(Q24*R27) -> 104936
D28: ='入力根拠'!K1194 -> 1.3 | F28: 116 | G28: =(C24*D28) -> 104936 | K28: ='入力根拠'!K1223 -> 1.3 | M28: 141 | N28: =(J24*K28) -> 69956.9 | R28: ='入力根拠'!K1252 -> 1.3 | T28: 166 | U28: =(Q24*R28) -> 104936
D29: ='入力根拠'!K1197 -> 1.3 | F29: 117 | G29: =(C24*D29) -> 104936 | K29: ='入力根拠'!K1224 -> 1.3 | M29: 142 | N29: =(J24*K29) -> 69956.9 | R29: ='入力根拠'!K1253 -> 1.3 | T29: 167 | U29: =(Q24*R29) -> 104936
D30: ='入力根拠'!K1198 -> 1.3 | F30: 118 | G30: =(C24*D30) -> 104936 | K30: ='入力根拠'!K1225 -> 1.3 | M30: 143 | N30: =(J24*K30) -> 69956.9 | R30: ='入力根拠'!K1254 -> 1.3 | T30: 168 | U30: =(Q24*R30) -> 104936
D31: ='入力根拠'!K1199 -> 1.3 | F31: 119 | G31: =(C24*D31) -> 104936 | K31: ='入力根拠'!K1226 -> 1.3 | M31: 144 | N31: =(J24*K31) -> 69956.9 | R31: ='入力根拠'!K1255 -> 1.3 | T31: 169 | U31: =(Q24*R31) -> 104936
D32: ='入力根拠'!K1200 -> 1.3 | F32: 120 | G32: =(C24*D32) -> 104936 | K32: ='入力根拠'!K1227 -> 1.3 | M32: 145 | N32: =(J24*K32) -> 69956.9 | R32: ='入力根拠'!K1256 -> 1.3 | T32: 170 | U32: =(Q24*R32) -> 104936
D33: ='入力根拠'!K1201 -> 1.2 | E33: ='入力根拠'!G1296 -> 0.45 | F33: 121 | G33: =SUM((C24*E33),(C34*E34)) -> 36324 | K33: ='入力根拠'!K1228 -> 1.2 | L33: ='入力根拠'!G1333 -> 0.45 | M33: 146 | N33: =SUM((J24*L33),(J34*L34)) -> 24215.85 | R33: ='入力根拠'!K1257 -> 1.2 | S33: ='入力根拠'!G1370 -> 0.45 | T33: 171 | U33: =SUM((Q24*S33),(Q34*S34)) -> 36324
B34: ='入力根拠'!G1150 -> 1.3 | C34: ='入力根拠'!H1150 -> 0 | E34: ='入力根拠'!G1297 -> 0.75 | I34: ='入力根拠'!G1159 -> 1.3 | J34: ='入力根拠'!H1159 -> 0 | L34: ='入力根拠'!G1334 -> 0.75 | P34: ='入力根拠'!G1170 -> 1.3 | Q34: ='入力根拠'!H1170 -> 0 | S34: ='入力根拠'!G1371 -> 0.75
D35: ='入力根拠'!K1202 -> 0.55 | F35: 122 | G35: =(C34*D35) -> 0 | K35: ='入力根拠'!K1231 -> 0.55 | M35: 147 | N35: =(J34*K35) -> 0 | R35: ='入力根拠'!K1258 -> 0.55 | T35: 172 | U35: =(Q34*R35) -> 0
A36: Σ | B36: =SUM(B3,B5,B7,B10,B11,B14,B16,B24,B34) -> 31 | D36: =SUM(D3,D4,D6,D8,D9,D12,D13,D15,D17,D18,D19,D20,D21,D22,D23,D25,D26,D27,D28,D29,D30,D31,D32,D33,D35) -> 31 | H36: Σ | I36: =SUM(I3,I5,I7,I10,I11,I14,I16,I24,I34) -> 31 | K36: =SUM(K3,K4,K6,K8,K9,K12,K13,K15,K17,K18,K19,K20,K21,K22,K23,K25,K26,K27,K28,K29,K30,K31,K32,K33,K35) -> 31 | O36: Σ | P36: =SUM(P3,P5,P7,P10,P11,P14,P16,P24,P34) -> 31 | R36: =SUM(R3,R4,R6,R8,R9,R12,R13,R15,R17,R18,R19,R20,R21,R22,R23,R25,R26,R27,R28,R29,R30,R31,R32,R33,R35) -> 31

Sheet 杭周面の支持力
A1: 杭周面の支持力 | H1: 杭周面の支持力 | O1: 杭周面の支持力
A2: 層番号 | B2: 層厚 (m) | C2: 周面支持力度 rfk (kN/m) | D2: 分布幅 (m) | F2: 節点番号 | G2: 各節点の周面支持力 Rfk (kN) | H2: 層番号 | I2: 層厚 (m) | J2: 周面支持力度 rfk (kN/m) | K2: 分布幅 (m) | M2: 節点番号 | N2: 各節点の周面支持力 Rfk (kN) | O2: 層番号 | P2: 層厚 (m) | Q2: 周面支持力度 rfk (kN/m) | R2: 分布幅 (m) | T2: 節点番号 | U2: 各節点の周面支持力 Rfk (kN)
A3: 1 | B3: ='入力根拠'!G1140 -> 1.5 | C3: ='入力根拠'!I1140 -> 0 | D3: ='入力根拠'!K1174 -> 0.65 | F3: 98 | G3: =(C3*D3) -> 0 | H3: 1 | I3: ='入力根拠'!G1151 -> 1.5 | J3: ='入力根拠'!I1151 -> 0 | K3: ='入力根拠'!K1203 -> 0.65 | M3: 123 | N3: =(J3*K3) -> 0 | O3: 1 | P3: ='入力根拠'!G1160 -> 1.5 | Q3: ='入力根拠'!I1160 -> 0 | R3: ='入力根拠'!K1232 -> 0.65 | T3: 148 | U3: =(Q3*R3) -> 0
D4: ='入力根拠'!K1175 -> 1.3 | E4: ='入力根拠'!G1263 -> 0.85 | F4: 99 | G4: =SUM((C3*E4),(C5*E5)) -> 0 | K4: ='入力根拠'!K1204 -> 1.3 | L4: ='入力根拠'!G1300 -> 0.85 | M4: 124 | N4: =SUM((J3*L4),(J5*L5)) -> 0 | R4: ='入力根拠'!K1233 -> 1.3 | S4: ='入力根拠'!G1337 -> 0.85 | T4: 149 | U4: =SUM((Q3*S4),(Q5*S5)) -> 0
A5: 2 | B5: ='入力根拠'!G1141 -> 1.3 | C5: ='入力根拠'!I1141 -> 0 | E5: ='入力根拠'!G1264 -> 0.45 | H5: 2 | I5: ='入力根拠'!G1152 -> 1.3 | J5: ='入力根拠'!I1152 -> 0 | L5: ='入力根拠'!G1301 -> 0.45 | O5: 2 | P5: ='入力根拠'!G1161 -> 1.3 | Q5: ='入力根拠'!I1161 -> 0 | S5: ='入力根拠'!G1338 -> 0.45
D6: ='入力根拠'!K1176 -> 1.3 | E6: ='入力根拠'!G1265 -> 0.85 | F6: 100 | G6: =SUM((C5*E6),(C7*E7)) -> 0 | K6: ='入力根拠'!K1205 -> 1.3 | L6: ='入力根拠'!G1302 -> 0.85 | M6: 125 | N6: =SUM((J5*L6),(J7*L7)) -> 0 | R6: ='入力根拠'!K1234 -> 1.3 | S6: ='入力根拠'!G1339 -> 0.85 | T6: 150 | U6: =SUM((Q5*S6),(Q7*S7)) -> 0
A7: 3 | B7: ='入力根拠'!G1142 -> 2.145 | C7: ='入力根拠'!I1142 -> 0 | E7: ='入力根拠'!G1266 -> 0.45 | H7: 3 | I7: ='入力根拠'!G1153 -> 2.145 | J7: ='入力根拠'!I1153 -> 0 | L7: ='入力根拠'!G1303 -> 0.45 | O7: 3 | P7: ='入力根拠'!G1164 -> 2.145 | Q7: ='入力根拠'!I1164 -> 0 | S7: ='入力根拠'!G1340 -> 0.45
D8: ='入力根拠'!K1177 -> 1.3 | F8: 101 | G8: =(C7*D8) -> 0 | K8: ='入力根拠'!K1206 -> 1.3 | M8: 126 | N8: =(J7*K8) -> 0 | R8: ='入力根拠'!K1235 -> 1.3 | T8: 151 | U8: =(Q7*R8) -> 0
D9: ='入力根拠'!K1180 -> 1.3 | E9: ='入力根拠'!G1268 -> 0.395 | F9: 102 | G9: =SUM((C7*E9),(C10*E10),(C11*E11)) -> 433.7705 | K9: ='入力根拠'!K1207 -> 1.3 | L9: ='入力根拠'!G1305 -> 0.395 | M9: 127 | N9: =SUM((J7*L9),(J10*L10),(J11*L11)) -> 289.13 | R9: ='入力根拠'!K1236 -> 1.3 | S9: ='入力根拠'!G1342 -> 0.395 | T9: 152 | U9: =SUM((Q7*S9),(Q10*S10),(Q11*S11)) -> 433.7705
B10: ='入力根拠'!G1143 -> 0.755 | C10: ='入力根拠'!I1143 -> 294.1 | E10: ='入力根拠'!G1269 -> 0.755 | I10: ='入力根拠'!G1154 -> 0.755 | J10: ='入力根拠'!I1154 -> 196 | L10: ='入力根拠'!G1306 -> 0.755 | P10: ='入力根拠'!G1165 -> 0.755 | Q10: ='入力根拠'!I1165 -> 294.1 | S10: ='入力根拠'!G1343 -> 0.755
A11: 4 | B11: ='入力根拠'!G1144 -> 2.6 | C11: ='入力根拠'!I1144 -> 1411.5 | E11: ='入力根拠'!G1270 -> 0.15 | H11: 4 | I11: ='入力根拠'!G1155 -> 2.6 | J11: ='入力根拠'!I1155 -> 941 | L11: ='入力根拠'!G1307 -> 0.15 | O11: 4 | P11: ='入力根拠'!G1166 -> 2.6 | Q11: ='入力根拠'!I1166 -> 1411.5 | S11: ='入力根拠'!G1344 -> 0.15
D12: ='入力根拠'!K1181 -> 1.3 | F12: 103 | G12: =(C11*D12) -> 1834.95 | K12: ='入力根拠'!K1208 -> 1.3 | M12: 128 | N12: =(J11*K12) -> 1223.3 | R12: ='入力根拠'!K1237 -> 1.3 | T12: 153 | U12: =(Q11*R12) -> 1834.95
D13: ='入力根拠'!K1182 -> 1.3 | E13: ='入力根拠'!G1272 -> 1.15 | F13: 104 | G13: =SUM((C11*E13),(C14*E14)) -> 1794.36 | K13: ='入力根拠'!K1209 -> 1.3 | L13: ='入力根拠'!G1309 -> 1.15 | M13: 129 | N13: =SUM((J11*L13),(J14*L14)) -> 1196.24 | R13: ='入力根拠'!K1238 -> 1.3 | S13: ='入力根拠'!G1348 -> 1.15 | T13: 154 | U13: =SUM((Q11*S13),(Q14*S14)) -> 1794.36
A14: 5 | B14: ='入力根拠'!G1147 -> 0.6 | C14: ='入力根拠'!I1147 -> 1140.9 | E14: ='入力根拠'!G1273 -> 0.15 | H14: 5 | I14: ='入力根拠'!G1156 -> 0.6 | J14: ='入力根拠'!I1156 -> 760.6 | L14: ='入力根拠'!G1310 -> 0.15 | O14: 5 | P14: ='入力根拠'!G1167 -> 0.6 | Q14: ='入力根拠'!I1167 -> 1140.9 | S14: ='入力根拠'!G1349 -> 0.15
D15: ='入力根拠'!K1183 -> 1.3 | E15: ='入力根拠'!G1274 -> 0.45 | F15: 105 | G15: =SUM((C14*E15),(C16*E16)) -> 2313.025 | K15: ='入力根拠'!K1210 -> 1.3 | L15: ='入力根拠'!G1313 -> 0.45 | M15: 130 | N15: =SUM((J14*L15),(J16*L16)) -> 1542.045 | R15: ='入力根拠'!K1239 -> 1.3 | S15: ='入力根拠'!G1350 -> 0.45 | T15: 155 | U15: =SUM((Q14*S15),(Q16*S16)) -> 2313.025
A16: 6 | B16: ='入力根拠'!G1148 -> 9.5 | C16: ='入力根拠'!I1148 -> 2117.2 | E16: ='入力根拠'!G1275 -> 0.85 | H16: 6 | I16: ='入力根拠'!G1157 -> 9.5 | J16: ='入力根拠'!I1157 -> 1411.5 | L16: ='入力根拠'!G1314 -> 0.85 | O16: 6 | P16: ='入力根拠'!G1168 -> 9.5 | Q16: ='入力根拠'!I1168 -> 2117.2 | S16: ='入力根拠'!G1351 -> 0.85
D17: ='入力根拠'!K1184 -> 1.3 | F17: 106 | G17: =(C16*D17) -> 2752.36 | K17: ='入力根拠'!K1211 -> 1.3 | M17: 131 | N17: =(J16*K17) -> 1834.95 | R17: ='入力根拠'!K1240 -> 1.3 | T17: 156 | U17: =(Q16*R17) -> 2752.36
D18: ='入力根拠'!K1185 -> 1.3 | F18: 107 | G18: =(C16*D18) -> 2752.36 | K18: ='入力根拠'!K1214 -> 1.3 | M18: 132 | N18: =(J16*K18) -> 1834.95 | R18: ='入力根拠'!K1241 -> 1.3 | T18: 157 | U18: =(Q16*R18) -> 2752.36
D19: ='入力根拠'!K1186 -> 1.3 | F19: 108 | G19: =(C16*D19) -> 2752.36 | K19: ='入力根拠'!K1215 -> 1.3 | M19: 133 | N19: =(J16*K19) -> 1834.95 | R19: ='入力根拠'!K1242 -> 1.3 | T19: 158 | U19: =(Q16*R19) -> 2752.36
D20: ='入力根拠'!K1187 -> 1.3 | F20: 109 | G20: =(C16*D20) -> 2752.36 | K20: ='入力根拠'!K1216 -> 1.3 | M20: 134 | N20: =(J16*K20) -> 1834.95 | R20: ='入力根拠'!K1243 -> 1.3 | T20: 159 | U20: =(Q16*R20) -> 2752.36
D21: ='入力根拠'!K1188 -> 1.3 | F21: 110 | G21: =(C16*D21) -> 2752.36 | K21: ='入力根拠'!K1217 -> 1.3 | M21: 135 | N21: =(J16*K21) -> 1834.95 | R21: ='入力根拠'!K1244 -> 1.3 | T21: 160 | U21: =(Q16*R21) -> 2752.36
D22: ='入力根拠'!K1189 -> 1.3 | F22: 111 | G22: =(C16*D22) -> 2752.36 | K22: ='入力根拠'!K1218 -> 1.3 | M22: 136 | N22: =(J16*K22) -> 1834.95 | R22: ='入力根拠'!K1245 -> 1.3 | T22: 161 | U22: =(Q16*R22) -> 2752.36
D23: ='入力根拠'!K1190 -> 1.3 | E23: ='入力根拠'!G1284 -> 0.85 | F23: 112 | G23: =SUM((C16*E23),(C24*E24)) -> 2032.495 | K23: ='入力根拠'!K1219 -> 1.3 | L23: ='入力根拠'!G1321 -> 0.85 | M23: 137 | N23: =SUM((J16*L23),(J24*L24)) -> 1355.025 | R23: ='入力根拠'!K1248 -> 1.3 | S23: ='入力根拠'!G1358 -> 0.85 | T23: 162 | U23: =SUM((Q16*S23),(Q24*S24)) -> 2032.495
A24: 7 | B24: ='入力根拠'!G1149 -> 11.3 | C24: ='入力根拠'!I1149 -> 517.5 | E24: ='入力根拠'!G1285 -> 0.45 | H24: 7 | I24: ='入力根拠'!G1158 -> 11.3 | J24: ='入力根拠'!I1158 -> 345 | L24: ='入力根拠'!G1322 -> 0.45 | O24: 7 | P24: ='入力根拠'!G1169 -> 11.3 | Q24: ='入力根拠'!I1169 -> 517.5 | S24: ='入力根拠'!G1359 -> 0.45
D25: ='入力根拠'!K1191 -> 1.3 | F25: 113 | G25: =(C24*D25) -> 672.75 | K25: ='入力根拠'!K1220 -> 1.3 | M25: 138 | N25: =(J24*K25) -> 448.5 | R25: ='入力根拠'!K1249 -> 1.3 | T25: 163 | U25: =(Q24*R25) -> 672.75
D26: ='入力根拠'!K1192 -> 1.3 | F26: 114 | G26: =(C24*D26) -> 672.75 | K26: ='入力根拠'!K1221 -> 1.3 | M26: 139 | N26: =(J24*K26) -> 448.5 | R26: ='入力根拠'!K1250 -> 1.3 | T26: 164 | U26: =(Q24*R26) -> 672.75
D27: ='入力根拠'!K1193 -> 1.3 | F27: 115 | G27: =(C24*D27) -> 672.75 | K27: ='入力根拠'!K1222 -> 1.3 | M27: 140 | N27: =(J24*K27) -> 448.5 | R27: ='入力根拠'!K1251 -> 1.3 | T27: 165 | U27: =(Q24*R27) -> 672.75
D28: ='入力根拠'!K1194 -> 1.3 | F28: 116 | G28: =(C24*D28) -> 672.75 | K28: ='入力根拠'!K1223 -> 1.3 | M28: 141 | N28: =(J24*K28) -> 448.5 | R28: ='入力根拠'!K1252 -> 1.3 | T28: 166 | U28: =(Q24*R28) -> 672.75
D29: ='入力根拠'!K1197 -> 1.3 | F29: 117 | G29: =(C24*D29) -> 672.75 | K29: ='入力根拠'!K1224 -> 1.3 | M29: 142 | N29: =(J24*K29) -> 448.5 | R29: ='入力根拠'!K1253 -> 1.3 | T29: 167 | U29: =(Q24*R29) -> 672.75
D30: ='入力根拠'!K1198 -> 1.3 | F30: 118 | G30: =(C24*D30) -> 672.75 | K30: ='入力根拠'!K1225 -> 1.3 | M30: 143 | N30: =(J24*K30) -> 448.5 | R30: ='入力根拠'!K1254 -> 1.3 | T30: 168 | U30: =(Q24*R30) -> 672.75
D31: ='入力根拠'!K1199 -> 1.3 | F31: 119 | G31: =(C24*D31) -> 672.75 | K31: ='入力根拠'!K1226 -> 1.3 | M31: 144 | N31: =(J24*K31) -> 448.5 | R31: ='入力根拠'!K1255 -> 1.3 | T31: 169 | U31: =(Q24*R31) -> 672.75
D32: ='入力根拠'!K1200 -> 1.3 | F32: 120 | G32: =(C24*D32) -> 672.75 | K32: ='入力根拠'!K1227 -> 1.3 | M32: 145 | N32: =(J24*K32) -> 448.5 | R32: ='入力根拠'!K1256 -> 1.3 | T32: 170 | U32: =(Q24*R32) -> 672.75
D33: ='入力根拠'!K1201 -> 1.2 | E33: ='入力根拠'!G1296 -> 0.45 | F33: 121 | G33: =SUM((C24*E33),(C34*E34)) -> 232.875 | K33: ='入力根拠'!K1228 -> 1.2 | L33: ='入力根拠'!G1333 -> 0.45 | M33: 146 | N33: =SUM((J24*L33),(J34*L34)) -> 155.25 | R33: ='入力根拠'!K1257 -> 1.2 | S33: ='入力根拠'!G1370 -> 0.45 | T33: 171 | U33: =SUM((Q24*S33),(Q34*S34)) -> 232.875
B34: ='入力根拠'!G1150 -> 1.3 | C34: ='入力根拠'!I1150 -> 0 | E34: ='入力根拠'!G1297 -> 0.75 | I34: ='入力根拠'!G1159 -> 1.3 | J34: ='入力根拠'!I1159 -> 0 | L34: ='入力根拠'!G1334 -> 0.75 | P34: ='入力根拠'!G1170 -> 1.3 | Q34: ='入力根拠'!I1170 -> 0 | S34: ='入力根拠'!G1371 -> 0.75
D35: ='入力根拠'!K1202 -> 0.55 | F35: 122 | G35: =(C34*D35) -> 0 | K35: ='入力根拠'!K1231 -> 0.55 | M35: 147 | N35: =(J34*K35) -> 0 | R35: ='入力根拠'!K1258 -> 0.55 | T35: 172 | U35: =(Q34*R35) -> 0
A36: Σ | B36: =SUM(B3,B5,B7,B10,B11,B14,B16,B24,B34) -> 31 | D36: =SUM(D3,D4,D6,D8,D9,D12,D13,D15,D17,D18,D19,D20,D21,D22,D23,D25,D26,D27,D28,D29,D30,D31,D32,D33,D35) -> 31 | H36: Σ | I36: =SUM(I3,I5,I7,I10,I11,I14,I16,I24,I34) -> 31 | K36: =SUM(K3,K4,K6,K8,K9,K12,K13,K15,K17,K18,K19,K20,K21,K22,K23,K25,K26,K27,K28,K29,K30,K31,K32,K33,K35) -> 31 | O36: Σ | P36: =SUM(P3,P5,P7,P10,P11,P14,P16,P24,P34) -> 31 | R36: =SUM(R3,R4,R6,R8,R9,R12,R13,R15,R17,R18,R19,R20,R21,R22,R23,R25,R26,R27,R28,R29,R30,R31,R32,R33,R35) -> 31

Sheet 杭先端ばね
A1: 杭先端のばね定数
A2: 節点番号 | B2: 杭先端の鉛直地盤ばね定数 Ktv(kN/m)
B3: 短期（第１勾配） | C3: 短期（第２勾配）
A4: 122 | B4: ='入力根拠'!F155 -> 327072 | C4: ='入力根拠'!F158 -> 88418
A5: 147 | B5: ='入力根拠'!F161 -> 218048 | C5: ='入力根拠'!F162 -> 58945
A6: 172 | B6: ='入力根拠'!F165 -> 327072 | C6: ='入力根拠'!F166 -> 88418
A9: 先端支持力
A10: 節点番号 | B10: 杭先端の鉛直地盤支持力 (kN)
B11: 降伏点 | C11: 終局点
A12: 122 | B12: ='入力根拠'!F159 -> 7167.5 | C12: ='入力根拠'!F160 -> 16724.3
A13: 147 | B13: ='入力根拠'!F163 -> 4778.4 | C13: ='入力根拠'!F164 -> 11149.5
A14: 172 | B14: ='入力根拠'!F167 -> 7167.5 | C14: ='入力根拠'!F168 -> 16724.3

Sheet 入力根拠
A1: 入力根拠
A2: 計算確認・モデル未保存 2026-09-18T00:52:32.060467+09:00
A3: 青文字：原値 黄色：変換時の実入力（固定） 数式：再計算値。条件変更時はアプリから再実行してください。
A6: 実行・ファイル情報
A7: 項目 | B7: 値
A8: 実行ID: d4dfda85a12b416abe77b212dedf7c8d
A9: アプリ: SDCConverter 1.1.0
A10: 帳票スキーマ: 1
A11: 対象モデル: C:\Users\sasai\Documents\structural-design\test\今町橋りょう4P(C方向･右押し→).ndu
A12: 状態: 計算確認・モデル未保存
A13: モデル出力: 未保存
A14: 出力予定SHA-256: 31e9e85971d07ae1a0b21273f500b0d8d039184ecf9febb6db642fbfabfbd22a
A15: JSON: 未保存
A16: Excel: 未保存
A17: バックアップ: なし
A18: 杭対応: 4:1 5:2 6:3
A19: 土圧方向: right
... A21: 実行・ファイル情報
A22: 項目 | B22: 値
A23: 水平境界: length-weighted
A24: 土圧境界: integral-average
A25: 土圧小数桁: 1
A26: 周面K小数桁: 0
A27: 周面F小数桁: 1
A28: 丸め: ROUND_HALF_UP（先端・水平単一層は原値）
A29: 入力: C:\Users\sasai\Documents\structural-design\test\今町橋りょう4P(右).sdc
A30: SHA-256: 9b9aed2461b87acb5193c8eac79cf07b6d9824bdbd80e096416e197f324f64a7
A31: 入力: C:\Users\sasai\Documents\structural-design\test\今町橋りょう4P(C方向･右押し→).ndu
A32: SHA-256: 31e9e85971d07ae1a0b21273f500b0d8d039184ecf9febb6db642fbfabfbd22a
A34: 採用したSDC原値
A35: 処理 | B35: SDC行 | C35: CSV欄 | D35: 項目 | E35: 単位 | F35: 原値 | G35: 正確な十進文字列
A36: 水平地盤ばね | B36: 174 | C36: 9 | D36: 1列目 短期(非線形) | E36: kN/m² | F36: 58812 | G36: 58812
A37: 採用したSDC原値
A38: 処理 | B38: SDC行 | C38: CSV欄 | D38: 項目 | E38: 単位 | F38: 原値 | G38: 正確な十進文字列
A39: 水平地盤ばね | B39: 175 | C39: 9 | D39: 1列目 短期(非線形) | E39: kN/m² | F39: 310863 | G39: 310863
A40: 水平地盤ばね | B40: 176 | C40: 9 | D40: 1列目 短期(非線形) | E40: kN/m² | F40: 110708 | G40: 110708
A41: 水平地盤ばね | B41: 177 | C41: 9 | D41: 1列目 短期(非線形) | E41: kN/m² | F41: 268854 | G41: 268854
A42: 水平地盤ばね | B42: 178 | C42: 9 | D42: 1列目 短期(非線形) | E42: kN/m² | F42: 428981 | G42: 428981
A43: 水平地盤ばね | B43: 179 | C43: 9 | D43: 1列目 短期(非線形) | E43: kN/m² | F43: 403280 | G43: 403280
A44: 水平地盤ばね | B44: 180 | C44: 9 | D44: 1列目 短期(非線形) | E44: kN/m² | F44: 193733 | G44: 193733
...
