Workbook

Sheet 変換結果
A1: 変換結果
A2: モデル保存と同一実行 2026-09-17T15:06:36.332488+09:00
A3: 青文字：原値 黄色：変換時の実入力（固定） 数式：再計算値。条件変更時はアプリから再実行してください。
A5: モデル: C:\Users\sasai\Documents\structural-design\snap\今町橋りょう4P(C方向･右押し→).ndu
A6: 計算対象 207件 変更 123件 追加 0件 同値 84件 保留 0件
A7: 周面の抵抗0による除外: 12節点
A9: 最終入力一覧
A10: 処理 | B10: KG | C10: 列 | D10: 対象 | E10: 番号 | F10: 支点項目 | G10: NDU行 | H10: 欄番号 | I10: 入力欄 | J10: 実入力 | K10: 単位 | L10: 結果
A11: 水平地盤ばね | B11: 4 | C11: 1 | D11: 部材 | E11: 98 | G11: 656 | H11: 2 | I11: 水平ばね | J11: 58812 | K11: kN/m² | L11: 同値
A12: 水平地盤ばね | B12: 4 | C12: 1 | D12: 部材 | E12: 99 | G12: 657 | H12: 2 | I12: 水平ばね | J12: 272086 | K12: kN/m² | L12: 変更
A13: 水平地盤ばね | B13: 4 | C13: 1 | D13: 部材 | E13: 100 | G13: 658 | H13: 2 | I13: 水平ばね | J13: 141501 | K13: kN/m² | L13: 変更
A14: 水平地盤ばね | B14: 4 | C14: 1 | D14: 部材 | E14: 101 | G14: 659 | H14: 2 | I14: 水平ばね | J14: 110708 | K14: kN/m² | L14: 変更
A15: 水平地盤ばね | B15: 4 | C15: 1 | D15: 部材 | E15: 102 | G15: 660 | H15: 2 | I15: 水平ばね | J15: 208029 | K15: kN/m² | L15: 変更
A16: 水平地盤ばね | B16: 4 | C16: 1 | D16: 部材 | E16: 103 | G16: 661 | H16: 2 | I16: 水平ばね | J16: 268854 | K16: kN/m² | L16: 同値
A17: 水平地盤ばね | B17: 4 | C17: 1 | D17: 部材 | E17: 104 | G17: 662 | H17: 2 | I17: 水平ばね | J17: 363440 | K17: kN/m² | L17: 同値
A18: 水平地盤ばね | B18: 4 | C18: 1 | D18: 部材 | E18: 105 | G18: 663 | H18: 2 | I18: 水平ばね | J18: 403280 | K18: kN/m² | L18: 同値
A19: 水平地盤ばね | B19: 4 | C19: 1 | D19: 部材 | E19: 106 | G19: 664 | H19: 2 | I19: 水平ばね | J19: 403280 | K19: kN/m² | L19: 同値
A20: 水平地盤ばね | B20: 4 | C20: 1 | D20: 部材 | E20: 107 | G20: 665 | H20: 2 | I20: 水平ばね | J20: 403280 | K20: kN/m² | L20: 同値
A21: 水平地盤ばね | B21: 4 | C21: 1 | D21: 部材 | E21: 108 | G21: 666 | H21: 2 | I21: 水平ばね | J21: 403280 | K21: kN/m² | L21: 同値
A22: 水平地盤ばね | B22: 4 | C22: 1 | D22: 部材 | E22: 109 | G22: 667 | H22: 2 | I22: 水平ばね | J22: 403280 | K22: kN/m² | L22: 同値
... A226: 有効抵抗土圧 | B226: 6 | C226: 3 | D226: 部材 | E226: 171 | G226: 729 | H226: 4 | I226: 下端土圧 | J226: 3088.8 | K226: kN/m | L226: 同値
A227: 杭周面ばね | B227: 4 | C227: 1 | D227: 節点 | E227: 102 | F227: 61 | G227: 1416 | H227: 4 | I227: K1+ | J227: 51629 | K227: kN/m | L227: 変更
A228: 杭周面ばね | B228: 4 | C228: 1 | D228: 節点 | E228: 102 | F228: 61 | G228: 1416 | H228: 5 | I228: F1+ | J228: 433.8 | K228: kN | L228: 変更
A229: 杭周面ばね | B229: 4 | C229: 1 | D229: 節点 | E229: 102 | F229: 61 | G229: 1416 | H229: 6 | I229: F1- | J229: 433.8 | K229: kN | L229: 変更
A230: 杭周面ばね | B230: 4 | C230: 1 | D230: 節点 | E230: 102 | F230: 61 | G230: 1416 | H230: 7 | I230: K2+ | J230: 51629 | K230: kN/m | L230: 変更
A231: 杭周面ばね | B231: 4 | C231: 1 | D231: 節点 | E231: 102 | F231: 61 | G231: 1416 | H231: 8 | I231: F2+ | J231: 433.8 | K231: kN | L231: 変更
A232: 杭周面ばね | B232: 4 | C232: 1 | D232: 節点 | E232: 102 | F232: 61 | G232: 1416 | H232: 9 | I232: F2- | J232: 433.8 | K232: kN | L232: 変更
A233: 杭周面ばね | B233: 4 | C233: 1 | D233: 節点 | E233: 102 | F233: 61 | G233: 1416 | H233: 10 | I233: K3+ | J233: 51629 | K233: kN/m | L233: 変更
A234: 杭周面ばね | B234: 4 | C234: 1 | D234: 節点 | E234: 102 | F234: 61 | G234: 1416 | H234: 11 | I234: K1- | J234: 51629 | K234: kN/m | L234: 変更
A235: 杭周面ばね | B235: 4 | C235: 1 | D235: 節点 | E235: 102 | F235: 61 | G235: 1416 | H235: 12 | I235: K2- | J235: 51629 | K235: kN/m | L235: 変更
A236: 杭周面ばね | B236: 4 | C236: 1 | D236: 節点 | E236: 102 | F236: 61 | G236: 1416 | H236: 13 | I236: K3- | J236: 51629 | K236: kN/m | L236: 変更
A237: 杭周面ばね | B237: 4 | C237: 1 | D237: 節点 | E237: 103 | F237: 62 | G237: 1417 | H237: 4 | I237: K1+ | J237: 145626 | K237: kN/m | L237: 変更
A238: 杭周面ばね | B238: 4 | C238: 1 | D238: 節点 | E238: 103 | F238: 62 | G238: 1417 | H238: 5 | I238: F1+ | J238: 1835 | K238: kN | L238: 変更
... A828: 杭先端ばね | B828: 4 | C828: 1 | D828: 節点 | E828: 122 | F828: 124 | G828: 1479 | H828: 5 | I828: F1+ | J828: 7167.5 | K828: kN | L828: 同値
A829: 杭先端ばね | B829: 4 | C829: 1 | D829: 節点 | E829: 122 | F829: 124 | G829: 1479 | H829: 6 | I829: F1- | K829: kN | L829: 同値
A830: 杭先端ばね | B830: 4 | C830: 1 | D830: 節点 | E830: 122 | F830: 124 | G830: 1479 | H830: 7 | I830: K2+ | J830: 88418 | K830: kN/m | L830: 同値
A831: 杭先端ばね | B831: 4 | C831: 1 | D831: 節点 | E831: 122 | F831: 124 | G831: 1479 | H831: 8 | I831: F2+ | J831: 16724.3 | K831: kN | L831: 同値
A832: 杭先端ばね | B832: 4 | C832: 1 | D832: 節点 | E832: 122 | F832: 124 | G832: 1479 | H832: 9 | I832: F2- | K832: kN | L832: 同値
A833: 杭先端ばね | B833: 4 | C833: 1 | D833: 節点 | E833: 122 | F833: 124 | G833: 1479 | H833: 10 | I833: K3+ | J833: 88418 | K833: kN/m | L833: 同値
A834: 杭先端ばね | B834: 4 | C834: 1 | D834: 節点 | E834: 122 | F834: 124 | G834: 1479 | H834: 11 | I834: K1- | J834: 327072 | K834: kN/m | L834: 同値
...

Sheet 水平地盤ばね
A1: 水平地盤ばね
A2: モデル保存と同一実行 2026-09-17T15:06:36.332488+09:00
A3: 青文字：原値 黄色：変換時の実入力（固定） 数式：再計算値。条件変更時はアプリから再実行してください。
A6: 部材別の結果
A7: KG | B7: 列 | C7: 部材 | D7: 方法 | E7: 丸め前 | F7: 再計算値 (kN/m²) | G7: 実入力 (kN/m²) | H7: 差
A8: 4 | B8: 1 | C8: 98 | D8: 単一層転記 | E8: =(SUM(K158)/H83) -> 58812 | F8: =J158 -> 58812 | G8: 58812 | H8: =(F8-G8) -> 0
A9: 4 | B9: 1 | C9: 99 | D9: 長さ加重平均 | E9: =(SUM(K159,K160)/H84) -> 272085.92 | F9: =ROUND(E9,0) -> 272086 | G9: 272086 | H9: =(F9-G9) -> 0
A10: 4 | B10: 1 | C10: 100 | D10: 長さ加重平均 | E10: =(SUM(K161,K162)/H85) -> 141501.08 | F10: =ROUND(E10,0) -> 141501 | G10: 141501 | H10: =(F10-G10) -> 0
A11: 4 | B11: 1 | C11: 101 | D11: 単一層転記 | E11: =(SUM(K163)/H86) -> 110708 | F11: =J163 -> 110708 | G11: 110708 | H11: =(F11-G11) -> 0
A12: 4 | B12: 1 | C12: 102 | D12: 長さ加重平均 | E12: =(SUM(K164,K165)/H87) -> 208028.62 | F12: =ROUND(E12,0) -> 208029 | G12: 208029 | H12: =(F12-G12) -> 0
A13: 4 | B13: 1 | C13: 103 | D13: 単一層転記 | E13: =(SUM(K166)/H88) -> 268854 | F13: =J166 -> 268854 | G13: 268854 | H13: =(F13-G13) -> 0
A14: 4 | B14: 1 | C14: 104 | D14: 長さ加重平均 | E14: =(SUM(K167,K168,K169)/H89) -> 363439.69 | F14: =ROUND(E14,0) -> 363440 | G14: 363440 | H14: =(F14-G14) -> 0
A15: 4 | B15: 1 | C15: 105 | D15: 単一層転記 | E15: =(SUM(K170)/H90) -> 403280 | F15: =J170 -> 403280 | G15: 403280 | H15: =(F15-G15) -> 0
A16: 4 | B16: 1 | C16: 106 | D16: 単一層転記 | E16: =(SUM(K171)/H91) -> 403280 | F16: =J171 -> 403280 | G16: 403280 | H16: =(F16-G16) -> 0
A17: 4 | B17: 1 | C17: 107 | D17: 単一層転記 | E17: =(SUM(K172)/H92) -> 403280 | F17: =J172 -> 403280 | G17: 403280 | H17: =(F17-G17) -> 0
A18: 4 | B18: 1 | C18: 108 | D18: 単一層転記 | E18: =(SUM(K173)/H93) -> 403280 | F18: =J173 -> 403280 | G18: 403280 | H18: =(F18-G18) -> 0
A19: 4 | B19: 1 | C19: 109 | D19: 単一層転記 | E19: =(SUM(K174)/H94) -> 403280 | F19: =J174 -> 403280 | G19: 403280 | H19: =(F19-G19) -> 0
A20: 4 | B20: 1 | C20: 110 | D20: 単一層転記 | E20: =(SUM(K175)/H95) -> 403280 | F20: =J175 -> 403280 | G20: 403280 | H20: =(F20-G20) -> 0
A21: 4 | B21: 1 | C21: 111 | D21: 単一層転記 | E21: =(SUM(K176)/H96) -> 403280 | F21: =J176 -> 403280 | G21: 403280 | H21: =(F21-G21) -> 0
A22: 4 | B22: 1 | C22: 112 | D22: 長さ加重平均 | E22: =(SUM(K177,K178)/H97) -> 225971 | F22: =ROUND(E22,0) -> 225971 | G22: 225971 | H22: =(F22-G22) -> 0
A23: 4 | B23: 1 | C23: 113 | D23: 単一層転記 | E23: =(SUM(K179)/H98) -> 193733 | F23: =J179 -> 193733 | G23: 193733 | H23: =(F23-G23) -> 0
A24: 4 | B24: 1 | C24: 114 | D24: 単一層転記 | E24: =(SUM(K180)/H99) -> 193733 | F24: =J180 -> 193733 | G24: 193733 | H24: =(F24-G24) -> 0
A25: 4 | B25: 1 | C25: 115 | D25: 単一層転記 | E25: =(SUM(K181)/H100) -> 193733 | F25: =J181 -> 193733 | G25: 193733 | H25: =(F25-G25) -> 0
A26: 4 | B26: 1 | C26: 116 | D26: 単一層転記 | E26: =(SUM(K182)/H101) -> 193733 | F26: =J182 -> 193733 | G26: 193733 | H26: =(F26-G26) -> 0
A27: 4 | B27: 1 | C27: 117 | D27: 単一層転記 | E27: =(SUM(K183)/H102) -> 193733 | F27: =J183 -> 193733 | G27: 193733 | H27: =(F27-G27) -> 0
A28: 4 | B28: 1 | C28: 118 | D28: 単一層転記 | E28: =(SUM(K184)/H103) -> 193733 | F28: =J184 -> 193733 | G28: 193733 | H28: =(F28-G28) -> 0
A29: 4 | B29: 1 | C29: 119 | D29: 単一層転記 | E29: =(SUM(K185)/H104) -> 193733 | F29: =J185 -> 193733 | G29: 193733 | H29: =(F29-G29) -> 0
A30: 4 | B30: 1 | C30: 120 | D30: 単一層転記 | E30: =(SUM(K186)/H105) -> 193733 | F30: =J186 -> 193733 | G30: 193733 | H30: =(F30-G30) -> 0
A31: 4 | B31: 1 | C31: 121 | D31: 単一層転記 | E31: =(SUM(K187)/H106) -> 193733 | F31: =J187 -> 193733 | G31: 193733 | H31: =(F31-G31) -> 0
A32: 5 | B32: 2 | C32: 123 | D32: 単一層転記 | E32: =(SUM(K188)/H107) -> 39208 | F32: =J188 -> 39208 | G32: 39208 | H32: =(F32-G32) -> 0
A33: 5 | B33: 2 | C33: 124 | D33: 長さ加重平均 | E33: =(SUM(K189,K190)/H108) -> 181390.62 | F33: =ROUND(E33,0) -> 181391 | G33: 181391 | H33: =(F33-G33) -> 0
A34: 5 | B34: 2 | C34: 125 | D34: 長さ加重平均 | E34: =(SUM(K191,K192)/H109) -> 94333.769 | F34: =ROUND(E34,0) -> 94334 | G34: 94334 | H34: =(F34-G34) -> 0
A35: 5 | B35: 2 | C35: 126 | D35: 単一層転記 | E35: =(SUM(K193)/H110) -> 73805 | F35: =J193 -> 73805 | G35: 73805 | H35: =(F35-G35) -> 0
A36: 5 | B36: 2 | C36: 127 | D36: 長さ加重平均 | E36: =(SUM(K194,K195)/H111) -> 138685.62 | F36: =ROUND(E36,0) -> 138686 | G36: 138686 | H36: =(F36-G36) -> 0
A37: 5 | B37: 2 | C37: 128 | D37: 単一層転記 | E37: =(SUM(K196)/H112) -> 179236 | F37: =J196 -> 179236 | G37: 179236 | H37: =(F37-G37) -> 0
A38: 5 | B38: 2 | C38: 129 | D38: 長さ加重平均 | E38: =(SUM(K197,K198,K199)/H113) -> 242293.08 | F38: =ROUND(E38,0) -> 242293 | G38: 242293 | H38: =(F38-G38) -> 0
A39: 5 | B39: 2 | C39: 130 | D39: 単一層転記 | E39: =(SUM(K200)/H114) -> 268854 | F39: =J200 -> 268854 | G39: 268854 | H39: =(F39-G39) -> 0
A40: 5 | B40: 2 | C40: 131 | D40: 単一層転記 | E40: =(SUM(K201)/H115) -> 268854 | F40: =J201 -> 268854 | G40: 268854 | H40: =(F40-G40) -> 0
A41: 5 | B41: 2 | C41: 132 | D41: 単一層転記 | E41: =(SUM(K202)/H116) -> 268854 | F41: =J202 -> 268854 | G41: 268854 | H41: =(F41-G41) -> 0
A42: 5 | B42: 2 | C42: 133 | D42: 単一層転記 | E42: =(SUM(K203)/H117) -> 268854 | F42: =J203 -> 268854 | G42: 268854 | H42: =(F42-G42) -> 0
...

Sheet 有効抵抗土圧
A1: 有効抵抗土圧
A2: モデル保存と同一実行 2026-09-17T15:06:36.332488+09:00
A3: 青文字：原値 黄色：変換時の実入力（固定） 数式：再計算値。条件変更時はアプリから再実行してください。
A6: 部材別の結果
A7: KG | B7: モデル列 | C7: 部材 | D7: 方法 | E7: 土圧列 | F7: 上端再計算 (kN/m) | G7: 上端実入力 (kN/m) | H7: 上端差 | I7: 下端再計算 (kN/m) | J7: 下端実入力 (kN/m) | K7: 下端差
A8: 4 | B8: 1 | C8: 98 | D8: 層内線形補間 | E8: 3 | F8: =ROUND(F251,1) -> 1162.9 | G8: 1162.9 | H8: =(F8-G8) -> 0 | I8: =ROUND(G251,1) -> 1307.5 | J8: 1307.5 | K8: =(I8-J8) -> 0
A9: 4 | B9: 1 | C9: 99 | D9: 積分平均 | E9: 3 | F9: =ROUND((SUM(I252,I253)/H84),1) -> 1989 | G9: 1989 | H9: =(F9-G9) -> 0 | I9: =ROUND((SUM(I252,I253)/H84),1) -> 1989 | J9: 1989 | K9: =(I9-J9) -> 0
A10: 4 | B10: 1 | C10: 100 | D10: 積分平均 | E10: 3 | F10: =ROUND((SUM(I254,I255)/H85),1) -> 1826.6 | G10: 1826.6 | H10: =(F10-G10) -> 0 | I10: =ROUND((SUM(I254,I255)/H85),1) -> 1826.6 | J10: 1826.6 | K10: =(I10-J10) -> 0
A11: 4 | B11: 1 | C11: 101 | D11: 層内線形補間 | E11: 3 | F11: =ROUND(F256,1) -> 1755 | G11: 1755 | H11: =(F11-G11) -> 0 | I11: =ROUND(G256,1) -> 1755 | J11: 1755 | K11: =(I11-J11) -> 0
A12: 4 | B12: 1 | C12: 102 | D12: 積分平均 | E12: 3 | F12: =ROUND((SUM(I257,I258)/H87),1) -> 2158.6 | G12: 2158.6 | H12: =(F12-G12) -> 0 | I12: =ROUND((SUM(I257,I258)/H87),1) -> 2158.6 | J12: 2158.6 | K12: =(I12-J12) -> 0
A13: 4 | B13: 1 | C13: 103 | D13: 層内線形補間 | E13: 3 | F13: =ROUND(F259,1) -> 2472.8 | G13: 2472.8 | H13: =(F13-G13) -> 0 | I13: =ROUND(G259,1) -> 2673.7 | J13: 2673.7 | K13: =(I13-J13) -> 0
A14: 4 | B14: 1 | C14: 104 | D14: 積分平均 | E14: 3 | F14: =ROUND((SUM(I260,I261,I262)/H89),1) -> 4642.1 | G14: 4642.1 | H14: =(F14-G14) -> 0 | I14: =ROUND((SUM(I260,I261,I262)/H89),1) -> 4642.1 | J14: 4642.1 | K14: =(I14-J14) -> 0
A15: 4 | B15: 1 | C15: 105 | D15: 層内線形補間 | E15: 3 | F15: =ROUND(F263,1) -> 2980.8 | G15: 2980.8 | H15: =(F15-G15) -> 0 | I15: =ROUND(G263,1) -> 3190.7 | J15: 3190.7 | K15: =(I15-J15) -> 0
A16: 4 | B16: 1 | C16: 106 | D16: 層内線形補間 | E16: 3 | F16: =ROUND(F264,1) -> 3190.7 | G16: 3190.7 | H16: =(F16-G16) -> 0 | I16: =ROUND(G264,1) -> 3400.6 | J16: 3400.6 | K16: =(I16-J16) -> 0
A17: 4 | B17: 1 | C17: 107 | D17: 層内線形補間 | E17: 3 | F17: =ROUND(F265,1) -> 3400.6 | G17: 3400.6 | H17: =(F17-G17) -> 0 | I17: =ROUND(G265,1) -> 3610.5 | J17: 3610.5 | K17: =(I17-J17) -> 0
A18: 4 | B18: 1 | C18: 108 | D18: 層内線形補間 | E18: 3 | F18: =ROUND(F266,1) -> 3610.5 | G18: 3610.5 | H18: =(F18-G18) -> 0 | I18: =ROUND(G266,1) -> 3820.5 | J18: 3820.5 | K18: =(I18-J18) -> 0
A19: 4 | B19: 1 | C19: 109 | D19: 層内線形補間 | E19: 3 | F19: =ROUND(F267,1) -> 3820.5 | G19: 3820.5 | H19: =(F19-G19) -> 0 | I19: =ROUND(G267,1) -> 4030.4 | J19: 4030.4 | K19: =(I19-J19) -> 0
A20: 4 | B20: 1 | C20: 110 | D20: 層内線形補間 | E20: 3 | F20: =ROUND(F268,1) -> 4030.4 | G20: 4030.4 | H20: =(F20-G20) -> 0 | I20: =ROUND(G268,1) -> 4240.3 | J20: 4240.3 | K20: =(I20-J20) -> 0
A21: 4 | B21: 1 | C21: 111 | D21: 層内線形補間 | E21: 3 | F21: =ROUND(F269,1) -> 4240.3 | G21: 4240.3 | H21: =(F21-G21) -> 0 | I21: =ROUND(G269,1) -> 4450.2 | J21: 4450.2 | K21: =(I21-J21) -> 0
A22: 4 | B22: 1 | C22: 112 | D22: 積分平均 | E22: 3 | F22: =ROUND((SUM(I270,I271)/H97),1) -> 3300.7 | G22: 3300.7 | H22: =(F22-G22) -> 0 | I22: =ROUND((SUM(I270,I271)/H97),1) -> 3300.7 | J22: 3300.7 | K22: =(I22-J22) -> 0
A23: 4 | B23: 1 | C23: 113 | D23: 層内線形補間 | E23: 3 | F23: =ROUND(F272,1) -> 3088.8 | G23: 3088.8 | H23: =(F23-G23) -> 0 | I23: =ROUND(G272,1) -> 3088.8 | J23: 3088.8 | K23: =(I23-J23) -> 0
A24: 4 | B24: 1 | C24: 114 | D24: 層内線形補間 | E24: 3 | F24: =ROUND(F273,1) -> 3088.8 | G24: 3088.8 | H24: =(F24-G24) -> 0 | I24: =ROUND(G273,1) -> 3088.8 | J24: 3088.8 | K24: =(I24-J24) -> 0
A25: 4 | B25: 1 | C25: 115 | D25: 層内線形補間 | E25: 3 | F25: =ROUND(F274,1) -> 3088.8 | G25: 3088.8 | H25: =(F25-G25) -> 0 | I25: =ROUND(G274,1) -> 3088.8 | J25: 3088.8 | K25: =(I25-J25) -> 0
A26: 4 | B26: 1 | C26: 116 | D26: 層内線形補間 | E26: 3 | F26: =ROUND(F275,1) -> 3088.8 | G26: 3088.8 | H26: =(F26-G26) -> 0 | I26: =ROUND(G275,1) -> 3088.8 | J26: 3088.8 | K26: =(I26-J26) -> 0
A27: 4 | B27: 1 | C27: 117 | D27: 層内線形補間 | E27: 3 | F27: =ROUND(F276,1) -> 3088.8 | G27: 3088.8 | H27: =(F27-G27) -> 0 | I27: =ROUND(G276,1) -> 3088.8 | J27: 3088.8 | K27: =(I27-J27) -> 0
A28: 4 | B28: 1 | C28: 118 | D28: 層内線形補間 | E28: 3 | F28: =ROUND(F277,1) -> 3088.8 | G28: 3088.8 | H28: =(F28-G28) -> 0 | I28: =ROUND(G277,1) -> 3088.8 | J28: 3088.8 | K28: =(I28-J28) -> 0
A29: 4 | B29: 1 | C29: 119 | D29: 層内線形補間 | E29: 3 | F29: =ROUND(F278,1) -> 3088.8 | G29: 3088.8 | H29: =(F29-G29) -> 0 | I29: =ROUND(G278,1) -> 3088.8 | J29: 3088.8 | K29: =(I29-J29) -> 0
A30: 4 | B30: 1 | C30: 120 | D30: 層内線形補間 | E30: 3 | F30: =ROUND(F279,1) -> 3088.8 | G30: 3088.8 | H30: =(F30-G30) -> 0 | I30: =ROUND(G279,1) -> 3088.8 | J30: 3088.8 | K30: =(I30-J30) -> 0
A31: 4 | B31: 1 | C31: 121 | D31: 層内線形補間 | E31: 3 | F31: =ROUND(F280,1) -> 3088.8 | G31: 3088.8 | H31: =(F31-G31) -> 0 | I31: =ROUND(G280,1) -> 3088.8 | J31: 3088.8 | K31: =(I31-J31) -> 0
A32: 5 | B32: 2 | C32: 123 | D32: 層内線形補間 | E32: 2 | F32: =ROUND(F281,1) -> 1005.1 | G32: 1005.1 | H32: =(F32-G32) -> 0 | I32: =ROUND(G281,1) -> 1130.1 | J32: 1130.1 | K32: =(I32-J32) -> 0
A33: 5 | B33: 2 | C33: 124 | D33: 積分平均 | E33: 2 | F33: =ROUND((SUM(I282,I283)/H108),1) -> 1719.1 | G33: 1719.1 | H33: =(F33-G33) -> 0 | I33: =ROUND((SUM(I282,I283)/H108),1) -> 1719.1 | J33: 1719.1 | K33: =(I33-J33) -> 0
A34: 5 | B34: 2 | C34: 125 | D34: 積分平均 | E34: 2 | F34: =ROUND((SUM(I284,I285)/H109),1) -> 1285.3 | G34: 1285.3 | H34: =(F34-G34) -> 0 | I34: =ROUND((SUM(I284,I285)/H109),1) -> 1285.3 | J34: 1285.3 | K34: =(I34-J34) -> 0
A35: 5 | B35: 2 | C35: 126 | D35: 層内線形補間 | E35: 2 | F35: =ROUND(F286,1) -> 1170 | G35: 1170 | H35: =(F35-G35) -> 0 | I35: =ROUND(G286,1) -> 1170 | J35: 1170 | K35: =(I35-J35) -> 0
A36: 5 | B36: 2 | C36: 127 | D36: 積分平均 | E36: 2 | F36: =ROUND((SUM(I287,I288)/H111),1) -> 1732.3 | G36: 1732.3 | H36: =(F36-G36) -> 0 | I36: =ROUND((SUM(I287,I288)/H111),1) -> 1732.3 | J36: 1732.3 | K36: =(I36-J36) -> 0
A37: 5 | B37: 2 | C37: 128 | D37: 層内線形補間 | E37: 2 | F37: =ROUND(F289,1) -> 2137.2 | G37: 2137.2 | H37: =(F37-G37) -> 0 | I37: =ROUND(G289,1) -> 2310.9 | J37: 2310.9 | K37: =(I37-J37) -> 0
A38: 5 | B38: 2 | C38: 129 | D38: 積分平均 | E38: 2 | F38: =ROUND((SUM(I290,I291,I292)/H113),1) -> 3391.1 | G38: 3391.1 | H38: =(F38-G38) -> 0 | I38: =ROUND((SUM(I290,I291,I292)/H113),1) -> 3391.1 | J38: 3391.1 | K38: =(I38-J38) -> 0
A39: 5 | B39: 2 | C39: 130 | D39: 層内線形補間 | E39: 2 | F39: =ROUND(F293,1) -> 2576.3 | G39: 2576.3 | H39: =(F39-G39) -> 0 | I39: =ROUND(G293,1) -> 2757.7 | J39: 2757.7 | K39: =(I39-J39) -> 0
A40: 5 | B40: 2 | C40: 131 | D40: 層内線形補間 | E40: 2 | F40: =ROUND(F294,1) -> 2757.7 | G40: 2757.7 | H40: =(F40-G40) -> 0 | I40: =ROUND(G294,1) -> 2939.2 | J40: 2939.2 | K40: =(I40-J40) -> 0
A41: 5 | B41: 2 | C41: 132 | D41: 層内線形補間 | E41: 2 | F41: =ROUND(F295,1) -> 2939.2 | G41: 2939.2 | H41: =(F41-G41) -> 0 | I41: =ROUND(G295,1) -> 3120.6 | J41: 3120.6 | K41: =(I41-J41) -> 0
A42: 5 | B42: 2 | C42: 133 | D42: 層内線形補間 | E42: 2 | F42: =ROUND(F296,1) -> 3120.6 | G42: 3120.6 | H42: =(F42-G42) -> 0 | I42: =ROUND(G296,1) -> 3302 | J42: 3302 | K42: =(I42-J42) -> 0
...

Sheet 杭周面ばね
A1: 杭周面ばね
A2: モデル保存と同一実行 2026-09-17T15:06:36.332488+09:00
A3: 青文字：原値 黄色：変換時の実入力（固定） 数式：再計算値。条件変更時はアプリから再実行してください。
A5: 既存画面方式：押込みK1/Fyを正負へ配置。長さ積分後に丸め、平均の除算・1.2補正・本数の追加乗算はしません。
A7: 節点別の結果
A8: KG | B8: 列 | C8: 節点 | D8: 有効長 (m) | E8: K丸め前 (kN/m) | F8: K再計算 (kN/m) | G8: K実入力 (kN/m) | H8: K差 | I8: F丸め前 (kN) | J8: F再計算 (kN) | K8: F実入力 (kN) | L8: F差
A9: 4 | B9: 1 | C9: 102 | D9: =SUM(K139,K140) -> 0.905 | E9: =SUM(I214,I215) -> 51628.885 | F9: =ROUND(E9,0) -> 51629 | G9: 51629 | H9: =(F9-G9) -> 0 | I9: =SUM(J214,J215) -> 433.7705 | J9: =ROUND(I9,1) -> 433.8 | K9: 433.8 | L9: =(J9-K9) -> 0
A10: 4 | B10: 1 | C10: 103 | D10: =SUM(K141) -> 1.3 | E10: =SUM(I216) -> 145626 | F10: =ROUND(E10,0) -> 145626 | G10: 145626 | H10: =(F10-G10) -> 0 | I10: =SUM(J216) -> 1834.95 | J10: =ROUND(I10,1) -> 1835 | K10: 1835 | L10: =(J10-K10) -> 0
A11: 4 | B11: 1 | C11: 104 | D11: =SUM(K142,K143) -> 1.3 | E11: =SUM(I217,I218) -> 155633.7 | F11: =ROUND(E11,0) -> 155634 | G11: 155634 | H11: =(F11-G11) -> 0 | I11: =SUM(J217,J218) -> 1794.36 | J11: =ROUND(I11,1) -> 1794.4 | K11: 1794.4 | L11: =(J11-K11) -> 0
A12: 4 | B12: 1 | C12: 105 | D12: =SUM(K144,K145) -> 1.3 | E12: =SUM(I219,I220) -> 223256.75 | F12: =ROUND(E12,0) -> 223257 | G12: 223257 | H12: =(F12-G12) -> 0 | I12: =SUM(J219,J220) -> 2313.025 | J12: =ROUND(I12,1) -> 2313 | K12: 2313 | L12: =(J12-K12) -> 0
A13: 4 | B13: 1 | C13: 106 | D13: =SUM(K146) -> 1.3 | E13: =SUM(I221) -> 218437.7 | F13: =ROUND(E13,0) -> 218438 | G13: 218438 | H13: =(F13-G13) -> 0 | I13: =SUM(J221) -> 2752.36 | J13: =ROUND(I13,1) -> 2752.4 | K13: 2752.4 | L13: =(J13-K13) -> 0
A14: 4 | B14: 1 | C14: 107 | D14: =SUM(K147) -> 1.3 | E14: =SUM(I222) -> 218437.7 | F14: =ROUND(E14,0) -> 218438 | G14: 218438 | H14: =(F14-G14) -> 0 | I14: =SUM(J222) -> 2752.36 | J14: =ROUND(I14,1) -> 2752.4 | K14: 2752.4 | L14: =(J14-K14) -> 0
A15: 4 | B15: 1 | C15: 108 | D15: =SUM(K148) -> 1.3 | E15: =SUM(I223) -> 218437.7 | F15: =ROUND(E15,0) -> 218438 | G15: 218438 | H15: =(F15-G15) -> 0 | I15: =SUM(J223) -> 2752.36 | J15: =ROUND(I15,1) -> 2752.4 | K15: 2752.4 | L15: =(J15-K15) -> 0
A16: 4 | B16: 1 | C16: 109 | D16: =SUM(K149) -> 1.3 | E16: =SUM(I224) -> 218437.7 | F16: =ROUND(E16,0) -> 218438 | G16: 218438 | H16: =(F16-G16) -> 0 | I16: =SUM(J224) -> 2752.36 | J16: =ROUND(I16,1) -> 2752.4 | K16: 2752.4 | L16: =(J16-K16) -> 0
A17: 4 | B17: 1 | C17: 110 | D17: =SUM(K150) -> 1.3 | E17: =SUM(I225) -> 218437.7 | F17: =ROUND(E17,0) -> 218438 | G17: 218438 | H17: =(F17-G17) -> 0 | I17: =SUM(J225) -> 2752.36 | J17: =ROUND(I17,1) -> 2752.4 | K17: 2752.4 | L17: =(J17-K17) -> 0
A18: 4 | B18: 1 | C18: 111 | D18: =SUM(K151) -> 1.3 | E18: =SUM(I226) -> 218437.7 | F18: =ROUND(E18,0) -> 218438 | G18: 218438 | H18: =(F18-G18) -> 0 | I18: =SUM(J226) -> 2752.36 | J18: =ROUND(I18,1) -> 2752.4 | K18: 2752.4 | L18: =(J18-K18) -> 0
A19: 4 | B19: 1 | C19: 112 | D19: =SUM(K152,K153) -> 1.3 | E19: =SUM(I227,I228) -> 179148.65 | F19: =ROUND(E19,0) -> 179149 | G19: 179149 | H19: =(F19-G19) -> 0 | I19: =SUM(J227,J228) -> 2032.495 | J19: =ROUND(I19,1) -> 2032.5 | K19: 2032.5 | L19: =(J19-K19) -> 0
A20: 4 | B20: 1 | C20: 113 | D20: =SUM(K154) -> 1.3 | E20: =SUM(I229) -> 104936 | F20: =ROUND(E20,0) -> 104936 | G20: 104936 | H20: =(F20-G20) -> 0 | I20: =SUM(J229) -> 672.75 | J20: =ROUND(I20,1) -> 672.8 | K20: 672.8 | L20: =(J20-K20) -> 0
A21: 4 | B21: 1 | C21: 114 | D21: =SUM(K155) -> 1.3 | E21: =SUM(I230) -> 104936 | F21: =ROUND(E21,0) -> 104936 | G21: 104936 | H21: =(F21-G21) -> 0 | I21: =SUM(J230) -> 672.75 | J21: =ROUND(I21,1) -> 672.8 | K21: 672.8 | L21: =(J21-K21) -> 0
A22: 4 | B22: 1 | C22: 115 | D22: =SUM(K156) -> 1.3 | E22: =SUM(I231) -> 104936 | F22: =ROUND(E22,0) -> 104936 | G22: 104936 | H22: =(F22-G22) -> 0 | I22: =SUM(J231) -> 672.75 | J22: =ROUND(I22,1) -> 672.8 | K22: 672.8 | L22: =(J22-K22) -> 0
A23: 4 | B23: 1 | C23: 116 | D23: =SUM(K157) -> 1.3 | E23: =SUM(I232) -> 104936 | F23: =ROUND(E23,0) -> 104936 | G23: 104936 | H23: =(F23-G23) -> 0 | I23: =SUM(J232) -> 672.75 | J23: =ROUND(I23,1) -> 672.8 | K23: 672.8 | L23: =(J23-K23) -> 0
A24: 4 | B24: 1 | C24: 117 | D24: =SUM(K158) -> 1.3 | E24: =SUM(I233) -> 104936 | F24: =ROUND(E24,0) -> 104936 | G24: 104936 | H24: =(F24-G24) -> 0 | I24: =SUM(J233) -> 672.75 | J24: =ROUND(I24,1) -> 672.8 | K24: 672.8 | L24: =(J24-K24) -> 0
A25: 4 | B25: 1 | C25: 118 | D25: =SUM(K159) -> 1.3 | E25: =SUM(I234) -> 104936 | F25: =ROUND(E25,0) -> 104936 | G25: 104936 | H25: =(F25-G25) -> 0 | I25: =SUM(J234) -> 672.75 | J25: =ROUND(I25,1) -> 672.8 | K25: 672.8 | L25: =(J25-K25) -> 0
A26: 4 | B26: 1 | C26: 119 | D26: =SUM(K160) -> 1.3 | E26: =SUM(I235) -> 104936 | F26: =ROUND(E26,0) -> 104936 | G26: 104936 | H26: =(F26-G26) -> 0 | I26: =SUM(J235) -> 672.75 | J26: =ROUND(I26,1) -> 672.8 | K26: 672.8 | L26: =(J26-K26) -> 0
A27: 4 | B27: 1 | C27: 120 | D27: =SUM(K161) -> 1.3 | E27: =SUM(I236) -> 104936 | F27: =ROUND(E27,0) -> 104936 | G27: 104936 | H27: =(F27-G27) -> 0 | I27: =SUM(J236) -> 672.75 | J27: =ROUND(I27,1) -> 672.8 | K27: 672.8 | L27: =(J27-K27) -> 0
A28: 4 | B28: 1 | C28: 121 | D28: =SUM(K162) -> 0.45 | E28: =SUM(I237) -> 36324 | F28: =ROUND(E28,0) -> 36324 | G28: 36324 | H28: =(F28-G28) -> 0 | I28: =SUM(J237) -> 232.875 | J28: =ROUND(I28,1) -> 232.9 | K28: 232.9 | L28: =(J28-K28) -> 0
A29: 5 | B29: 2 | C29: 127 | D29: =SUM(K163,K164) -> 0.905 | E29: =SUM(I238,I239) -> 34419.005 | F29: =ROUND(E29,0) -> 34419 | G29: 34419 | H29: =(F29-G29) -> 0 | I29: =SUM(J238,J239) -> 289.13 | J29: =ROUND(I29,1) -> 289.1 | K29: 289.1 | L29: =(J29-K29) -> 0
A30: 5 | B30: 2 | C30: 128 | D30: =SUM(K165) -> 1.3 | E30: =SUM(I240) -> 97084 | F30: =ROUND(E30,0) -> 97084 | G30: 97084 | H30: =(F30-G30) -> 0 | I30: =SUM(J240) -> 1223.3 | J30: =ROUND(I30,1) -> 1223.3 | K30: 1223.3 | L30: =(J30-K30) -> 0
A31: 5 | B31: 2 | C31: 129 | D31: =SUM(K166,K167) -> 1.3 | E31: =SUM(I241,I242) -> 103755.7 | F31: =ROUND(E31,0) -> 103756 | G31: 103756 | H31: =(F31-G31) -> 0 | I31: =SUM(J241,J242) -> 1196.24 | J31: =ROUND(I31,1) -> 1196.2 | K31: 1196.2 | L31: =(J31-K31) -> 0
A32: 5 | B32: 2 | C32: 130 | D32: =SUM(K168,K169) -> 1.3 | E32: =SUM(I243,I244) -> 148838.1 | F32: =ROUND(E32,0) -> 148838 | G32: 148838 | H32: =(F32-G32) -> 0 | I32: =SUM(J243,J244) -> 1542.045 | J32: =ROUND(I32,1) -> 1542 | K32: 1542 | L32: =(J32-K32) -> 0
A33: 5 | B33: 2 | C33: 131 | D33: =SUM(K170) -> 1.3 | E33: =SUM(I245) -> 145626 | F33: =ROUND(E33,0) -> 145626 | G33: 145626 | H33: =(F33-G33) -> 0 | I33: =SUM(J245) -> 1834.95 | J33: =ROUND(I33,1) -> 1835 | K33: 1835 | L33: =(J33-K33) -> 0
A34: 5 | B34: 2 | C34: 132 | D34: =SUM(K171) -> 1.3 | E34: =SUM(I246) -> 145626 | F34: =ROUND(E34,0) -> 145626 | G34: 145626 | H34: =(F34-G34) -> 0 | I34: =SUM(J246) -> 1834.95 | J34: =ROUND(I34,1) -> 1835 | K34: 1835 | L34: =(J34-K34) -> 0
A35: 5 | B35: 2 | C35: 133 | D35: =SUM(K172) -> 1.3 | E35: =SUM(I247) -> 145626 | F35: =ROUND(E35,0) -> 145626 | G35: 145626 | H35: =(F35-G35) -> 0 | I35: =SUM(J247) -> 1834.95 | J35: =ROUND(I35,1) -> 1835 | K35: 1835 | L35: =(J35-K35) -> 0
A36: 5 | B36: 2 | C36: 134 | D36: =SUM(K173) -> 1.3 | E36: =SUM(I248) -> 145626 | F36: =ROUND(E36,0) -> 145626 | G36: 145626 | H36: =(F36-G36) -> 0 | I36: =SUM(J248) -> 1834.95 | J36: =ROUND(I36,1) -> 1835 | K36: 1835 | L36: =(J36-K36) -> 0
A37: 5 | B37: 2 | C37: 135 | D37: =SUM(K174) -> 1.3 | E37: =SUM(I249) -> 145626 | F37: =ROUND(E37,0) -> 145626 | G37: 145626 | H37: =(F37-G37) -> 0 | I37: =SUM(J249) -> 1834.95 | J37: =ROUND(I37,1) -> 1835 | K37: 1835 | L37: =(J37-K37) -> 0
A38: 5 | B38: 2 | C38: 136 | D38: =SUM(K175) -> 1.3 | E38: =SUM(I250) -> 145626 | F38: =ROUND(E38,0) -> 145626 | G38: 145626 | H38: =(F38-G38) -> 0 | I38: =SUM(J250) -> 1834.95 | J38: =ROUND(I38,1) -> 1835 | K38: 1835 | L38: =(J38-K38) -> 0
A39: 5 | B39: 2 | C39: 137 | D39: =SUM(K176,K177) -> 1.3 | E39: =SUM(I251,I252) -> 119432.85 | F39: =ROUND(E39,0) -> 119433 | G39: 119433 | H39: =(F39-G39) -> 0 | I39: =SUM(J251,J252) -> 1355.025 | J39: =ROUND(I39,1) -> 1355 | K39: 1355 | L39: =(J39-K39) -> 0
A40: 5 | B40: 2 | C40: 138 | D40: =SUM(K178) -> 1.3 | E40: =SUM(I253) -> 69956.9 | F40: =ROUND(E40,0) -> 69957 | G40: 69957 | H40: =(F40-G40) -> 0 | I40: =SUM(J253) -> 448.5 | J40: =ROUND(I40,1) -> 448.5 | K40: 448.5 | L40: =(J40-K40) -> 0
A41: 5 | B41: 2 | C41: 139 | D41: =SUM(K179) -> 1.3 | E41: =SUM(I254) -> 69956.9 | F41: =ROUND(E41,0) -> 69957 | G41: 69957 | H41: =(F41-G41) -> 0 | I41: =SUM(J254) -> 448.5 | J41: =ROUND(I41,1) -> 448.5 | K41: 448.5 | L41: =(J41-K41) -> 0
A42: 5 | B42: 2 | C42: 140 | D42: =SUM(K180) -> 1.3 | E42: =SUM(I255) -> 69956.9 | F42: =ROUND(E42,0) -> 69957 | G42: 69957 | H42: =(F42-G42) -> 0 | I42: =SUM(J255) -> 448.5 | J42: =ROUND(I42,1) -> 448.5 | K42: 448.5 | L42: =(J42-K42) -> 0
...

Sheet 杭先端ばね
A1: 杭先端ばね
A2: モデル保存と同一実行 2026-09-17T15:06:36.332488+09:00
A3: 青文字：原値 黄色：変換時の実入力（固定） 数式：再計算値。条件変更時はアプリから再実行してください。
A5: SDCの短期K1/K2・押込みFy/Fuを転記。負側制限値F1−/F2−は空欄のまま転記します。
A7: 杭先端の結果
A8: KG | B8: 列 | C8: 先端節点 | D8: K1再計算 (kN/m) | E8: K1実入力 (kN/m) | F8: K2再計算 (kN/m) | G8: K2実入力 (kN/m) | H8: Fy再計算 (kN) | I8: Fy実入力 (kN) | J8: Fu再計算 (kN) | K8: Fu実入力 (kN)
A9: 4 | B9: 1 | C9: 122 | D9: ='入力根拠'!F127 -> 327072 | E9: 327072 | F9: ='入力根拠'!F128 -> 88418 | G9: 88418 | H9: ='入力根拠'!F129 -> 7167.5 | I9: 7167.5 | J9: ='入力根拠'!F130 -> 16724.3 | K9: 16724.3
A10: 5 | B10: 2 | C10: 147 | D10: ='入力根拠'!F131 -> 218048 | E10: 218048 | F10: ='入力根拠'!F132 -> 58945 | G10: 58945 | H10: ='入力根拠'!F133 -> 4778.4 | I10: 4778.4 | J10: ='入力根拠'!F134 -> 11149.5 | K10: 11149.5
A11: 6 | B11: 3 | C11: 172 | D11: ='入力根拠'!F135 -> 327072 | E11: 327072 | F11: ='入力根拠'!F136 -> 88418 | G11: 88418 | H11: ='入力根拠'!F137 -> 7167.5 | I11: 7167.5 | J11: ='入力根拠'!F138 -> 16724.3 | K11: 16724.3
A13: 杭頭・最深節点と杭長
A14: KG | B14: 列 | C14: 杭頭節点 | D14: 先端節点 | E14: x座標 (m) | F14: 杭頭y (m) | G14: 先端y (m) | H14: 座標差 (m) | I14: SDC杭長 (m)
A15: 4 | B15: 1 | C15: 98 | D15: 122 | E15: 29.8 | F15: 13.041 | G15: 44.041 | H15: =ROUND((G15-F15),4) -> 31 | I15: 31
A16: 5 | B16: 2 | C16: 123 | D16: 147 | E16: 33.5 | F16: 13.041 | G16: 44.041 | H16: =ROUND((G16-F16),4) -> 31 | I16: 31
A17: 6 | B17: 3 | C17: 148 | D17: 172 | E17: 37.2 | F17: 13.041 | G17: 44.041 | H17: =ROUND((G17-F17),4) -> 31 | I17: 31
A19: 正負・勾配別の実入力（固定）
A20: KG | B20: 列 | C20: 節点 | D20: 支点項目 | E20: 欄番号 | F20: 入力欄 | G20: 実入力 | H20: 単位
A21: 4 | B21: 1 | C21: 122 | D21: 124 | E21: 4 | F21: K1+ | G21: 327072 | H21: kN/m
A22: 4 | B22: 1 | C22: 122 | D22: 124 | E22: 5 | F22: F1+ | G22: 7167.5 | H22: kN
A23: 4 | B23: 1 | C23: 122 | D23: 124 | E23: 6 | F23: F1- | H23: kN
A24: 4 | B24: 1 | C24: 122 | D24: 124 | E24: 7 | F24: K2+ | G24: 88418 | H24: kN/m
A25: 4 | B25: 1 | C25: 122 | D25: 124 | E25: 8 | F25: F2+ | G25: 16724.3 | H25: kN
A26: 4 | B26: 1 | C26: 122 | D26: 124 | E26: 9 | F26: F2- | H26: kN
A27: 4 | B27: 1 | C27: 122 | D27: 124 | E27: 10 | F27: K3+ | G27: 88418 | H27: kN/m
A28: 4 | B28: 1 | C28: 122 | D28: 124 | E28: 11 | F28: K1- | G28: 327072 | H28: kN/m
A29: 4 | B29: 1 | C29: 122 | D29: 124 | E29: 12 | F29: K2- | G29: 88418 | H29: kN/m
A30: 4 | B30: 1 | C30: 122 | D30: 124 | E30: 13 | F30: K3- | G30: 88418 | H30: kN/m
A31: 5 | B31: 2 | C31: 147 | D31: 125 | E31: 4 | F31: K1+ | G31: 218048 | H31: kN/m
A32: 5 | B32: 2 | C32: 147 | D32: 125 | E32: 5 | F32: F1+ | G32: 4778.4 | H32: kN
A33: 5 | B33: 2 | C33: 147 | D33: 125 | E33: 6 | F33: F1- | H33: kN
A34: 5 | B34: 2 | C34: 147 | D34: 125 | E34: 7 | F34: K2+ | G34: 58945 | H34: kN/m
A35: 5 | B35: 2 | C35: 147 | D35: 125 | E35: 8 | F35: F2+ | G35: 11149.5 | H35: kN
A36: 5 | B36: 2 | C36: 147 | D36: 125 | E36: 9 | F36: F2- | H36: kN
A37: 5 | B37: 2 | C37: 147 | D37: 125 | E37: 10 | F37: K3+ | G37: 58945 | H37: kN/m
A38: 5 | B38: 2 | C38: 147 | D38: 125 | E38: 11 | F38: K1- | G38: 218048 | H38: kN/m
A39: 5 | B39: 2 | C39: 147 | D39: 125 | E39: 12 | F39: K2- | G39: 58945 | H39: kN/m
A40: 5 | B40: 2 | C40: 147 | D40: 125 | E40: 13 | F40: K3- | G40: 58945 | H40: kN/m
A41: 6 | B41: 3 | C41: 172 | D41: 126 | E41: 4 | F41: K1+ | G41: 327072 | H41: kN/m
A42: 6 | B42: 3 | C42: 172 | D42: 126 | E42: 5 | F42: F1+ | G42: 7167.5 | H42: kN
A43: 6 | B43: 3 | C43: 172 | D43: 126 | E43: 6 | F43: F1- | H43: kN
A44: 6 | B44: 3 | C44: 172 | D44: 126 | E44: 7 | F44: K2+ | G44: 88418 | H44: kN/m
...

Sheet 入力根拠
A1: 入力根拠
A2: モデル保存と同一実行 2026-09-17T15:06:36.332488+09:00
A3: 青文字：原値 黄色：変換時の実入力（固定） 数式：再計算値。条件変更時はアプリから再実行してください。
A6: 実行・ファイル情報
A7: 項目 | B7: 値
A8: 実行ID: 20260917-150636-518155-23f5184f
A9: アプリ: SDCConverter 1.1.0
A10: 帳票スキーマ: 1
A11: 対象モデル: C:\Users\sasai\Documents\structural-design\snap\今町橋りょう4P(C方向･右押し→).ndu
A12: 状態: モデル保存と同一実行
A13: モデル出力: C:\Users\sasai\Documents\structural-design\snap\今町橋りょう4P(C方向･右押し→)_変換済み.ndu
A14: 出力予定SHA-256: 09d7ed88c1067d4333f6210d06dccb3b6fbf6e8d9fd2b2d4f6f90c7ba2e17ec0
A15: JSON: C:\Users\sasai\Documents\structural-design\snap\今町橋りょう4P(C方向･右押し→)_変換済み.ndu.20260917-150636-518155-23f5184f.report.json
A16: Excel: C:\Users\sasai\Documents\structural-design\snap\今町橋りょう4P(C方向･右押し→)_変換済み.ndu.20260917-150636-518155-23f5184f.計算過程.xlsx
A17: バックアップ: なし
A18: 杭対応: 4:1 5:2 6:3
A19: 土圧方向: right
... A32: 採用したSDC原値
A33: 処理 | B33: SDC行 | C33: CSV欄 | D33: 項目 | E33: 単位 | F33: 原値 | G33: 正確な十進文字列
A34: 水平地盤ばね | B34: 174 | C34: 9 | D34: 1列目 短期(非線形) | E34: kN/m² | F34: 58812 | G34: 58812
A35: 水平地盤ばね | B35: 175 | C35: 9 | D35: 1列目 短期(非線形) | E35: kN/m² | F35: 310863 | G35: 310863
A36: 水平地盤ばね | B36: 176 | C36: 9 | D36: 1列目 短期(非線形) | E36: kN/m² | F36: 110708 | G36: 110708
A37: 水平地盤ばね | B37: 177 | C37: 9 | D37: 1列目 短期(非線形) | E37: kN/m² | F37: 268854 | G37: 268854
A38: 水平地盤ばね | B38: 178 | C38: 9 | D38: 1列目 短期(非線形) | E38: kN/m² | F38: 428981 | G38: 428981
A39: 水平地盤ばね | B39: 179 | C39: 9 | D39: 1列目 短期(非線形) | E39: kN/m² | F39: 403280 | G39: 403280
A40: 水平地盤ばね | B40: 180 | C40: 9 | D40: 1列目 短期(非線形) | E40: kN/m² | F40: 193733 | G40: 193733
A41: 水平地盤ばね | B41: 174 | C41: 10 | D41: 2列目 短期(非線形) | E41: kN/m² | F41: 39208 | G41: 39208
A42: 水平地盤ばね | B42: 175 | C42: 10 | D42: 2列目 短期(非線形) | E42: kN/m² | F42: 207242 | G42: 207242
A43: 水平地盤ばね | B43: 176 | C43: 10 | D43: 2列目 短期(非線形) | E43: kN/m² | F43: 73805 | G43: 73805
A44: 水平地盤ばね | B44: 177 | C44: 10 | D44: 2列目 短期(非線形) | E44: kN/m² | F44: 179236 | G44: 179236
A45: 水平地盤ばね | B45: 178 | C45: 10 | D45: 2列目 短期(非線形) | E45: kN/m² | F45: 285987 | G45: 285987
... A138: 杭先端ばね | B138: 293 | C138: 6 | D138: 押込みFu | E138: kN | F138: 16724.3 | G138: 16724.3
A139: 座標演算の保持小数桁: 4（入力座標の最大精度＋中点の1桁）。積分・補間の結果は途中で丸めません。
A141: SDC見出しと原行（文字列保存）
A142: 原行
A143: SDC 18行: 杭長,突出長,根入れ深さ,平水位,弾性係数Es,弾性係数Ec,D1,D2,t1,t2,腐食代,A,I
A144: SDC 19行: 31, 0, 1.3, 4.86, , 22.4, 1.3, , , , , 1.327323, 0.140198
A145: SDC 162行: 杭列数,奥行き本数,,1/β(m)
A146: SDC 163行: ,奇数列,偶数列
A147: SDC 164行: 3, 3, 2, 4.945
...
